{"timestamp": "2025-04-30 13:44:28,551", "level": "ERROR", "message": "Error in analyze: (sqlite3.IntegrityError) datatype mismatch\n[SQL: INSERT INTO startups (id, name, description, created_at, updated_at) VALUES (?, ?, ?, ?, ?)]\n[parameters: ('test123', 'Company test123', None, '2025-04-30 13:44:28.551249', '2025-04-30 13:44:28.551254')]\n(Background on this error at: https://sqlalche.me/e/20/gkpj)", "module": "app", "function": "analyze", "line": "218", "process": "1", "thread": "140563984018304", "exception": {"type": "IntegrityError", "message": "(sqlite3.IntegrityError) datatype mismatch\n[SQL: INSERT INTO startups (id, name, description, created_at, updated_at) VALUES (?, ?, ?, ?, ?)]\n[parameters: ('test123', 'Company test123', None, '2025-04-30 13:44:28.551249', '2025-04-30 13:44:28.551254')]\n(Background on this error at: https://sqlalche.me/e/20/gkpj)", "traceback": "Traceback (most recent call last):\n  File \"/usr/local/lib/python3.11/site-packages/sqlalchemy/engine/base.py\", line 1964, in _exec_single_context\n    self.dialect.do_execute(\n  File \"/usr/local/lib/python3.11/site-packages/sqlalchemy/engine/default.py\", line 945, in do_execute\n    cursor.execute(statement, parameters)\nsqlite3.IntegrityError: datatype mismatch\n\nThe above exception was the direct cause of the following exception:\n\nTraceback (most recent call last):\n  File \"/app/backend/app.py\", line 178, in analyze\n    db.flush()\n  File \"/usr/local/lib/python3.11/site-packages/sqlalchemy/orm/session.py\", line 4353, in flush\n    self._flush(objects)\n  File \"/usr/local/lib/python3.11/site-packages/sqlalchemy/orm/session.py\", line 4488, in _flush\n    with util.safe_reraise():\n  File \"/usr/local/lib/python3.11/site-packages/sqlalchemy/util/langhelpers.py\", line 146, in __exit__\n    raise exc_value.with_traceback(exc_tb)\n  File \"/usr/local/lib/python3.11/site-packages/sqlalchemy/orm/session.py\", line 4449, in _flush\n    flush_context.execute()\n  File \"/usr/local/lib/python3.11/site-packages/sqlalchemy/orm/unitofwork.py\", line 466, in execute\n    rec.execute(self)\n  File \"/usr/local/lib/python3.11/site-packages/sqlalchemy/orm/unitofwork.py\", line 642, in execute\n    util.preloaded.orm_persistence.save_obj(\n  File \"/usr/local/lib/python3.11/site-packages/sqlalchemy/orm/persistence.py\", line 93, in save_obj\n    _emit_insert_statements(\n  File \"/usr/local/lib/python3.11/site-packages/sqlalchemy/orm/persistence.py\", line 1048, in _emit_insert_statements\n    result = connection.execute(\n             ^^^^^^^^^^^^^^^^^^^\n  File \"/usr/local/lib/python3.11/site-packages/sqlalchemy/engine/base.py\", line 1416, in execute\n    return meth(\n           ^^^^^\n  File \"/usr/local/lib/python3.11/site-packages/sqlalchemy/sql/elements.py\", line 523, in _execute_on_connection\n    return connection._execute_clauseelement(\n           ^^^^^^^^^^^^^^^^^^^^^^^^^^^^^^^^^^\n  File \"/usr/local/lib/python3.11/site-packages/sqlalchemy/engine/base.py\", line 1638, in _execute_clauseelement\n    ret = self._execute_context(\n          ^^^^^^^^^^^^^^^^^^^^^^\n  File \"/usr/local/lib/python3.11/site-packages/sqlalchemy/engine/base.py\", line 1843, in _execute_context\n    return self._exec_single_context(\n           ^^^^^^^^^^^^^^^^^^^^^^^^^^\n  File \"/usr/local/lib/python3.11/site-packages/sqlalchemy/engine/base.py\", line 1983, in _exec_single_context\n    self._handle_dbapi_exception(\n  File \"/usr/local/lib/python3.11/site-packages/sqlalchemy/engine/base.py\", line 2352, in _handle_dbapi_exception\n    raise sqlalchemy_exception.with_traceback(exc_info[2]) from e\n  File \"/usr/local/lib/python3.11/site-packages/sqlalchemy/engine/base.py\", line 1964, in _exec_single_context\n    self.dialect.do_execute(\n  File \"/usr/local/lib/python3.11/site-packages/sqlalchemy/engine/default.py\", line 945, in do_execute\n    cursor.execute(statement, parameters)\nsqlalchemy.exc.IntegrityError: (sqlite3.IntegrityError) datatype mismatch\n[SQL: INSERT INTO startups (id, name, description, created_at, updated_at) VALUES (?, ?, ?, ?, ?)]\n[parameters: ('test123', 'Company test123', None, '2025-04-30 13:44:28.551249', '2025-04-30 13:44:28.551254')]\n(Background on this error at: https://sqlalche.me/e/20/gkpj)"}}
{"timestamp": "2025-04-30 13:53:51,667", "level": "ERROR", "message": "Error in analyze: (sqlite3.OperationalError) unable to open database file\n(Background on this error at: https://sqlalche.me/e/20/e3q8)", "module": "app", "function": "analyze", "line": "218", "process": "1", "thread": "139843088423808", "exception": {"type": "OperationalError", "message": "(sqlite3.OperationalError) unable to open database file\n(Background on this error at: https://sqlalche.me/e/20/e3q8)", "traceback": "Traceback (most recent call last):\n  File \"/usr/local/lib/python3.11/site-packages/sqlalchemy/engine/base.py\", line 146, in __init__\n    self._dbapi_connection = engine.raw_connection()\n                             ^^^^^^^^^^^^^^^^^^^^^^^\n  File \"/usr/local/lib/python3.11/site-packages/sqlalchemy/engine/base.py\", line 3298, in raw_connection\n    return self.pool.connect()\n           ^^^^^^^^^^^^^^^^^^^\n  File \"/usr/local/lib/python3.11/site-packages/sqlalchemy/pool/base.py\", line 449, in connect\n    return _ConnectionFairy._checkout(self)\n           ^^^^^^^^^^^^^^^^^^^^^^^^^^^^^^^^\n  File \"/usr/local/lib/python3.11/site-packages/sqlalchemy/pool/base.py\", line 1264, in _checkout\n    fairy = _ConnectionRecord.checkout(pool)\n            ^^^^^^^^^^^^^^^^^^^^^^^^^^^^^^^^\n  File \"/usr/local/lib/python3.11/site-packages/sqlalchemy/pool/base.py\", line 713, in checkout\n    rec = pool._do_get()\n          ^^^^^^^^^^^^^^\n  File \"/usr/local/lib/python3.11/site-packages/sqlalchemy/pool/impl.py\", line 179, in _do_get\n    with util.safe_reraise():\n  File \"/usr/local/lib/python3.11/site-packages/sqlalchemy/util/langhelpers.py\", line 146, in __exit__\n    raise exc_value.with_traceback(exc_tb)\n  File \"/usr/local/lib/python3.11/site-packages/sqlalchemy/pool/impl.py\", line 177, in _do_get\n    return self._create_connection()\n           ^^^^^^^^^^^^^^^^^^^^^^^^^\n  File \"/usr/local/lib/python3.11/site-packages/sqlalchemy/pool/base.py\", line 390, in _create_connection\n    return _ConnectionRecord(self)\n           ^^^^^^^^^^^^^^^^^^^^^^^\n  File \"/usr/local/lib/python3.11/site-packages/sqlalchemy/pool/base.py\", line 675, in __init__\n    self.__connect()\n  File \"/usr/local/lib/python3.11/site-packages/sqlalchemy/pool/base.py\", line 901, in __connect\n    with util.safe_reraise():\n  File \"/usr/local/lib/python3.11/site-packages/sqlalchemy/util/langhelpers.py\", line 146, in __exit__\n    raise exc_value.with_traceback(exc_tb)\n  File \"/usr/local/lib/python3.11/site-packages/sqlalchemy/pool/base.py\", line 897, in __connect\n    self.dbapi_connection = connection = pool._invoke_creator(self)\n                                         ^^^^^^^^^^^^^^^^^^^^^^^^^^\n  File \"/usr/local/lib/python3.11/site-packages/sqlalchemy/engine/create.py\", line 646, in connect\n    return dialect.connect(*cargs, **cparams)\n           ^^^^^^^^^^^^^^^^^^^^^^^^^^^^^^^^^^\n  File \"/usr/local/lib/python3.11/site-packages/sqlalchemy/engine/default.py\", line 625, in connect\n    return self.loaded_dbapi.connect(*cargs, **cparams)  # type: ignore[no-any-return]  # NOQA: E501\n           ^^^^^^^^^^^^^^^^^^^^^^^^^^^^^^^^^^^^^^^^^^^^\nsqlite3.OperationalError: unable to open database file\n\nThe above exception was the direct cause of the following exception:\n\nTraceback (most recent call last):\n  File \"/app/backend/app.py\", line 168, in analyze\n    startup = db.query(Startup).filter(Startup.id == metrics.startup_id).first()\n              ^^^^^^^^^^^^^^^^^^^^^^^^^^^^^^^^^^^^^^^^^^^^^^^^^^^^^^^^^^^^^^^^^^\n  File \"/usr/local/lib/python3.11/site-packages/sqlalchemy/orm/query.py\", line 2759, in first\n    return self.limit(1)._iter().first()  # type: ignore\n           ^^^^^^^^^^^^^^^^^^^^^\n  File \"/usr/local/lib/python3.11/site-packages/sqlalchemy/orm/query.py\", line 2858, in _iter\n    result: Union[ScalarResult[_T], Result[_T]] = self.session.execute(\n                                                  ^^^^^^^^^^^^^^^^^^^^^\n  File \"/usr/local/lib/python3.11/site-packages/sqlalchemy/orm/session.py\", line 2365, in execute\n    return self._execute_internal(\n           ^^^^^^^^^^^^^^^^^^^^^^^\n  File \"/usr/local/lib/python3.11/site-packages/sqlalchemy/orm/session.py\", line 2241, in _execute_internal\n    conn = self._connection_for_bind(bind)\n           ^^^^^^^^^^^^^^^^^^^^^^^^^^^^^^^\n  File \"/usr/local/lib/python3.11/site-packages/sqlalchemy/orm/session.py\", line 2110, in _connection_for_bind\n    return trans._connection_for_bind(engine, execution_options)\n           ^^^^^^^^^^^^^^^^^^^^^^^^^^^^^^^^^^^^^^^^^^^^^^^^^^^^^\n  File \"<string>\", line 2, in _connection_for_bind\n  File \"/usr/local/lib/python3.11/site-packages/sqlalchemy/orm/state_changes.py\", line 139, in _go\n    ret_value = fn(self, *arg, **kw)\n                ^^^^^^^^^^^^^^^^^^^^\n  File \"/usr/local/lib/python3.11/site-packages/sqlalchemy/orm/session.py\", line 1189, in _connection_for_bind\n    conn = bind.connect()\n           ^^^^^^^^^^^^^^\n  File \"/usr/local/lib/python3.11/site-packages/sqlalchemy/engine/base.py\", line 3274, in connect\n    return self._connection_cls(self)\n           ^^^^^^^^^^^^^^^^^^^^^^^^^^\n  File \"/usr/local/lib/python3.11/site-packages/sqlalchemy/engine/base.py\", line 148, in __init__\n    Connection._handle_dbapi_exception_noconnection(\n  File \"/usr/local/lib/python3.11/site-packages/sqlalchemy/engine/base.py\", line 2439, in _handle_dbapi_exception_noconnection\n    raise sqlalchemy_exception.with_traceback(exc_info[2]) from e\n  File \"/usr/local/lib/python3.11/site-packages/sqlalchemy/engine/base.py\", line 146, in __init__\n    self._dbapi_connection = engine.raw_connection()\n                             ^^^^^^^^^^^^^^^^^^^^^^^\n  File \"/usr/local/lib/python3.11/site-packages/sqlalchemy/engine/base.py\", line 3298, in raw_connection\n    return self.pool.connect()\n           ^^^^^^^^^^^^^^^^^^^\n  File \"/usr/local/lib/python3.11/site-packages/sqlalchemy/pool/base.py\", line 449, in connect\n    return _ConnectionFairy._checkout(self)\n           ^^^^^^^^^^^^^^^^^^^^^^^^^^^^^^^^\n  File \"/usr/local/lib/python3.11/site-packages/sqlalchemy/pool/base.py\", line 1264, in _checkout\n    fairy = _ConnectionRecord.checkout(pool)\n            ^^^^^^^^^^^^^^^^^^^^^^^^^^^^^^^^\n  File \"/usr/local/lib/python3.11/site-packages/sqlalchemy/pool/base.py\", line 713, in checkout\n    rec = pool._do_get()\n          ^^^^^^^^^^^^^^\n  File \"/usr/local/lib/python3.11/site-packages/sqlalchemy/pool/impl.py\", line 179, in _do_get\n    with util.safe_reraise():\n  File \"/usr/local/lib/python3.11/site-packages/sqlalchemy/util/langhelpers.py\", line 146, in __exit__\n    raise exc_value.with_traceback(exc_tb)\n  File \"/usr/local/lib/python3.11/site-packages/sqlalchemy/pool/impl.py\", line 177, in _do_get\n    return self._create_connection()\n           ^^^^^^^^^^^^^^^^^^^^^^^^^\n  File \"/usr/local/lib/python3.11/site-packages/sqlalchemy/pool/base.py\", line 390, in _create_connection\n    return _ConnectionRecord(self)\n           ^^^^^^^^^^^^^^^^^^^^^^^\n  File \"/usr/local/lib/python3.11/site-packages/sqlalchemy/pool/base.py\", line 675, in __init__\n    self.__connect()\n  File \"/usr/local/lib/python3.11/site-packages/sqlalchemy/pool/base.py\", line 901, in __connect\n    with util.safe_reraise():\n  File \"/usr/local/lib/python3.11/site-packages/sqlalchemy/util/langhelpers.py\", line 146, in __exit__\n    raise exc_value.with_traceback(exc_tb)\n  File \"/usr/local/lib/python3.11/site-packages/sqlalchemy/pool/base.py\", line 897, in __connect\n    self.dbapi_connection = connection = pool._invoke_creator(self)\n                                         ^^^^^^^^^^^^^^^^^^^^^^^^^^\n  File \"/usr/local/lib/python3.11/site-packages/sqlalchemy/engine/create.py\", line 646, in connect\n    return dialect.connect(*cargs, **cparams)\n           ^^^^^^^^^^^^^^^^^^^^^^^^^^^^^^^^^^\n  File \"/usr/local/lib/python3.11/site-packages/sqlalchemy/engine/default.py\", line 625, in connect\n    return self.loaded_dbapi.connect(*cargs, **cparams)  # type: ignore[no-any-return]  # NOQA: E501\n           ^^^^^^^^^^^^^^^^^^^^^^^^^^^^^^^^^^^^^^^^^^^^\nsqlalchemy.exc.OperationalError: (sqlite3.OperationalError) unable to open database file\n(Background on this error at: https://sqlalche.me/e/20/e3q8)"}}
{"timestamp": "2025-04-30 13:54:49,948", "level": "ERROR", "message": "Error in analyze: unsupported format string passed to dict.__format__", "module": "app", "function": "analyze", "line": "218", "process": "1", "thread": "140415055555456", "exception": {"type": "TypeError", "message": "unsupported format string passed to dict.__format__", "traceback": "Traceback (most recent call last):\n  File \"/app/backend/app.py\", line 207, in analyze\n    logger.info(f\"Analysis complete for startup ID: {metrics.startup_id or 'unknown'}, success prob: {success_prob:.2f}\")\n                ^^^^^^^^^^^^^^^^^^^^^^^^^^^^^^^^^^^^^^^^^^^^^^^^^^^^^^^^^^^^^^^^^^^^^^^^^^^^^^^^^^^^^^^^^^^^^^^^^^^^^^^^\nTypeError: unsupported format string passed to dict.__format__"}}
{"timestamp": "2025-05-01 13:15:57,240", "level": "ERROR", "message": "Error initializing database: (sqlite3.OperationalError) unable to open database file\n(Background on this error at: https://sqlalche.me/e/20/e3q8)", "module": "database", "function": "init_db", "line": "61", "process": "1", "thread": "139685430750080"}
{"timestamp": "2025-05-01 13:15:57,242", "level": "ERROR", "message": "Error during startup: (sqlite3.OperationalError) unable to open database file\n(Background on this error at: https://sqlalche.me/e/20/e3q8)", "module": "app", "function": "startup_event", "line": "132", "process": "1", "thread": "139685430750080"}
{"timestamp": "2025-05-01 13:18:49,466", "level": "ERROR", "message": "Error initializing database: (sqlite3.OperationalError) unable to open database file\n(Background on this error at: https://sqlalche.me/e/20/e3q8)", "module": "database", "function": "init_db", "line": "61", "process": "1", "thread": "140334564158336"}
{"timestamp": "2025-05-01 13:18:49,468", "level": "ERROR", "message": "Error during startup: (sqlite3.OperationalError) unable to open database file\n(Background on this error at: https://sqlalche.me/e/20/e3q8)", "module": "app", "function": "startup_event", "line": "132", "process": "1", "thread": "140334564158336"}
