{"timestamp": "2025-05-02 20:30:28,885", "level": "ERROR", "message": "Error calculating pillar scores: '<=' not supported between instances of 'NoneType' and 'int'", "module": "analysis", "function": "pillar_scores", "line": "106", "process": "42787", "thread": "140704650779584", "exception": {"type": "TypeError", "message": "'<=' not supported between instances of 'NoneType' and 'int'", "traceback": "Traceback (most recent call last):\n  File \"/Users/sf/Desktop/FLASH/flashcamp/backend/analysis.py\", line 83, in pillar_scores\n    capital_score, _ = calculate_capital_score_fn(metrics_data)\n                       ^^^^^^^^^^^^^^^^^^^^^^^^^^^^^^^^^^^^^^^^\n  File \"/Users/sf/Desktop/FLASH/flashcamp/backend/app/engines/capital.py\", line 174, in calculate_capital_score\n    unit_economics_score = calculate_unit_economics_score(metrics)\n                           ^^^^^^^^^^^^^^^^^^^^^^^^^^^^^^^^^^^^^^^\n  File \"/Users/sf/Desktop/FLASH/flashcamp/backend/app/engines/capital.py\", line 117, in calculate_unit_economics_score\n    if payback_months <= 0:\n       ^^^^^^^^^^^^^^^^^^^\nTypeError: '<=' not supported between instances of 'NoneType' and 'int'"}}
{"timestamp": "2025-05-02 20:30:28,888", "level": "ERROR", "message": "Error loading model: [Errno 2] No such file or directory: '/mnt/data/success_xgb.joblib'", "module": "ml", "function": "_load_model", "line": "52", "process": "42787", "thread": "140704650779584"}
{"timestamp": "2025-05-02 20:33:40,288", "level": "ERROR", "message": "Error calculating pillar scores: '<=' not supported between instances of 'NoneType' and 'int'", "module": "analysis", "function": "pillar_scores", "line": "106", "process": "43312", "thread": "140704650779584", "exception": {"type": "TypeError", "message": "'<=' not supported between instances of 'NoneType' and 'int'", "traceback": "Traceback (most recent call last):\n  File \"/Users/sf/Desktop/FLASH/flashcamp/backend/analysis.py\", line 83, in pillar_scores\n    capital_score, _ = calculate_capital_score_fn(metrics_data)\n                       ^^^^^^^^^^^^^^^^^^^^^^^^^^^^^^^^^^^^^^^^\n  File \"/Users/sf/Desktop/FLASH/flashcamp/backend/app/engines/capital.py\", line 174, in calculate_capital_score\n    unit_economics_score = calculate_unit_economics_score(metrics)\n                           ^^^^^^^^^^^^^^^^^^^^^^^^^^^^^^^^^^^^^^^\n  File \"/Users/sf/Desktop/FLASH/flashcamp/backend/app/engines/capital.py\", line 117, in calculate_unit_economics_score\n    if payback_months <= 0:\n       ^^^^^^^^^^^^^^^^^^^\nTypeError: '<=' not supported between instances of 'NoneType' and 'int'"}}
{"timestamp": "2025-05-02 20:33:40,291", "level": "ERROR", "message": "Error loading model: [Errno 2] No such file or directory: '/mnt/data/success_xgb.joblib'", "module": "ml", "function": "_load_model", "line": "55", "process": "43312", "thread": "140704650779584"}
{"timestamp": "2025-05-02 20:40:28,986", "level": "ERROR", "message": "Error during market score prediction: 'Booster' object has no attribute 'predict_proba'", "module": "market", "function": "calculate_market_score", "line": "37", "process": "43806", "thread": "140704650779584", "exception": {"type": "AttributeError", "message": "'Booster' object has no attribute 'predict_proba'", "traceback": "Traceback (most recent call last):\n  File \"/Users/sf/Desktop/FLASH/flashcamp/backend/app/engines/market.py\", line 29, in calculate_market_score\n    score = float(_model.predict_proba(X)[0, 1])\n                  ^^^^^^^^^^^^^^^^^^^^\nAttributeError: 'Booster' object has no attribute 'predict_proba'"}}
{"timestamp": "2025-05-02 20:40:28,997", "level": "ERROR", "message": "Error during advantage score prediction: 'Booster' object has no attribute 'predict_proba'", "module": "advantage", "function": "calculate_advantage_score", "line": "33", "process": "43806", "thread": "140704650779584", "exception": {"type": "AttributeError", "message": "'Booster' object has no attribute 'predict_proba'", "traceback": "Traceback (most recent call last):\n  File \"/Users/sf/Desktop/FLASH/flashcamp/backend/app/engines/advantage.py\", line 27, in calculate_advantage_score\n    score = float(_model.predict_proba(X)[0, 1])\n                  ^^^^^^^^^^^^^^^^^^^^\nAttributeError: 'Booster' object has no attribute 'predict_proba'"}}
{"timestamp": "2025-05-02 20:40:29,006", "level": "ERROR", "message": "Error during people score prediction: 'Booster' object has no attribute 'predict_proba'", "module": "people", "function": "calculate_people_score", "line": "33", "process": "43806", "thread": "140704650779584", "exception": {"type": "AttributeError", "message": "'Booster' object has no attribute 'predict_proba'", "traceback": "Traceback (most recent call last):\n  File \"/Users/sf/Desktop/FLASH/flashcamp/backend/app/engines/people.py\", line 27, in calculate_people_score\n    score = float(_model.predict_proba(X)[0, 1])\n                  ^^^^^^^^^^^^^^^^^^^^\nAttributeError: 'Booster' object has no attribute 'predict_proba'"}}
{"timestamp": "2025-05-02 20:40:29,013", "level": "ERROR", "message": "Error during capital score prediction: 'Booster' object has no attribute 'predict_proba'", "module": "capital", "function": "calculate_capital_score", "line": "33", "process": "43806", "thread": "140704650779584", "exception": {"type": "AttributeError", "message": "'Booster' object has no attribute 'predict_proba'", "traceback": "Traceback (most recent call last):\n  File \"/Users/sf/Desktop/FLASH/flashcamp/backend/app/engines/capital.py\", line 27, in calculate_capital_score\n    score = float(_model.predict_proba(X)[0, 1])\n                  ^^^^^^^^^^^^^^^^^^^^\nAttributeError: 'Booster' object has no attribute 'predict_proba'"}}
{"timestamp": "2025-05-02 20:40:29,015", "level": "ERROR", "message": "Error calculating pillar scores: unsupported operand type(s) for /=: 'tuple' and 'int'", "module": "analysis", "function": "pillar_scores", "line": "106", "process": "43806", "thread": "140704650779584", "exception": {"type": "TypeError", "message": "unsupported operand type(s) for /=: 'tuple' and 'int'", "traceback": "Traceback (most recent call last):\n  File \"/Users/sf/Desktop/FLASH/flashcamp/backend/analysis.py\", line 89, in pillar_scores\n    people_score /= 10\nTypeError: unsupported operand type(s) for /=: 'tuple' and 'int'"}}
{"timestamp": "2025-05-02 20:40:29,018", "level": "ERROR", "message": "Error loading model: [Errno 2] No such file or directory: '/mnt/data/success_xgb.joblib'", "module": "ml", "function": "_load_model", "line": "55", "process": "43806", "thread": "140704650779584"}
{"timestamp": "2025-05-02 20:48:17,562", "level": "ERROR", "message": "Error during market score prediction: pandas dtypes must be int, float or bool.\nFields with bad pandas dtypes: startup_id: object, start_date: object, founding_year: object, sector: object, subsector: object, industry: object, market_geography: object, funding_stage: object, team_size_total: object, technical_team_size: object, team_diversity_percent: object, ltv_cac_ratio: object, customer_churn_rate_percent: object, patents_count: object, has_data_moat: object, prior_startup_experience_count: object, debt_ratio: object, has_debt: object, viral_coefficient: object, conversion_rate_percent: object, brand_strength_score: object, website: object, country: object, regulatory_risk_score: object, board_advisor_experience_score: object, sales_cycle_length_days: object, scalability_score: object, cac_payback_months: object, distribution_partner_count: object, tech_differentiation_score: object", "module": "market", "function": "calculate_market_score", "line": "40", "process": "44466", "thread": "140704650779584", "exception": {"type": "ValueError", "message": "pandas dtypes must be int, float or bool.\nFields with bad pandas dtypes: startup_id: object, start_date: object, founding_year: object, sector: object, subsector: object, industry: object, market_geography: object, funding_stage: object, team_size_total: object, technical_team_size: object, team_diversity_percent: object, ltv_cac_ratio: object, customer_churn_rate_percent: object, patents_count: object, has_data_moat: object, prior_startup_experience_count: object, debt_ratio: object, has_debt: object, viral_coefficient: object, conversion_rate_percent: object, brand_strength_score: object, website: object, country: object, regulatory_risk_score: object, board_advisor_experience_score: object, sales_cycle_length_days: object, scalability_score: object, cac_payback_months: object, distribution_partner_count: object, tech_differentiation_score: object", "traceback": "Traceback (most recent call last):\n  File \"/Users/sf/Desktop/FLASH/flashcamp/backend/app/engines/market.py\", line 30, in calculate_market_score\n    raw_prediction = _model.predict(X)\n                     ^^^^^^^^^^^^^^^^^\n  File \"/Users/sf/Desktop/FLASH/.venv/lib/python3.11/site-packages/lightgbm/basic.py\", line 4453, in predict\n    return predictor.predict(\n           ^^^^^^^^^^^^^^^^^^\n  File \"/Users/sf/Desktop/FLASH/.venv/lib/python3.11/site-packages/lightgbm/basic.py\", line 1116, in predict\n    data = _data_from_pandas(\n           ^^^^^^^^^^^^^^^^^^\n  File \"/Users/sf/Desktop/FLASH/.venv/lib/python3.11/site-packages/lightgbm/basic.py\", line 825, in _data_from_pandas\n    _pandas_to_numpy(data, target_dtype=target_dtype),\n    ^^^^^^^^^^^^^^^^^^^^^^^^^^^^^^^^^^^^^^^^^^^^^^^^^\n  File \"/Users/sf/Desktop/FLASH/.venv/lib/python3.11/site-packages/lightgbm/basic.py\", line 771, in _pandas_to_numpy\n    _check_for_bad_pandas_dtypes(data.dtypes)\n  File \"/Users/sf/Desktop/FLASH/.venv/lib/python3.11/site-packages/lightgbm/basic.py\", line 763, in _check_for_bad_pandas_dtypes\n    raise ValueError('pandas dtypes must be int, float or bool.\\n'\nValueError: pandas dtypes must be int, float or bool.\nFields with bad pandas dtypes: startup_id: object, start_date: object, founding_year: object, sector: object, subsector: object, industry: object, market_geography: object, funding_stage: object, team_size_total: object, technical_team_size: object, team_diversity_percent: object, ltv_cac_ratio: object, customer_churn_rate_percent: object, patents_count: object, has_data_moat: object, prior_startup_experience_count: object, debt_ratio: object, has_debt: object, viral_coefficient: object, conversion_rate_percent: object, brand_strength_score: object, website: object, country: object, regulatory_risk_score: object, board_advisor_experience_score: object, sales_cycle_length_days: object, scalability_score: object, cac_payback_months: object, distribution_partner_count: object, tech_differentiation_score: object"}}
{"timestamp": "2025-05-02 20:48:17,578", "level": "ERROR", "message": "Error during advantage score prediction: pandas dtypes must be int, float or bool.\nFields with bad pandas dtypes: startup_id: object, start_date: object, founding_year: object, sector: object, subsector: object, industry: object, market_geography: object, funding_stage: object, team_size_total: object, technical_team_size: object, team_diversity_percent: object, ltv_cac_ratio: object, customer_churn_rate_percent: object, patents_count: object, has_data_moat: object, prior_startup_experience_count: object, debt_ratio: object, has_debt: object, viral_coefficient: object, conversion_rate_percent: object, brand_strength_score: object, website: object, country: object, regulatory_risk_score: object, board_advisor_experience_score: object, sales_cycle_length_days: object, scalability_score: object, cac_payback_months: object, distribution_partner_count: object, tech_differentiation_score: object", "module": "advantage", "function": "calculate_advantage_score", "line": "34", "process": "44466", "thread": "140704650779584", "exception": {"type": "ValueError", "message": "pandas dtypes must be int, float or bool.\nFields with bad pandas dtypes: startup_id: object, start_date: object, founding_year: object, sector: object, subsector: object, industry: object, market_geography: object, funding_stage: object, team_size_total: object, technical_team_size: object, team_diversity_percent: object, ltv_cac_ratio: object, customer_churn_rate_percent: object, patents_count: object, has_data_moat: object, prior_startup_experience_count: object, debt_ratio: object, has_debt: object, viral_coefficient: object, conversion_rate_percent: object, brand_strength_score: object, website: object, country: object, regulatory_risk_score: object, board_advisor_experience_score: object, sales_cycle_length_days: object, scalability_score: object, cac_payback_months: object, distribution_partner_count: object, tech_differentiation_score: object", "traceback": "Traceback (most recent call last):\n  File \"/Users/sf/Desktop/FLASH/flashcamp/backend/app/engines/advantage.py\", line 27, in calculate_advantage_score\n    raw_prediction = _model.predict(X)\n                     ^^^^^^^^^^^^^^^^^\n  File \"/Users/sf/Desktop/FLASH/.venv/lib/python3.11/site-packages/lightgbm/basic.py\", line 4453, in predict\n    return predictor.predict(\n           ^^^^^^^^^^^^^^^^^^\n  File \"/Users/sf/Desktop/FLASH/.venv/lib/python3.11/site-packages/lightgbm/basic.py\", line 1116, in predict\n    data = _data_from_pandas(\n           ^^^^^^^^^^^^^^^^^^\n  File \"/Users/sf/Desktop/FLASH/.venv/lib/python3.11/site-packages/lightgbm/basic.py\", line 825, in _data_from_pandas\n    _pandas_to_numpy(data, target_dtype=target_dtype),\n    ^^^^^^^^^^^^^^^^^^^^^^^^^^^^^^^^^^^^^^^^^^^^^^^^^\n  File \"/Users/sf/Desktop/FLASH/.venv/lib/python3.11/site-packages/lightgbm/basic.py\", line 771, in _pandas_to_numpy\n    _check_for_bad_pandas_dtypes(data.dtypes)\n  File \"/Users/sf/Desktop/FLASH/.venv/lib/python3.11/site-packages/lightgbm/basic.py\", line 763, in _check_for_bad_pandas_dtypes\n    raise ValueError('pandas dtypes must be int, float or bool.\\n'\nValueError: pandas dtypes must be int, float or bool.\nFields with bad pandas dtypes: startup_id: object, start_date: object, founding_year: object, sector: object, subsector: object, industry: object, market_geography: object, funding_stage: object, team_size_total: object, technical_team_size: object, team_diversity_percent: object, ltv_cac_ratio: object, customer_churn_rate_percent: object, patents_count: object, has_data_moat: object, prior_startup_experience_count: object, debt_ratio: object, has_debt: object, viral_coefficient: object, conversion_rate_percent: object, brand_strength_score: object, website: object, country: object, regulatory_risk_score: object, board_advisor_experience_score: object, sales_cycle_length_days: object, scalability_score: object, cac_payback_months: object, distribution_partner_count: object, tech_differentiation_score: object"}}
{"timestamp": "2025-05-02 20:48:17,590", "level": "ERROR", "message": "Error during people score prediction: pandas dtypes must be int, float or bool.\nFields with bad pandas dtypes: startup_id: object, start_date: object, founding_year: object, sector: object, subsector: object, industry: object, market_geography: object, funding_stage: object, team_size_total: object, technical_team_size: object, team_diversity_percent: object, ltv_cac_ratio: object, customer_churn_rate_percent: object, patents_count: object, has_data_moat: object, prior_startup_experience_count: object, debt_ratio: object, has_debt: object, viral_coefficient: object, conversion_rate_percent: object, brand_strength_score: object, website: object, country: object, regulatory_risk_score: object, board_advisor_experience_score: object, sales_cycle_length_days: object, scalability_score: object, cac_payback_months: object, distribution_partner_count: object, tech_differentiation_score: object", "module": "people", "function": "calculate_people_score", "line": "34", "process": "44466", "thread": "140704650779584", "exception": {"type": "ValueError", "message": "pandas dtypes must be int, float or bool.\nFields with bad pandas dtypes: startup_id: object, start_date: object, founding_year: object, sector: object, subsector: object, industry: object, market_geography: object, funding_stage: object, team_size_total: object, technical_team_size: object, team_diversity_percent: object, ltv_cac_ratio: object, customer_churn_rate_percent: object, patents_count: object, has_data_moat: object, prior_startup_experience_count: object, debt_ratio: object, has_debt: object, viral_coefficient: object, conversion_rate_percent: object, brand_strength_score: object, website: object, country: object, regulatory_risk_score: object, board_advisor_experience_score: object, sales_cycle_length_days: object, scalability_score: object, cac_payback_months: object, distribution_partner_count: object, tech_differentiation_score: object", "traceback": "Traceback (most recent call last):\n  File \"/Users/sf/Desktop/FLASH/flashcamp/backend/app/engines/people.py\", line 27, in calculate_people_score\n    raw_prediction = _model.predict(X)\n                     ^^^^^^^^^^^^^^^^^\n  File \"/Users/sf/Desktop/FLASH/.venv/lib/python3.11/site-packages/lightgbm/basic.py\", line 4453, in predict\n    return predictor.predict(\n           ^^^^^^^^^^^^^^^^^^\n  File \"/Users/sf/Desktop/FLASH/.venv/lib/python3.11/site-packages/lightgbm/basic.py\", line 1116, in predict\n    data = _data_from_pandas(\n           ^^^^^^^^^^^^^^^^^^\n  File \"/Users/sf/Desktop/FLASH/.venv/lib/python3.11/site-packages/lightgbm/basic.py\", line 825, in _data_from_pandas\n    _pandas_to_numpy(data, target_dtype=target_dtype),\n    ^^^^^^^^^^^^^^^^^^^^^^^^^^^^^^^^^^^^^^^^^^^^^^^^^\n  File \"/Users/sf/Desktop/FLASH/.venv/lib/python3.11/site-packages/lightgbm/basic.py\", line 771, in _pandas_to_numpy\n    _check_for_bad_pandas_dtypes(data.dtypes)\n  File \"/Users/sf/Desktop/FLASH/.venv/lib/python3.11/site-packages/lightgbm/basic.py\", line 763, in _check_for_bad_pandas_dtypes\n    raise ValueError('pandas dtypes must be int, float or bool.\\n'\nValueError: pandas dtypes must be int, float or bool.\nFields with bad pandas dtypes: startup_id: object, start_date: object, founding_year: object, sector: object, subsector: object, industry: object, market_geography: object, funding_stage: object, team_size_total: object, technical_team_size: object, team_diversity_percent: object, ltv_cac_ratio: object, customer_churn_rate_percent: object, patents_count: object, has_data_moat: object, prior_startup_experience_count: object, debt_ratio: object, has_debt: object, viral_coefficient: object, conversion_rate_percent: object, brand_strength_score: object, website: object, country: object, regulatory_risk_score: object, board_advisor_experience_score: object, sales_cycle_length_days: object, scalability_score: object, cac_payback_months: object, distribution_partner_count: object, tech_differentiation_score: object"}}
{"timestamp": "2025-05-02 20:48:17,602", "level": "ERROR", "message": "Error during capital score prediction: pandas dtypes must be int, float or bool.\nFields with bad pandas dtypes: startup_id: object, start_date: object, founding_year: object, sector: object, subsector: object, industry: object, market_geography: object, funding_stage: object, team_size_total: object, technical_team_size: object, team_diversity_percent: object, ltv_cac_ratio: object, customer_churn_rate_percent: object, patents_count: object, has_data_moat: object, prior_startup_experience_count: object, debt_ratio: object, has_debt: object, viral_coefficient: object, conversion_rate_percent: object, brand_strength_score: object, website: object, country: object, regulatory_risk_score: object, board_advisor_experience_score: object, sales_cycle_length_days: object, scalability_score: object, cac_payback_months: object, distribution_partner_count: object, tech_differentiation_score: object", "module": "capital", "function": "calculate_capital_score", "line": "34", "process": "44466", "thread": "140704650779584", "exception": {"type": "ValueError", "message": "pandas dtypes must be int, float or bool.\nFields with bad pandas dtypes: startup_id: object, start_date: object, founding_year: object, sector: object, subsector: object, industry: object, market_geography: object, funding_stage: object, team_size_total: object, technical_team_size: object, team_diversity_percent: object, ltv_cac_ratio: object, customer_churn_rate_percent: object, patents_count: object, has_data_moat: object, prior_startup_experience_count: object, debt_ratio: object, has_debt: object, viral_coefficient: object, conversion_rate_percent: object, brand_strength_score: object, website: object, country: object, regulatory_risk_score: object, board_advisor_experience_score: object, sales_cycle_length_days: object, scalability_score: object, cac_payback_months: object, distribution_partner_count: object, tech_differentiation_score: object", "traceback": "Traceback (most recent call last):\n  File \"/Users/sf/Desktop/FLASH/flashcamp/backend/app/engines/capital.py\", line 27, in calculate_capital_score\n    raw_prediction = _model.predict(X)\n                     ^^^^^^^^^^^^^^^^^\n  File \"/Users/sf/Desktop/FLASH/.venv/lib/python3.11/site-packages/lightgbm/basic.py\", line 4453, in predict\n    return predictor.predict(\n           ^^^^^^^^^^^^^^^^^^\n  File \"/Users/sf/Desktop/FLASH/.venv/lib/python3.11/site-packages/lightgbm/basic.py\", line 1116, in predict\n    data = _data_from_pandas(\n           ^^^^^^^^^^^^^^^^^^\n  File \"/Users/sf/Desktop/FLASH/.venv/lib/python3.11/site-packages/lightgbm/basic.py\", line 825, in _data_from_pandas\n    _pandas_to_numpy(data, target_dtype=target_dtype),\n    ^^^^^^^^^^^^^^^^^^^^^^^^^^^^^^^^^^^^^^^^^^^^^^^^^\n  File \"/Users/sf/Desktop/FLASH/.venv/lib/python3.11/site-packages/lightgbm/basic.py\", line 771, in _pandas_to_numpy\n    _check_for_bad_pandas_dtypes(data.dtypes)\n  File \"/Users/sf/Desktop/FLASH/.venv/lib/python3.11/site-packages/lightgbm/basic.py\", line 763, in _check_for_bad_pandas_dtypes\n    raise ValueError('pandas dtypes must be int, float or bool.\\n'\nValueError: pandas dtypes must be int, float or bool.\nFields with bad pandas dtypes: startup_id: object, start_date: object, founding_year: object, sector: object, subsector: object, industry: object, market_geography: object, funding_stage: object, team_size_total: object, technical_team_size: object, team_diversity_percent: object, ltv_cac_ratio: object, customer_churn_rate_percent: object, patents_count: object, has_data_moat: object, prior_startup_experience_count: object, debt_ratio: object, has_debt: object, viral_coefficient: object, conversion_rate_percent: object, brand_strength_score: object, website: object, country: object, regulatory_risk_score: object, board_advisor_experience_score: object, sales_cycle_length_days: object, scalability_score: object, cac_payback_months: object, distribution_partner_count: object, tech_differentiation_score: object"}}
{"timestamp": "2025-05-02 20:48:17,607", "level": "ERROR", "message": "Error calculating pillar scores: unsupported operand type(s) for /=: 'tuple' and 'int'", "module": "analysis", "function": "pillar_scores", "line": "106", "process": "44466", "thread": "140704650779584", "exception": {"type": "TypeError", "message": "unsupported operand type(s) for /=: 'tuple' and 'int'", "traceback": "Traceback (most recent call last):\n  File \"/Users/sf/Desktop/FLASH/flashcamp/backend/analysis.py\", line 89, in pillar_scores\n    people_score /= 10\nTypeError: unsupported operand type(s) for /=: 'tuple' and 'int'"}}
{"timestamp": "2025-05-02 20:48:17,610", "level": "ERROR", "message": "Error loading model: [Errno 2] No such file or directory: '/mnt/data/success_xgb.joblib'", "module": "ml", "function": "_load_model", "line": "55", "process": "44466", "thread": "140704650779584"}
{"timestamp": "2025-05-02 20:49:17,456", "level": "ERROR", "message": "Error during market score prediction: The number of features in data (32) is not the same as it was in training data (4).\nYou can set ``predict_disable_shape_check=true`` to discard this error, but please be aware what you are doing.", "module": "market", "function": "calculate_market_score", "line": "40", "process": "44599", "thread": "140704650779584", "exception": {"type": "LightGBMError", "message": "The number of features in data (32) is not the same as it was in training data (4).\nYou can set ``predict_disable_shape_check=true`` to discard this error, but please be aware what you are doing.", "traceback": "Traceback (most recent call last):\n  File \"/Users/sf/Desktop/FLASH/flashcamp/backend/app/engines/market.py\", line 30, in calculate_market_score\n    raw_prediction = _model.predict(X)\n                     ^^^^^^^^^^^^^^^^^\n  File \"/Users/sf/Desktop/FLASH/.venv/lib/python3.11/site-packages/lightgbm/basic.py\", line 4453, in predict\n    return predictor.predict(\n           ^^^^^^^^^^^^^^^^^^\n  File \"/Users/sf/Desktop/FLASH/.venv/lib/python3.11/site-packages/lightgbm/basic.py\", line 1159, in predict\n    preds, nrow = self.__pred_for_np2d(\n                  ^^^^^^^^^^^^^^^^^^^^^\n  File \"/Users/sf/Desktop/FLASH/.venv/lib/python3.11/site-packages/lightgbm/basic.py\", line 1306, in __pred_for_np2d\n    return self.__inner_predict_np2d(\n           ^^^^^^^^^^^^^^^^^^^^^^^^^^\n  File \"/Users/sf/Desktop/FLASH/.venv/lib/python3.11/site-packages/lightgbm/basic.py\", line 1259, in __inner_predict_np2d\n    _safe_call(_LIB.LGBM_BoosterPredictForMat(\n  File \"/Users/sf/Desktop/FLASH/.venv/lib/python3.11/site-packages/lightgbm/basic.py\", line 263, in _safe_call\n    raise LightGBMError(_LIB.LGBM_GetLastError().decode('utf-8'))\nlightgbm.basic.LightGBMError: The number of features in data (32) is not the same as it was in training data (4).\nYou can set ``predict_disable_shape_check=true`` to discard this error, but please be aware what you are doing."}}
{"timestamp": "2025-05-02 20:49:17,485", "level": "ERROR", "message": "Error during advantage score prediction: The number of features in data (32) is not the same as it was in training data (8).\nYou can set ``predict_disable_shape_check=true`` to discard this error, but please be aware what you are doing.", "module": "advantage", "function": "calculate_advantage_score", "line": "34", "process": "44599", "thread": "140704650779584", "exception": {"type": "LightGBMError", "message": "The number of features in data (32) is not the same as it was in training data (8).\nYou can set ``predict_disable_shape_check=true`` to discard this error, but please be aware what you are doing.", "traceback": "Traceback (most recent call last):\n  File \"/Users/sf/Desktop/FLASH/flashcamp/backend/app/engines/advantage.py\", line 27, in calculate_advantage_score\n    raw_prediction = _model.predict(X)\n                     ^^^^^^^^^^^^^^^^^\n  File \"/Users/sf/Desktop/FLASH/.venv/lib/python3.11/site-packages/lightgbm/basic.py\", line 4453, in predict\n    return predictor.predict(\n           ^^^^^^^^^^^^^^^^^^\n  File \"/Users/sf/Desktop/FLASH/.venv/lib/python3.11/site-packages/lightgbm/basic.py\", line 1159, in predict\n    preds, nrow = self.__pred_for_np2d(\n                  ^^^^^^^^^^^^^^^^^^^^^\n  File \"/Users/sf/Desktop/FLASH/.venv/lib/python3.11/site-packages/lightgbm/basic.py\", line 1306, in __pred_for_np2d\n    return self.__inner_predict_np2d(\n           ^^^^^^^^^^^^^^^^^^^^^^^^^^\n  File \"/Users/sf/Desktop/FLASH/.venv/lib/python3.11/site-packages/lightgbm/basic.py\", line 1259, in __inner_predict_np2d\n    _safe_call(_LIB.LGBM_BoosterPredictForMat(\n  File \"/Users/sf/Desktop/FLASH/.venv/lib/python3.11/site-packages/lightgbm/basic.py\", line 263, in _safe_call\n    raise LightGBMError(_LIB.LGBM_GetLastError().decode('utf-8'))\nlightgbm.basic.LightGBMError: The number of features in data (32) is not the same as it was in training data (8).\nYou can set ``predict_disable_shape_check=true`` to discard this error, but please be aware what you are doing."}}
{"timestamp": "2025-05-02 20:49:17,510", "level": "ERROR", "message": "Error during people score prediction: The number of features in data (32) is not the same as it was in training data (7).\nYou can set ``predict_disable_shape_check=true`` to discard this error, but please be aware what you are doing.", "module": "people", "function": "calculate_people_score", "line": "34", "process": "44599", "thread": "140704650779584", "exception": {"type": "LightGBMError", "message": "The number of features in data (32) is not the same as it was in training data (7).\nYou can set ``predict_disable_shape_check=true`` to discard this error, but please be aware what you are doing.", "traceback": "Traceback (most recent call last):\n  File \"/Users/sf/Desktop/FLASH/flashcamp/backend/app/engines/people.py\", line 27, in calculate_people_score\n    raw_prediction = _model.predict(X)\n                     ^^^^^^^^^^^^^^^^^\n  File \"/Users/sf/Desktop/FLASH/.venv/lib/python3.11/site-packages/lightgbm/basic.py\", line 4453, in predict\n    return predictor.predict(\n           ^^^^^^^^^^^^^^^^^^\n  File \"/Users/sf/Desktop/FLASH/.venv/lib/python3.11/site-packages/lightgbm/basic.py\", line 1159, in predict\n    preds, nrow = self.__pred_for_np2d(\n                  ^^^^^^^^^^^^^^^^^^^^^\n  File \"/Users/sf/Desktop/FLASH/.venv/lib/python3.11/site-packages/lightgbm/basic.py\", line 1306, in __pred_for_np2d\n    return self.__inner_predict_np2d(\n           ^^^^^^^^^^^^^^^^^^^^^^^^^^\n  File \"/Users/sf/Desktop/FLASH/.venv/lib/python3.11/site-packages/lightgbm/basic.py\", line 1259, in __inner_predict_np2d\n    _safe_call(_LIB.LGBM_BoosterPredictForMat(\n  File \"/Users/sf/Desktop/FLASH/.venv/lib/python3.11/site-packages/lightgbm/basic.py\", line 263, in _safe_call\n    raise LightGBMError(_LIB.LGBM_GetLastError().decode('utf-8'))\nlightgbm.basic.LightGBMError: The number of features in data (32) is not the same as it was in training data (7).\nYou can set ``predict_disable_shape_check=true`` to discard this error, but please be aware what you are doing."}}
{"timestamp": "2025-05-02 20:49:17,536", "level": "ERROR", "message": "Error during capital score prediction: The number of features in data (32) is not the same as it was in training data (4).\nYou can set ``predict_disable_shape_check=true`` to discard this error, but please be aware what you are doing.", "module": "capital", "function": "calculate_capital_score", "line": "34", "process": "44599", "thread": "140704650779584", "exception": {"type": "LightGBMError", "message": "The number of features in data (32) is not the same as it was in training data (4).\nYou can set ``predict_disable_shape_check=true`` to discard this error, but please be aware what you are doing.", "traceback": "Traceback (most recent call last):\n  File \"/Users/sf/Desktop/FLASH/flashcamp/backend/app/engines/capital.py\", line 27, in calculate_capital_score\n    raw_prediction = _model.predict(X)\n                     ^^^^^^^^^^^^^^^^^\n  File \"/Users/sf/Desktop/FLASH/.venv/lib/python3.11/site-packages/lightgbm/basic.py\", line 4453, in predict\n    return predictor.predict(\n           ^^^^^^^^^^^^^^^^^^\n  File \"/Users/sf/Desktop/FLASH/.venv/lib/python3.11/site-packages/lightgbm/basic.py\", line 1159, in predict\n    preds, nrow = self.__pred_for_np2d(\n                  ^^^^^^^^^^^^^^^^^^^^^\n  File \"/Users/sf/Desktop/FLASH/.venv/lib/python3.11/site-packages/lightgbm/basic.py\", line 1306, in __pred_for_np2d\n    return self.__inner_predict_np2d(\n           ^^^^^^^^^^^^^^^^^^^^^^^^^^\n  File \"/Users/sf/Desktop/FLASH/.venv/lib/python3.11/site-packages/lightgbm/basic.py\", line 1259, in __inner_predict_np2d\n    _safe_call(_LIB.LGBM_BoosterPredictForMat(\n  File \"/Users/sf/Desktop/FLASH/.venv/lib/python3.11/site-packages/lightgbm/basic.py\", line 263, in _safe_call\n    raise LightGBMError(_LIB.LGBM_GetLastError().decode('utf-8'))\nlightgbm.basic.LightGBMError: The number of features in data (32) is not the same as it was in training data (4).\nYou can set ``predict_disable_shape_check=true`` to discard this error, but please be aware what you are doing."}}
{"timestamp": "2025-05-02 20:49:17,541", "level": "ERROR", "message": "Error calculating pillar scores: unsupported operand type(s) for /=: 'tuple' and 'int'", "module": "analysis", "function": "pillar_scores", "line": "106", "process": "44599", "thread": "140704650779584", "exception": {"type": "TypeError", "message": "unsupported operand type(s) for /=: 'tuple' and 'int'", "traceback": "Traceback (most recent call last):\n  File \"/Users/sf/Desktop/FLASH/flashcamp/backend/analysis.py\", line 89, in pillar_scores\n    people_score /= 10\nTypeError: unsupported operand type(s) for /=: 'tuple' and 'int'"}}
{"timestamp": "2025-05-02 20:49:17,544", "level": "ERROR", "message": "Error loading model: [Errno 2] No such file or directory: '/mnt/data/success_xgb.joblib'", "module": "ml", "function": "_load_model", "line": "55", "process": "44599", "thread": "140704650779584"}
{"timestamp": "2025-05-02 21:01:43,442", "level": "ERROR", "message": "Error calculating pillar scores: unsupported operand type(s) for /=: 'tuple' and 'int'", "module": "analysis", "function": "pillar_scores", "line": "106", "process": "45444", "thread": "140704650779584", "exception": {"type": "TypeError", "message": "unsupported operand type(s) for /=: 'tuple' and 'int'", "traceback": "Traceback (most recent call last):\n  File \"/Users/sf/Desktop/FLASH/flashcamp/backend/analysis.py\", line 89, in pillar_scores\n    people_score /= 10\nTypeError: unsupported operand type(s) for /=: 'tuple' and 'int'"}}
{"timestamp": "2025-05-02 21:01:43,445", "level": "ERROR", "message": "Error loading model: [Errno 2] No such file or directory: '/mnt/data/success_xgb.joblib'", "module": "ml", "function": "_load_model", "line": "55", "process": "45444", "thread": "140704650779584"}
{"timestamp": "2025-05-02 21:02:16,927", "level": "ERROR", "message": "Error loading model: [Errno 2] No such file or directory: '/mnt/data/success_xgb.joblib'", "module": "ml", "function": "_load_model", "line": "55", "process": "45593", "thread": "140704650779584"}
{"timestamp": "2025-05-02 21:05:53,054", "level": "ERROR", "message": "Error loading model: [Errno 2] No such file or directory: '/mnt/data/success_xgb.joblib'", "module": "ml", "function": "_load_model", "line": "55", "process": "45593", "thread": "140704650779584"}
{"timestamp": "2025-05-02 21:07:22,992", "level": "ERROR", "message": "Error loading model: [Errno 2] No such file or directory: '/mnt/data/success_xgb.joblib'", "module": "ml", "function": "_load_model", "line": "55", "process": "45593", "thread": "140704650779584"}
{"timestamp": "2025-05-02 21:08:27,728", "level": "ERROR", "message": "Error during market score prediction: 'Booster' object has no attribute 'predict_proba'", "module": "market", "function": "calculate_market_score", "line": "38", "process": "46205", "thread": "140704650779584", "exception": {"type": "AttributeError", "message": "'Booster' object has no attribute 'predict_proba'", "traceback": "Traceback (most recent call last):\n  File \"/Users/sf/Desktop/FLASH/flashcamp/backend/app/engines/market.py\", line 29, in calculate_market_score\n    score = float(_model.predict_proba(X)[0, 1]) # Probability of class 1\n                  ^^^^^^^^^^^^^^^^^^^^\nAttributeError: 'Booster' object has no attribute 'predict_proba'"}}
{"timestamp": "2025-05-02 21:08:27,731", "level": "ERROR", "message": "Error during advantage score prediction: 'Booster' object has no attribute 'predict_proba'", "module": "advantage", "function": "calculate_advantage_score", "line": "36", "process": "46205", "thread": "140704650779584", "exception": {"type": "AttributeError", "message": "'Booster' object has no attribute 'predict_proba'", "traceback": "Traceback (most recent call last):\n  File \"/Users/sf/Desktop/FLASH/flashcamp/backend/app/engines/advantage.py\", line 29, in calculate_advantage_score\n    score = float(_model.predict_proba(X)[0, 1]) # Probability of class 1\n                  ^^^^^^^^^^^^^^^^^^^^\nAttributeError: 'Booster' object has no attribute 'predict_proba'"}}
{"timestamp": "2025-05-02 21:08:27,733", "level": "ERROR", "message": "Error during people score prediction: 'Booster' object has no attribute 'predict_proba'", "module": "people", "function": "calculate_people_score", "line": "36", "process": "46205", "thread": "140704650779584", "exception": {"type": "AttributeError", "message": "'Booster' object has no attribute 'predict_proba'", "traceback": "Traceback (most recent call last):\n  File \"/Users/sf/Desktop/FLASH/flashcamp/backend/app/engines/people.py\", line 29, in calculate_people_score\n    score = float(_model.predict_proba(X)[0, 1]) # Probability of class 1\n                  ^^^^^^^^^^^^^^^^^^^^\nAttributeError: 'Booster' object has no attribute 'predict_proba'"}}
{"timestamp": "2025-05-02 21:08:27,735", "level": "ERROR", "message": "Error during capital score prediction: 'Booster' object has no attribute 'predict_proba'", "module": "capital", "function": "calculate_capital_score", "line": "36", "process": "46205", "thread": "140704650779584", "exception": {"type": "AttributeError", "message": "'Booster' object has no attribute 'predict_proba'", "traceback": "Traceback (most recent call last):\n  File \"/Users/sf/Desktop/FLASH/flashcamp/backend/app/engines/capital.py\", line 29, in calculate_capital_score\n    score = float(_model.predict_proba(X)[0, 1]) # Probability of class 1\n                  ^^^^^^^^^^^^^^^^^^^^\nAttributeError: 'Booster' object has no attribute 'predict_proba'"}}
{"timestamp": "2025-05-02 21:08:27,739", "level": "ERROR", "message": "Error loading model: [Errno 2] No such file or directory: '/mnt/data/success_xgb.joblib'", "module": "ml", "function": "_load_model", "line": "56", "process": "46205", "thread": "140704650779584"}
{"timestamp": "2025-05-02 21:13:10,363", "level": "ERROR", "message": "Error loading model: [Errno 2] No such file or directory: '/mnt/data/success_xgb.joblib'", "module": "ml", "function": "_load_model", "line": "55", "process": "46456", "thread": "140704650779584"}
{"timestamp": "2025-05-02 21:29:39,893", "level": "ERROR", "message": "Error loading model from /mnt/data/success_xgb.joblib: [Errno 2] No such file or directory: '/mnt/data/success_xgb.joblib'", "module": "ml", "function": "_load_model", "line": "57", "process": "47883", "thread": "140704650779584"}
{"timestamp": "2025-05-02 21:30:05,118", "level": "ERROR", "message": "Error in prediction: Feature shape mismatch, expected: 79, got 13", "module": "ml", "function": "predict_success_probability", "line": "136", "process": "48038", "thread": "140704650779584"}
{"timestamp": "2025-05-02 21:30:38,138", "level": "ERROR", "message": "Error in prediction: Feature shape mismatch, expected: 79, got 39", "module": "ml", "function": "predict_success_probability", "line": "143", "process": "48102", "thread": "140704650779584"}
{"timestamp": "2025-05-02 23:42:29,671", "level": "ERROR", "message": "Error calculating pillar scores: The number of features in data (39) is not the same as it was in training data (4).\nYou can set ``predict_disable_shape_check=true`` to discard this error, but please be aware what you are doing.", "module": "analysis", "function": "pillar_scores", "line": "105", "process": "56387", "thread": "140704650779584", "exception": {"type": "LightGBMError", "message": "The number of features in data (39) is not the same as it was in training data (4).\nYou can set ``predict_disable_shape_check=true`` to discard this error, but please be aware what you are doing.", "traceback": "Traceback (most recent call last):\n  File \"/Users/sf/Desktop/FLASH/flashcamp/backend/analysis.py\", line 80, in pillar_scores\n    market_score, _ = calculate_market_score_fn(metrics_data)\n                      ^^^^^^^^^^^^^^^^^^^^^^^^^^^^^^^^^^^^^^^\n  File \"/Users/sf/Desktop/FLASH/flashcamp/backend/app/engines/market.py\", line 26, in calculate_market_score\n    raw_prediction = _model.predict(X)\n                     ^^^^^^^^^^^^^^^^^\n  File \"/Users/sf/Desktop/FLASH/.venv/lib/python3.11/site-packages/lightgbm/basic.py\", line 4453, in predict\n    return predictor.predict(\n           ^^^^^^^^^^^^^^^^^^\n  File \"/Users/sf/Desktop/FLASH/.venv/lib/python3.11/site-packages/lightgbm/basic.py\", line 1159, in predict\n    preds, nrow = self.__pred_for_np2d(\n                  ^^^^^^^^^^^^^^^^^^^^^\n  File \"/Users/sf/Desktop/FLASH/.venv/lib/python3.11/site-packages/lightgbm/basic.py\", line 1306, in __pred_for_np2d\n    return self.__inner_predict_np2d(\n           ^^^^^^^^^^^^^^^^^^^^^^^^^^\n  File \"/Users/sf/Desktop/FLASH/.venv/lib/python3.11/site-packages/lightgbm/basic.py\", line 1259, in __inner_predict_np2d\n    _safe_call(_LIB.LGBM_BoosterPredictForMat(\n  File \"/Users/sf/Desktop/FLASH/.venv/lib/python3.11/site-packages/lightgbm/basic.py\", line 263, in _safe_call\n    raise LightGBMError(_LIB.LGBM_GetLastError().decode('utf-8'))\nlightgbm.basic.LightGBMError: The number of features in data (39) is not the same as it was in training data (4).\nYou can set ``predict_disable_shape_check=true`` to discard this error, but please be aware what you are doing."}}
{"timestamp": "2025-05-02 23:42:29,681", "level": "ERROR", "message": "Error importing engine function _fallback_prediction: module 'flashcamp.backend.app.engines.ml' has no attribute '_fallback_prediction'", "module": "analysis", "function": "_import_engine_function", "line": "54", "process": "56387", "thread": "140704650779584"}
{"timestamp": "2025-05-02 23:42:29,681", "level": "ERROR", "message": "Could not import fallback prediction function!", "module": "analysis", "function": "predict_success", "line": "178", "process": "56387", "thread": "140704650779584"}
{"timestamp": "2025-05-03 00:05:35,317", "level": "ERROR", "message": "Error importing engine function _fallback_prediction: module 'flashcamp.backend.app.engines.ml' has no attribute '_fallback_prediction'", "module": "analysis", "function": "_import_engine_function", "line": "54", "process": "58676", "thread": "140704650779584"}
{"timestamp": "2025-05-03 00:05:35,317", "level": "ERROR", "message": "Could not import fallback prediction function!", "module": "analysis", "function": "predict_success", "line": "178", "process": "58676", "thread": "140704650779584"}
{"timestamp": "2025-05-03 00:05:35,319", "level": "ERROR", "message": "Request failed: 'MetricsInput' object has no attribute 'startup_id'", "module": "main", "function": "request_middleware", "line": "95", "process": "58676", "thread": "140704650779584", "exception": {"type": "AttributeError", "message": "'MetricsInput' object has no attribute 'startup_id'", "traceback": "Traceback (most recent call last):\n  File \"/Users/sf/Desktop/FLASH/.venv/lib/python3.11/site-packages/starlette/middleware/base.py\", line 148, in call_next\n    message = await recv_stream.receive()\n              ^^^^^^^^^^^^^^^^^^^^^^^^^^^\n  File \"/Users/sf/Desktop/FLASH/.venv/lib/python3.11/site-packages/anyio/streams/memory.py\", line 126, in receive\n    raise EndOfStream from None\nanyio.EndOfStream\n\nDuring handling of the above exception, another exception occurred:\n\nTraceback (most recent call last):\n  File \"/Users/sf/Desktop/FLASH/flashcamp/backend/main.py\", line 79, in request_middleware\n    response = await call_next(request)\n               ^^^^^^^^^^^^^^^^^^^^^^^^\n  File \"/Users/sf/Desktop/FLASH/.venv/lib/python3.11/site-packages/starlette/middleware/base.py\", line 156, in call_next\n    raise app_exc\n  File \"/Users/sf/Desktop/FLASH/.venv/lib/python3.11/site-packages/starlette/middleware/base.py\", line 141, in coro\n    await self.app(scope, receive_or_disconnect, send_no_error)\n  File \"/Users/sf/Desktop/FLASH/.venv/lib/python3.11/site-packages/starlette/middleware/base.py\", line 176, in __call__\n    with recv_stream, send_stream, collapse_excgroups():\n  File \"/Users/sf/.pyenv/versions/3.11.7/lib/python3.11/contextlib.py\", line 158, in __exit__\n    self.gen.throw(typ, value, traceback)\n  File \"/Users/sf/Desktop/FLASH/.venv/lib/python3.11/site-packages/starlette/_utils.py\", line 82, in collapse_excgroups\n    raise exc\n  File \"/Users/sf/Desktop/FLASH/.venv/lib/python3.11/site-packages/starlette/middleware/base.py\", line 178, in __call__\n    response = await self.dispatch_func(request, call_next)\n               ^^^^^^^^^^^^^^^^^^^^^^^^^^^^^^^^^^^^^^^^^^^^\n  File \"/Users/sf/Desktop/FLASH/flashcamp/backend/metrics.py\", line 173, in dispatch\n    response = await call_next(request)\n               ^^^^^^^^^^^^^^^^^^^^^^^^\n  File \"/Users/sf/Desktop/FLASH/.venv/lib/python3.11/site-packages/starlette/middleware/base.py\", line 156, in call_next\n    raise app_exc\n  File \"/Users/sf/Desktop/FLASH/.venv/lib/python3.11/site-packages/starlette/middleware/base.py\", line 141, in coro\n    await self.app(scope, receive_or_disconnect, send_no_error)\n  File \"/Users/sf/Desktop/FLASH/.venv/lib/python3.11/site-packages/starlette/middleware/exceptions.py\", line 62, in __call__\n    await wrap_app_handling_exceptions(self.app, conn)(scope, receive, send)\n  File \"/Users/sf/Desktop/FLASH/.venv/lib/python3.11/site-packages/starlette/_exception_handler.py\", line 53, in wrapped_app\n    raise exc\n  File \"/Users/sf/Desktop/FLASH/.venv/lib/python3.11/site-packages/starlette/_exception_handler.py\", line 42, in wrapped_app\n    await app(scope, receive, sender)\n  File \"/Users/sf/Desktop/FLASH/.venv/lib/python3.11/site-packages/starlette/routing.py\", line 714, in __call__\n    await self.middleware_stack(scope, receive, send)\n  File \"/Users/sf/Desktop/FLASH/.venv/lib/python3.11/site-packages/starlette/routing.py\", line 734, in app\n    await route.handle(scope, receive, send)\n  File \"/Users/sf/Desktop/FLASH/.venv/lib/python3.11/site-packages/starlette/routing.py\", line 288, in handle\n    await self.app(scope, receive, send)\n  File \"/Users/sf/Desktop/FLASH/.venv/lib/python3.11/site-packages/starlette/routing.py\", line 76, in app\n    await wrap_app_handling_exceptions(app, request)(scope, receive, send)\n  File \"/Users/sf/Desktop/FLASH/.venv/lib/python3.11/site-packages/starlette/_exception_handler.py\", line 53, in wrapped_app\n    raise exc\n  File \"/Users/sf/Desktop/FLASH/.venv/lib/python3.11/site-packages/starlette/_exception_handler.py\", line 42, in wrapped_app\n    await app(scope, receive, sender)\n  File \"/Users/sf/Desktop/FLASH/.venv/lib/python3.11/site-packages/starlette/routing.py\", line 73, in app\n    response = await f(request)\n               ^^^^^^^^^^^^^^^^\n  File \"/Users/sf/Desktop/FLASH/.venv/lib/python3.11/site-packages/fastapi/routing.py\", line 301, in app\n    raw_response = await run_endpoint_function(\n                   ^^^^^^^^^^^^^^^^^^^^^^^^^^^^\n  File \"/Users/sf/Desktop/FLASH/.venv/lib/python3.11/site-packages/fastapi/routing.py\", line 212, in run_endpoint_function\n    return await dependant.call(**values)\n           ^^^^^^^^^^^^^^^^^^^^^^^^^^^^^^\n  File \"/Users/sf/Desktop/FLASH/flashcamp/backend/main.py\", line 203, in analyze\n    logger.error(f\"Internal server error during analysis for startup_id {metrics.startup_id}: {e}\", exc_info=True)\n                                                                         ^^^^^^^^^^^^^^^^^^\n  File \"/Users/sf/Desktop/FLASH/.venv/lib/python3.11/site-packages/pydantic/main.py\", line 994, in __getattr__\n    raise AttributeError(f'{type(self).__name__!r} object has no attribute {item!r}')\nAttributeError: 'MetricsInput' object has no attribute 'startup_id'"}}
{"timestamp": "2025-05-03 00:08:35,294", "level": "ERROR", "message": "Error importing engine function _fallback_prediction: module 'flashcamp.backend.app.engines.ml' has no attribute '_fallback_prediction'", "module": "analysis", "function": "_import_engine_function", "line": "54", "process": "59080", "thread": "140704650779584"}
{"timestamp": "2025-05-03 00:08:35,295", "level": "ERROR", "message": "Could not import fallback prediction function!", "module": "analysis", "function": "predict_success", "line": "178", "process": "59080", "thread": "140704650779584"}
{"timestamp": "2025-05-03 00:12:02,097", "level": "ERROR", "message": "Error importing engine function _fallback_prediction: module 'flashcamp.backend.app.engines.ml' has no attribute '_fallback_prediction'", "module": "analysis", "function": "_import_engine_function", "line": "54", "process": "1", "thread": "140527905106816"}
{"timestamp": "2025-05-03 00:12:02,099", "level": "ERROR", "message": "Could not import fallback prediction function!", "module": "analysis", "function": "predict_success", "line": "178", "process": "1", "thread": "140527905106816"}
{"timestamp": "2025-05-03 00:12:18,769", "level": "ERROR", "message": "Error importing engine function _fallback_prediction: module 'flashcamp.backend.app.engines.ml' has no attribute '_fallback_prediction'", "module": "analysis", "function": "_import_engine_function", "line": "54", "process": "1", "thread": "140527905106816"}
{"timestamp": "2025-05-03 00:12:18,770", "level": "ERROR", "message": "Could not import fallback prediction function!", "module": "analysis", "function": "predict_success", "line": "178", "process": "1", "thread": "140527905106816"}
{"timestamp": "2025-05-03 09:56:11,999", "level": "ERROR", "message": "Error importing engine function _fallback_prediction: module 'flashcamp.backend.app.engines.ml' has no attribute '_fallback_prediction'", "module": "analysis", "function": "_import_engine_function", "line": "54", "process": "11695", "thread": "140704650779584"}
{"timestamp": "2025-05-03 09:56:11,999", "level": "ERROR", "message": "Could not import fallback prediction function!", "module": "analysis", "function": "predict_success", "line": "178", "process": "11695", "thread": "140704650779584"}
{"timestamp": "2025-05-03 09:56:39,554", "level": "ERROR", "message": "Error importing engine function _fallback_prediction: module 'flashcamp.backend.app.engines.ml' has no attribute '_fallback_prediction'", "module": "analysis", "function": "_import_engine_function", "line": "54", "process": "11742", "thread": "140704650779584"}
{"timestamp": "2025-05-03 09:56:39,554", "level": "ERROR", "message": "Could not import fallback prediction function!", "module": "analysis", "function": "predict_success", "line": "178", "process": "11742", "thread": "140704650779584"}
{"timestamp": "2025-05-03 10:23:04,475", "level": "ERROR", "message": "Error loading model /app/flashcamp/models/pillar/capital_lgbm.joblib: libgomp.so.1: cannot open shared object file: No such file or directory", "module": "model_loader", "function": "load_model", "line": "43", "process": "1", "thread": "139756757089152", "exception": {"type": "OSError", "message": "libgomp.so.1: cannot open shared object file: No such file or directory", "traceback": "Traceback (most recent call last):\n  File \"/app/flashcamp/backend/model_loader.py\", line 28, in load_model\n    model = joblib.load(absolute_path)\n            ^^^^^^^^^^^^^^^^^^^^^^^^^^\n  File \"/root/.local/lib/python3.11/site-packages/joblib/numpy_pickle.py\", line 658, in load\n    obj = _unpickle(fobj, filename, mmap_mode)\n          ^^^^^^^^^^^^^^^^^^^^^^^^^^^^^^^^^^^^\n  File \"/root/.local/lib/python3.11/site-packages/joblib/numpy_pickle.py\", line 577, in _unpickle\n    obj = unpickler.load()\n          ^^^^^^^^^^^^^^^^\n  File \"/usr/local/lib/python3.11/pickle.py\", line 1213, in load\n    dispatch[key[0]](self)\n  File \"/usr/local/lib/python3.11/pickle.py\", line 1538, in load_stack_global\n    self.append(self.find_class(module, name))\n                ^^^^^^^^^^^^^^^^^^^^^^^^^^^^^\n  File \"/usr/local/lib/python3.11/pickle.py\", line 1580, in find_class\n    __import__(module, level=0)\n  File \"/root/.local/lib/python3.11/site-packages/lightgbm/__init__.py\", line 8, in <module>\n    from .basic import Booster, Dataset, Sequence, register_logger\n  File \"/root/.local/lib/python3.11/site-packages/lightgbm/basic.py\", line 247, in <module>\n    _LIB = _load_lib()\n           ^^^^^^^^^^^\n  File \"/root/.local/lib/python3.11/site-packages/lightgbm/basic.py\", line 232, in _load_lib\n    lib = ctypes.cdll.LoadLibrary(lib_path[0])\n          ^^^^^^^^^^^^^^^^^^^^^^^^^^^^^^^^^^^^\n  File \"/usr/local/lib/python3.11/ctypes/__init__.py\", line 454, in LoadLibrary\n    return self._dlltype(name)\n           ^^^^^^^^^^^^^^^^^^^\n  File \"/usr/local/lib/python3.11/ctypes/__init__.py\", line 376, in __init__\n    self._handle = _dlopen(self._name, mode)\n                   ^^^^^^^^^^^^^^^^^^^^^^^^^\nOSError: libgomp.so.1: cannot open shared object file: No such file or directory"}}
{"timestamp": "2025-05-03 10:23:04,501", "level": "ERROR", "message": "Error loading model /app/flashcamp/models/pillar/advantage_lgbm.joblib: libgomp.so.1: cannot open shared object file: No such file or directory", "module": "model_loader", "function": "load_model", "line": "43", "process": "1", "thread": "139756757089152", "exception": {"type": "OSError", "message": "libgomp.so.1: cannot open shared object file: No such file or directory", "traceback": "Traceback (most recent call last):\n  File \"/app/flashcamp/backend/model_loader.py\", line 28, in load_model\n    model = joblib.load(absolute_path)\n            ^^^^^^^^^^^^^^^^^^^^^^^^^^\n  File \"/root/.local/lib/python3.11/site-packages/joblib/numpy_pickle.py\", line 658, in load\n    obj = _unpickle(fobj, filename, mmap_mode)\n          ^^^^^^^^^^^^^^^^^^^^^^^^^^^^^^^^^^^^\n  File \"/root/.local/lib/python3.11/site-packages/joblib/numpy_pickle.py\", line 577, in _unpickle\n    obj = unpickler.load()\n          ^^^^^^^^^^^^^^^^\n  File \"/usr/local/lib/python3.11/pickle.py\", line 1213, in load\n    dispatch[key[0]](self)\n  File \"/usr/local/lib/python3.11/pickle.py\", line 1538, in load_stack_global\n    self.append(self.find_class(module, name))\n                ^^^^^^^^^^^^^^^^^^^^^^^^^^^^^\n  File \"/usr/local/lib/python3.11/pickle.py\", line 1580, in find_class\n    __import__(module, level=0)\n  File \"/root/.local/lib/python3.11/site-packages/lightgbm/__init__.py\", line 8, in <module>\n    from .basic import Booster, Dataset, Sequence, register_logger\n  File \"/root/.local/lib/python3.11/site-packages/lightgbm/basic.py\", line 247, in <module>\n    _LIB = _load_lib()\n           ^^^^^^^^^^^\n  File \"/root/.local/lib/python3.11/site-packages/lightgbm/basic.py\", line 232, in _load_lib\n    lib = ctypes.cdll.LoadLibrary(lib_path[0])\n          ^^^^^^^^^^^^^^^^^^^^^^^^^^^^^^^^^^^^\n  File \"/usr/local/lib/python3.11/ctypes/__init__.py\", line 454, in LoadLibrary\n    return self._dlltype(name)\n           ^^^^^^^^^^^^^^^^^^^\n  File \"/usr/local/lib/python3.11/ctypes/__init__.py\", line 376, in __init__\n    self._handle = _dlopen(self._name, mode)\n                   ^^^^^^^^^^^^^^^^^^^^^^^^^\nOSError: libgomp.so.1: cannot open shared object file: No such file or directory"}}
{"timestamp": "2025-05-03 10:23:04,515", "level": "ERROR", "message": "Error loading model /app/flashcamp/models/pillar/market_lgbm.joblib: libgomp.so.1: cannot open shared object file: No such file or directory", "module": "model_loader", "function": "load_model", "line": "43", "process": "1", "thread": "139756757089152", "exception": {"type": "OSError", "message": "libgomp.so.1: cannot open shared object file: No such file or directory", "traceback": "Traceback (most recent call last):\n  File \"/app/flashcamp/backend/model_loader.py\", line 28, in load_model\n    model = joblib.load(absolute_path)\n            ^^^^^^^^^^^^^^^^^^^^^^^^^^\n  File \"/root/.local/lib/python3.11/site-packages/joblib/numpy_pickle.py\", line 658, in load\n    obj = _unpickle(fobj, filename, mmap_mode)\n          ^^^^^^^^^^^^^^^^^^^^^^^^^^^^^^^^^^^^\n  File \"/root/.local/lib/python3.11/site-packages/joblib/numpy_pickle.py\", line 577, in _unpickle\n    obj = unpickler.load()\n          ^^^^^^^^^^^^^^^^\n  File \"/usr/local/lib/python3.11/pickle.py\", line 1213, in load\n    dispatch[key[0]](self)\n  File \"/usr/local/lib/python3.11/pickle.py\", line 1538, in load_stack_global\n    self.append(self.find_class(module, name))\n                ^^^^^^^^^^^^^^^^^^^^^^^^^^^^^\n  File \"/usr/local/lib/python3.11/pickle.py\", line 1580, in find_class\n    __import__(module, level=0)\n  File \"/root/.local/lib/python3.11/site-packages/lightgbm/__init__.py\", line 8, in <module>\n    from .basic import Booster, Dataset, Sequence, register_logger\n  File \"/root/.local/lib/python3.11/site-packages/lightgbm/basic.py\", line 247, in <module>\n    _LIB = _load_lib()\n           ^^^^^^^^^^^\n  File \"/root/.local/lib/python3.11/site-packages/lightgbm/basic.py\", line 232, in _load_lib\n    lib = ctypes.cdll.LoadLibrary(lib_path[0])\n          ^^^^^^^^^^^^^^^^^^^^^^^^^^^^^^^^^^^^\n  File \"/usr/local/lib/python3.11/ctypes/__init__.py\", line 454, in LoadLibrary\n    return self._dlltype(name)\n           ^^^^^^^^^^^^^^^^^^^\n  File \"/usr/local/lib/python3.11/ctypes/__init__.py\", line 376, in __init__\n    self._handle = _dlopen(self._name, mode)\n                   ^^^^^^^^^^^^^^^^^^^^^^^^^\nOSError: libgomp.so.1: cannot open shared object file: No such file or directory"}}
{"timestamp": "2025-05-03 10:23:04,528", "level": "ERROR", "message": "Error loading model /app/flashcamp/models/pillar/people_lgbm.joblib: libgomp.so.1: cannot open shared object file: No such file or directory", "module": "model_loader", "function": "load_model", "line": "43", "process": "1", "thread": "139756757089152", "exception": {"type": "OSError", "message": "libgomp.so.1: cannot open shared object file: No such file or directory", "traceback": "Traceback (most recent call last):\n  File \"/app/flashcamp/backend/model_loader.py\", line 28, in load_model\n    model = joblib.load(absolute_path)\n            ^^^^^^^^^^^^^^^^^^^^^^^^^^\n  File \"/root/.local/lib/python3.11/site-packages/joblib/numpy_pickle.py\", line 658, in load\n    obj = _unpickle(fobj, filename, mmap_mode)\n          ^^^^^^^^^^^^^^^^^^^^^^^^^^^^^^^^^^^^\n  File \"/root/.local/lib/python3.11/site-packages/joblib/numpy_pickle.py\", line 577, in _unpickle\n    obj = unpickler.load()\n          ^^^^^^^^^^^^^^^^\n  File \"/usr/local/lib/python3.11/pickle.py\", line 1213, in load\n    dispatch[key[0]](self)\n  File \"/usr/local/lib/python3.11/pickle.py\", line 1538, in load_stack_global\n    self.append(self.find_class(module, name))\n                ^^^^^^^^^^^^^^^^^^^^^^^^^^^^^\n  File \"/usr/local/lib/python3.11/pickle.py\", line 1580, in find_class\n    __import__(module, level=0)\n  File \"/root/.local/lib/python3.11/site-packages/lightgbm/__init__.py\", line 8, in <module>\n    from .basic import Booster, Dataset, Sequence, register_logger\n  File \"/root/.local/lib/python3.11/site-packages/lightgbm/basic.py\", line 247, in <module>\n    _LIB = _load_lib()\n           ^^^^^^^^^^^\n  File \"/root/.local/lib/python3.11/site-packages/lightgbm/basic.py\", line 232, in _load_lib\n    lib = ctypes.cdll.LoadLibrary(lib_path[0])\n          ^^^^^^^^^^^^^^^^^^^^^^^^^^^^^^^^^^^^\n  File \"/usr/local/lib/python3.11/ctypes/__init__.py\", line 454, in LoadLibrary\n    return self._dlltype(name)\n           ^^^^^^^^^^^^^^^^^^^\n  File \"/usr/local/lib/python3.11/ctypes/__init__.py\", line 376, in __init__\n    self._handle = _dlopen(self._name, mode)\n                   ^^^^^^^^^^^^^^^^^^^^^^^^^\nOSError: libgomp.so.1: cannot open shared object file: No such file or directory"}}
{"timestamp": "2025-05-03 10:23:04,539", "level": "ERROR", "message": "Market model not loaded.", "module": "market", "function": "calculate_market_score", "line": "19", "process": "1", "thread": "139756757089152"}
{"timestamp": "2025-05-03 10:23:04,541", "level": "ERROR", "message": "Error calculating pillar scores: Market model not loaded or unavailable", "module": "analysis", "function": "pillar_scores", "line": "105", "process": "1", "thread": "139756757089152", "exception": {"type": "ValueError", "message": "Market model not loaded or unavailable", "traceback": "Traceback (most recent call last):\n  File \"/app/flashcamp/backend/analysis.py\", line 80, in pillar_scores\n    market_score, _ = calculate_market_score_fn(metrics_data)\n                      ^^^^^^^^^^^^^^^^^^^^^^^^^^^^^^^^^^^^^^^\n  File \"/app/flashcamp/backend/app/engines/market.py\", line 20, in calculate_market_score\n    raise ValueError(\"Market model not loaded or unavailable\")\nValueError: Market model not loaded or unavailable"}}
{"timestamp": "2025-05-03 10:23:04,545", "level": "ERROR", "message": "Error importing engine function _fallback_prediction: module 'flashcamp.backend.app.engines.ml' has no attribute '_fallback_prediction'", "module": "analysis", "function": "_import_engine_function", "line": "54", "process": "1", "thread": "139756757089152"}
{"timestamp": "2025-05-03 10:23:04,547", "level": "ERROR", "message": "Could not import fallback prediction function!", "module": "analysis", "function": "predict_success", "line": "178", "process": "1", "thread": "139756757089152"}
{"timestamp": "2025-05-03 13:20:14,190", "level": "ERROR", "message": "Error loading model /app/flashcamp/models/pillar/capital_lgbm.joblib: libgomp.so.1: cannot open shared object file: No such file or directory", "module": "model_loader", "function": "load_model", "line": "43", "process": "1", "thread": "140466041285504", "exception": {"type": "OSError", "message": "libgomp.so.1: cannot open shared object file: No such file or directory", "traceback": "Traceback (most recent call last):\n  File \"/app/flashcamp/backend/model_loader.py\", line 28, in load_model\n    model = joblib.load(absolute_path)\n            ^^^^^^^^^^^^^^^^^^^^^^^^^^\n  File \"/root/.local/lib/python3.11/site-packages/joblib/numpy_pickle.py\", line 658, in load\n    obj = _unpickle(fobj, filename, mmap_mode)\n          ^^^^^^^^^^^^^^^^^^^^^^^^^^^^^^^^^^^^\n  File \"/root/.local/lib/python3.11/site-packages/joblib/numpy_pickle.py\", line 577, in _unpickle\n    obj = unpickler.load()\n          ^^^^^^^^^^^^^^^^\n  File \"/usr/local/lib/python3.11/pickle.py\", line 1213, in load\n    dispatch[key[0]](self)\n  File \"/usr/local/lib/python3.11/pickle.py\", line 1538, in load_stack_global\n    self.append(self.find_class(module, name))\n                ^^^^^^^^^^^^^^^^^^^^^^^^^^^^^\n  File \"/usr/local/lib/python3.11/pickle.py\", line 1580, in find_class\n    __import__(module, level=0)\n  File \"/root/.local/lib/python3.11/site-packages/lightgbm/__init__.py\", line 8, in <module>\n    from .basic import Booster, Dataset, Sequence, register_logger\n  File \"/root/.local/lib/python3.11/site-packages/lightgbm/basic.py\", line 247, in <module>\n    _LIB = _load_lib()\n           ^^^^^^^^^^^\n  File \"/root/.local/lib/python3.11/site-packages/lightgbm/basic.py\", line 232, in _load_lib\n    lib = ctypes.cdll.LoadLibrary(lib_path[0])\n          ^^^^^^^^^^^^^^^^^^^^^^^^^^^^^^^^^^^^\n  File \"/usr/local/lib/python3.11/ctypes/__init__.py\", line 454, in LoadLibrary\n    return self._dlltype(name)\n           ^^^^^^^^^^^^^^^^^^^\n  File \"/usr/local/lib/python3.11/ctypes/__init__.py\", line 376, in __init__\n    self._handle = _dlopen(self._name, mode)\n                   ^^^^^^^^^^^^^^^^^^^^^^^^^\nOSError: libgomp.so.1: cannot open shared object file: No such file or directory"}}
{"timestamp": "2025-05-03 13:20:14,235", "level": "ERROR", "message": "Error loading model /app/flashcamp/models/pillar/advantage_lgbm.joblib: libgomp.so.1: cannot open shared object file: No such file or directory", "module": "model_loader", "function": "load_model", "line": "43", "process": "1", "thread": "140466041285504", "exception": {"type": "OSError", "message": "libgomp.so.1: cannot open shared object file: No such file or directory", "traceback": "Traceback (most recent call last):\n  File \"/app/flashcamp/backend/model_loader.py\", line 28, in load_model\n    model = joblib.load(absolute_path)\n            ^^^^^^^^^^^^^^^^^^^^^^^^^^\n  File \"/root/.local/lib/python3.11/site-packages/joblib/numpy_pickle.py\", line 658, in load\n    obj = _unpickle(fobj, filename, mmap_mode)\n          ^^^^^^^^^^^^^^^^^^^^^^^^^^^^^^^^^^^^\n  File \"/root/.local/lib/python3.11/site-packages/joblib/numpy_pickle.py\", line 577, in _unpickle\n    obj = unpickler.load()\n          ^^^^^^^^^^^^^^^^\n  File \"/usr/local/lib/python3.11/pickle.py\", line 1213, in load\n    dispatch[key[0]](self)\n  File \"/usr/local/lib/python3.11/pickle.py\", line 1538, in load_stack_global\n    self.append(self.find_class(module, name))\n                ^^^^^^^^^^^^^^^^^^^^^^^^^^^^^\n  File \"/usr/local/lib/python3.11/pickle.py\", line 1580, in find_class\n    __import__(module, level=0)\n  File \"/root/.local/lib/python3.11/site-packages/lightgbm/__init__.py\", line 8, in <module>\n    from .basic import Booster, Dataset, Sequence, register_logger\n  File \"/root/.local/lib/python3.11/site-packages/lightgbm/basic.py\", line 247, in <module>\n    _LIB = _load_lib()\n           ^^^^^^^^^^^\n  File \"/root/.local/lib/python3.11/site-packages/lightgbm/basic.py\", line 232, in _load_lib\n    lib = ctypes.cdll.LoadLibrary(lib_path[0])\n          ^^^^^^^^^^^^^^^^^^^^^^^^^^^^^^^^^^^^\n  File \"/usr/local/lib/python3.11/ctypes/__init__.py\", line 454, in LoadLibrary\n    return self._dlltype(name)\n           ^^^^^^^^^^^^^^^^^^^\n  File \"/usr/local/lib/python3.11/ctypes/__init__.py\", line 376, in __init__\n    self._handle = _dlopen(self._name, mode)\n                   ^^^^^^^^^^^^^^^^^^^^^^^^^\nOSError: libgomp.so.1: cannot open shared object file: No such file or directory"}}
{"timestamp": "2025-05-03 13:20:14,260", "level": "ERROR", "message": "Error loading model /app/flashcamp/models/pillar/market_lgbm.joblib: libgomp.so.1: cannot open shared object file: No such file or directory", "module": "model_loader", "function": "load_model", "line": "43", "process": "1", "thread": "140466041285504", "exception": {"type": "OSError", "message": "libgomp.so.1: cannot open shared object file: No such file or directory", "traceback": "Traceback (most recent call last):\n  File \"/app/flashcamp/backend/model_loader.py\", line 28, in load_model\n    model = joblib.load(absolute_path)\n            ^^^^^^^^^^^^^^^^^^^^^^^^^^\n  File \"/root/.local/lib/python3.11/site-packages/joblib/numpy_pickle.py\", line 658, in load\n    obj = _unpickle(fobj, filename, mmap_mode)\n          ^^^^^^^^^^^^^^^^^^^^^^^^^^^^^^^^^^^^\n  File \"/root/.local/lib/python3.11/site-packages/joblib/numpy_pickle.py\", line 577, in _unpickle\n    obj = unpickler.load()\n          ^^^^^^^^^^^^^^^^\n  File \"/usr/local/lib/python3.11/pickle.py\", line 1213, in load\n    dispatch[key[0]](self)\n  File \"/usr/local/lib/python3.11/pickle.py\", line 1538, in load_stack_global\n    self.append(self.find_class(module, name))\n                ^^^^^^^^^^^^^^^^^^^^^^^^^^^^^\n  File \"/usr/local/lib/python3.11/pickle.py\", line 1580, in find_class\n    __import__(module, level=0)\n  File \"/root/.local/lib/python3.11/site-packages/lightgbm/__init__.py\", line 8, in <module>\n    from .basic import Booster, Dataset, Sequence, register_logger\n  File \"/root/.local/lib/python3.11/site-packages/lightgbm/basic.py\", line 247, in <module>\n    _LIB = _load_lib()\n           ^^^^^^^^^^^\n  File \"/root/.local/lib/python3.11/site-packages/lightgbm/basic.py\", line 232, in _load_lib\n    lib = ctypes.cdll.LoadLibrary(lib_path[0])\n          ^^^^^^^^^^^^^^^^^^^^^^^^^^^^^^^^^^^^\n  File \"/usr/local/lib/python3.11/ctypes/__init__.py\", line 454, in LoadLibrary\n    return self._dlltype(name)\n           ^^^^^^^^^^^^^^^^^^^\n  File \"/usr/local/lib/python3.11/ctypes/__init__.py\", line 376, in __init__\n    self._handle = _dlopen(self._name, mode)\n                   ^^^^^^^^^^^^^^^^^^^^^^^^^\nOSError: libgomp.so.1: cannot open shared object file: No such file or directory"}}
{"timestamp": "2025-05-03 13:20:14,446", "level": "ERROR", "message": "Error loading model /app/flashcamp/models/pillar/people_lgbm.joblib: libgomp.so.1: cannot open shared object file: No such file or directory", "module": "model_loader", "function": "load_model", "line": "43", "process": "1", "thread": "140466041285504", "exception": {"type": "OSError", "message": "libgomp.so.1: cannot open shared object file: No such file or directory", "traceback": "Traceback (most recent call last):\n  File \"/app/flashcamp/backend/model_loader.py\", line 28, in load_model\n    model = joblib.load(absolute_path)\n            ^^^^^^^^^^^^^^^^^^^^^^^^^^\n  File \"/root/.local/lib/python3.11/site-packages/joblib/numpy_pickle.py\", line 658, in load\n    obj = _unpickle(fobj, filename, mmap_mode)\n          ^^^^^^^^^^^^^^^^^^^^^^^^^^^^^^^^^^^^\n  File \"/root/.local/lib/python3.11/site-packages/joblib/numpy_pickle.py\", line 577, in _unpickle\n    obj = unpickler.load()\n          ^^^^^^^^^^^^^^^^\n  File \"/usr/local/lib/python3.11/pickle.py\", line 1213, in load\n    dispatch[key[0]](self)\n  File \"/usr/local/lib/python3.11/pickle.py\", line 1538, in load_stack_global\n    self.append(self.find_class(module, name))\n                ^^^^^^^^^^^^^^^^^^^^^^^^^^^^^\n  File \"/usr/local/lib/python3.11/pickle.py\", line 1580, in find_class\n    __import__(module, level=0)\n  File \"/root/.local/lib/python3.11/site-packages/lightgbm/__init__.py\", line 8, in <module>\n    from .basic import Booster, Dataset, Sequence, register_logger\n  File \"/root/.local/lib/python3.11/site-packages/lightgbm/basic.py\", line 247, in <module>\n    _LIB = _load_lib()\n           ^^^^^^^^^^^\n  File \"/root/.local/lib/python3.11/site-packages/lightgbm/basic.py\", line 232, in _load_lib\n    lib = ctypes.cdll.LoadLibrary(lib_path[0])\n          ^^^^^^^^^^^^^^^^^^^^^^^^^^^^^^^^^^^^\n  File \"/usr/local/lib/python3.11/ctypes/__init__.py\", line 454, in LoadLibrary\n    return self._dlltype(name)\n           ^^^^^^^^^^^^^^^^^^^\n  File \"/usr/local/lib/python3.11/ctypes/__init__.py\", line 376, in __init__\n    self._handle = _dlopen(self._name, mode)\n                   ^^^^^^^^^^^^^^^^^^^^^^^^^\nOSError: libgomp.so.1: cannot open shared object file: No such file or directory"}}
{"timestamp": "2025-05-03 13:20:14,465", "level": "ERROR", "message": "Market model not loaded.", "module": "market", "function": "calculate_market_score", "line": "19", "process": "1", "thread": "140466041285504"}
{"timestamp": "2025-05-03 13:20:14,469", "level": "ERROR", "message": "Error calculating pillar scores: Market model not loaded or unavailable", "module": "analysis", "function": "pillar_scores", "line": "105", "process": "1", "thread": "140466041285504", "exception": {"type": "ValueError", "message": "Market model not loaded or unavailable", "traceback": "Traceback (most recent call last):\n  File \"/app/flashcamp/backend/analysis.py\", line 80, in pillar_scores\n    market_score, _ = calculate_market_score_fn(metrics_data)\n                      ^^^^^^^^^^^^^^^^^^^^^^^^^^^^^^^^^^^^^^^\n  File \"/app/flashcamp/backend/app/engines/market.py\", line 20, in calculate_market_score\n    raise ValueError(\"Market model not loaded or unavailable\")\nValueError: Market model not loaded or unavailable"}}
{"timestamp": "2025-05-03 13:20:14,478", "level": "ERROR", "message": "Error importing engine function _fallback_prediction: module 'flashcamp.backend.app.engines.ml' has no attribute '_fallback_prediction'", "module": "analysis", "function": "_import_engine_function", "line": "54", "process": "1", "thread": "140466041285504"}
{"timestamp": "2025-05-03 13:20:14,479", "level": "ERROR", "message": "Could not import fallback prediction function!", "module": "analysis", "function": "predict_success", "line": "178", "process": "1", "thread": "140466041285504"}
{"timestamp": "2025-05-03 13:34:13,710", "level": "ERROR", "message": "Error loading model /app/flashcamp/models/pillar/capital_lgbm.joblib: libgomp.so.1: cannot open shared object file: No such file or directory", "module": "model_loader", "function": "load_model", "line": "43", "process": "1", "thread": "140320016731008", "exception": {"type": "OSError", "message": "libgomp.so.1: cannot open shared object file: No such file or directory", "traceback": "Traceback (most recent call last):\n  File \"/app/flashcamp/backend/model_loader.py\", line 28, in load_model\n    model = joblib.load(absolute_path)\n            ^^^^^^^^^^^^^^^^^^^^^^^^^^\n  File \"/root/.local/lib/python3.11/site-packages/joblib/numpy_pickle.py\", line 658, in load\n    obj = _unpickle(fobj, filename, mmap_mode)\n          ^^^^^^^^^^^^^^^^^^^^^^^^^^^^^^^^^^^^\n  File \"/root/.local/lib/python3.11/site-packages/joblib/numpy_pickle.py\", line 577, in _unpickle\n    obj = unpickler.load()\n          ^^^^^^^^^^^^^^^^\n  File \"/usr/local/lib/python3.11/pickle.py\", line 1213, in load\n    dispatch[key[0]](self)\n  File \"/usr/local/lib/python3.11/pickle.py\", line 1538, in load_stack_global\n    self.append(self.find_class(module, name))\n                ^^^^^^^^^^^^^^^^^^^^^^^^^^^^^\n  File \"/usr/local/lib/python3.11/pickle.py\", line 1580, in find_class\n    __import__(module, level=0)\n  File \"/root/.local/lib/python3.11/site-packages/lightgbm/__init__.py\", line 8, in <module>\n    from .basic import Booster, Dataset, Sequence, register_logger\n  File \"/root/.local/lib/python3.11/site-packages/lightgbm/basic.py\", line 247, in <module>\n    _LIB = _load_lib()\n           ^^^^^^^^^^^\n  File \"/root/.local/lib/python3.11/site-packages/lightgbm/basic.py\", line 232, in _load_lib\n    lib = ctypes.cdll.LoadLibrary(lib_path[0])\n          ^^^^^^^^^^^^^^^^^^^^^^^^^^^^^^^^^^^^\n  File \"/usr/local/lib/python3.11/ctypes/__init__.py\", line 454, in LoadLibrary\n    return self._dlltype(name)\n           ^^^^^^^^^^^^^^^^^^^\n  File \"/usr/local/lib/python3.11/ctypes/__init__.py\", line 376, in __init__\n    self._handle = _dlopen(self._name, mode)\n                   ^^^^^^^^^^^^^^^^^^^^^^^^^\nOSError: libgomp.so.1: cannot open shared object file: No such file or directory"}}
{"timestamp": "2025-05-03 13:34:13,737", "level": "ERROR", "message": "Error loading model /app/flashcamp/models/pillar/advantage_lgbm.joblib: libgomp.so.1: cannot open shared object file: No such file or directory", "module": "model_loader", "function": "load_model", "line": "43", "process": "1", "thread": "140320016731008", "exception": {"type": "OSError", "message": "libgomp.so.1: cannot open shared object file: No such file or directory", "traceback": "Traceback (most recent call last):\n  File \"/app/flashcamp/backend/model_loader.py\", line 28, in load_model\n    model = joblib.load(absolute_path)\n            ^^^^^^^^^^^^^^^^^^^^^^^^^^\n  File \"/root/.local/lib/python3.11/site-packages/joblib/numpy_pickle.py\", line 658, in load\n    obj = _unpickle(fobj, filename, mmap_mode)\n          ^^^^^^^^^^^^^^^^^^^^^^^^^^^^^^^^^^^^\n  File \"/root/.local/lib/python3.11/site-packages/joblib/numpy_pickle.py\", line 577, in _unpickle\n    obj = unpickler.load()\n          ^^^^^^^^^^^^^^^^\n  File \"/usr/local/lib/python3.11/pickle.py\", line 1213, in load\n    dispatch[key[0]](self)\n  File \"/usr/local/lib/python3.11/pickle.py\", line 1538, in load_stack_global\n    self.append(self.find_class(module, name))\n                ^^^^^^^^^^^^^^^^^^^^^^^^^^^^^\n  File \"/usr/local/lib/python3.11/pickle.py\", line 1580, in find_class\n    __import__(module, level=0)\n  File \"/root/.local/lib/python3.11/site-packages/lightgbm/__init__.py\", line 8, in <module>\n    from .basic import Booster, Dataset, Sequence, register_logger\n  File \"/root/.local/lib/python3.11/site-packages/lightgbm/basic.py\", line 247, in <module>\n    _LIB = _load_lib()\n           ^^^^^^^^^^^\n  File \"/root/.local/lib/python3.11/site-packages/lightgbm/basic.py\", line 232, in _load_lib\n    lib = ctypes.cdll.LoadLibrary(lib_path[0])\n          ^^^^^^^^^^^^^^^^^^^^^^^^^^^^^^^^^^^^\n  File \"/usr/local/lib/python3.11/ctypes/__init__.py\", line 454, in LoadLibrary\n    return self._dlltype(name)\n           ^^^^^^^^^^^^^^^^^^^\n  File \"/usr/local/lib/python3.11/ctypes/__init__.py\", line 376, in __init__\n    self._handle = _dlopen(self._name, mode)\n                   ^^^^^^^^^^^^^^^^^^^^^^^^^\nOSError: libgomp.so.1: cannot open shared object file: No such file or directory"}}
{"timestamp": "2025-05-03 13:34:13,754", "level": "ERROR", "message": "Error loading model /app/flashcamp/models/pillar/market_lgbm.joblib: libgomp.so.1: cannot open shared object file: No such file or directory", "module": "model_loader", "function": "load_model", "line": "43", "process": "1", "thread": "140320016731008", "exception": {"type": "OSError", "message": "libgomp.so.1: cannot open shared object file: No such file or directory", "traceback": "Traceback (most recent call last):\n  File \"/app/flashcamp/backend/model_loader.py\", line 28, in load_model\n    model = joblib.load(absolute_path)\n            ^^^^^^^^^^^^^^^^^^^^^^^^^^\n  File \"/root/.local/lib/python3.11/site-packages/joblib/numpy_pickle.py\", line 658, in load\n    obj = _unpickle(fobj, filename, mmap_mode)\n          ^^^^^^^^^^^^^^^^^^^^^^^^^^^^^^^^^^^^\n  File \"/root/.local/lib/python3.11/site-packages/joblib/numpy_pickle.py\", line 577, in _unpickle\n    obj = unpickler.load()\n          ^^^^^^^^^^^^^^^^\n  File \"/usr/local/lib/python3.11/pickle.py\", line 1213, in load\n    dispatch[key[0]](self)\n  File \"/usr/local/lib/python3.11/pickle.py\", line 1538, in load_stack_global\n    self.append(self.find_class(module, name))\n                ^^^^^^^^^^^^^^^^^^^^^^^^^^^^^\n  File \"/usr/local/lib/python3.11/pickle.py\", line 1580, in find_class\n    __import__(module, level=0)\n  File \"/root/.local/lib/python3.11/site-packages/lightgbm/__init__.py\", line 8, in <module>\n    from .basic import Booster, Dataset, Sequence, register_logger\n  File \"/root/.local/lib/python3.11/site-packages/lightgbm/basic.py\", line 247, in <module>\n    _LIB = _load_lib()\n           ^^^^^^^^^^^\n  File \"/root/.local/lib/python3.11/site-packages/lightgbm/basic.py\", line 232, in _load_lib\n    lib = ctypes.cdll.LoadLibrary(lib_path[0])\n          ^^^^^^^^^^^^^^^^^^^^^^^^^^^^^^^^^^^^\n  File \"/usr/local/lib/python3.11/ctypes/__init__.py\", line 454, in LoadLibrary\n    return self._dlltype(name)\n           ^^^^^^^^^^^^^^^^^^^\n  File \"/usr/local/lib/python3.11/ctypes/__init__.py\", line 376, in __init__\n    self._handle = _dlopen(self._name, mode)\n                   ^^^^^^^^^^^^^^^^^^^^^^^^^\nOSError: libgomp.so.1: cannot open shared object file: No such file or directory"}}
{"timestamp": "2025-05-03 13:34:13,771", "level": "ERROR", "message": "Error loading model /app/flashcamp/models/pillar/people_lgbm.joblib: libgomp.so.1: cannot open shared object file: No such file or directory", "module": "model_loader", "function": "load_model", "line": "43", "process": "1", "thread": "140320016731008", "exception": {"type": "OSError", "message": "libgomp.so.1: cannot open shared object file: No such file or directory", "traceback": "Traceback (most recent call last):\n  File \"/app/flashcamp/backend/model_loader.py\", line 28, in load_model\n    model = joblib.load(absolute_path)\n            ^^^^^^^^^^^^^^^^^^^^^^^^^^\n  File \"/root/.local/lib/python3.11/site-packages/joblib/numpy_pickle.py\", line 658, in load\n    obj = _unpickle(fobj, filename, mmap_mode)\n          ^^^^^^^^^^^^^^^^^^^^^^^^^^^^^^^^^^^^\n  File \"/root/.local/lib/python3.11/site-packages/joblib/numpy_pickle.py\", line 577, in _unpickle\n    obj = unpickler.load()\n          ^^^^^^^^^^^^^^^^\n  File \"/usr/local/lib/python3.11/pickle.py\", line 1213, in load\n    dispatch[key[0]](self)\n  File \"/usr/local/lib/python3.11/pickle.py\", line 1538, in load_stack_global\n    self.append(self.find_class(module, name))\n                ^^^^^^^^^^^^^^^^^^^^^^^^^^^^^\n  File \"/usr/local/lib/python3.11/pickle.py\", line 1580, in find_class\n    __import__(module, level=0)\n  File \"/root/.local/lib/python3.11/site-packages/lightgbm/__init__.py\", line 8, in <module>\n    from .basic import Booster, Dataset, Sequence, register_logger\n  File \"/root/.local/lib/python3.11/site-packages/lightgbm/basic.py\", line 247, in <module>\n    _LIB = _load_lib()\n           ^^^^^^^^^^^\n  File \"/root/.local/lib/python3.11/site-packages/lightgbm/basic.py\", line 232, in _load_lib\n    lib = ctypes.cdll.LoadLibrary(lib_path[0])\n          ^^^^^^^^^^^^^^^^^^^^^^^^^^^^^^^^^^^^\n  File \"/usr/local/lib/python3.11/ctypes/__init__.py\", line 454, in LoadLibrary\n    return self._dlltype(name)\n           ^^^^^^^^^^^^^^^^^^^\n  File \"/usr/local/lib/python3.11/ctypes/__init__.py\", line 376, in __init__\n    self._handle = _dlopen(self._name, mode)\n                   ^^^^^^^^^^^^^^^^^^^^^^^^^\nOSError: libgomp.so.1: cannot open shared object file: No such file or directory"}}
{"timestamp": "2025-05-03 13:34:13,787", "level": "ERROR", "message": "Market model not loaded.", "module": "market", "function": "calculate_market_score", "line": "19", "process": "1", "thread": "140320016731008"}
{"timestamp": "2025-05-03 13:34:13,789", "level": "ERROR", "message": "Error calculating pillar scores: Market model not loaded or unavailable", "module": "analysis", "function": "pillar_scores", "line": "105", "process": "1", "thread": "140320016731008", "exception": {"type": "ValueError", "message": "Market model not loaded or unavailable", "traceback": "Traceback (most recent call last):\n  File \"/app/flashcamp/backend/analysis.py\", line 80, in pillar_scores\n    market_score, _ = calculate_market_score_fn(metrics_data)\n                      ^^^^^^^^^^^^^^^^^^^^^^^^^^^^^^^^^^^^^^^\n  File \"/app/flashcamp/backend/app/engines/market.py\", line 20, in calculate_market_score\n    raise ValueError(\"Market model not loaded or unavailable\")\nValueError: Market model not loaded or unavailable"}}
{"timestamp": "2025-05-03 13:34:13,794", "level": "ERROR", "message": "Error importing engine function _fallback_prediction: module 'flashcamp.backend.app.engines.ml' has no attribute '_fallback_prediction'", "module": "analysis", "function": "_import_engine_function", "line": "54", "process": "1", "thread": "140320016731008"}
{"timestamp": "2025-05-03 13:34:13,796", "level": "ERROR", "message": "Could not import fallback prediction function!", "module": "analysis", "function": "predict_success", "line": "178", "process": "1", "thread": "140320016731008"}
{"timestamp": "2025-05-03 13:36:03,619", "level": "ERROR", "message": "Market model not loaded.", "module": "market", "function": "calculate_market_score", "line": "19", "process": "1", "thread": "140320016731008"}
{"timestamp": "2025-05-03 13:36:03,622", "level": "ERROR", "message": "Error calculating pillar scores: Market model not loaded or unavailable", "module": "analysis", "function": "pillar_scores", "line": "105", "process": "1", "thread": "140320016731008", "exception": {"type": "ValueError", "message": "Market model not loaded or unavailable", "traceback": "Traceback (most recent call last):\n  File \"/app/flashcamp/backend/analysis.py\", line 80, in pillar_scores\n    market_score, _ = calculate_market_score_fn(metrics_data)\n                      ^^^^^^^^^^^^^^^^^^^^^^^^^^^^^^^^^^^^^^^\n  File \"/app/flashcamp/backend/app/engines/market.py\", line 20, in calculate_market_score\n    raise ValueError(\"Market model not loaded or unavailable\")\nValueError: Market model not loaded or unavailable"}}
{"timestamp": "2025-05-03 13:36:03,629", "level": "ERROR", "message": "Error importing engine function _fallback_prediction: module 'flashcamp.backend.app.engines.ml' has no attribute '_fallback_prediction'", "module": "analysis", "function": "_import_engine_function", "line": "54", "process": "1", "thread": "140320016731008"}
{"timestamp": "2025-05-03 13:36:03,630", "level": "ERROR", "message": "Could not import fallback prediction function!", "module": "analysis", "function": "predict_success", "line": "178", "process": "1", "thread": "140320016731008"}
{"timestamp": "2025-05-03 13:43:07,014", "level": "ERROR", "message": "Market model not loaded.", "module": "market", "function": "calculate_market_score", "line": "19", "process": "1", "thread": "140320016731008"}
{"timestamp": "2025-05-03 13:43:07,016", "level": "ERROR", "message": "Error calculating pillar scores: Market model not loaded or unavailable", "module": "analysis", "function": "pillar_scores", "line": "105", "process": "1", "thread": "140320016731008", "exception": {"type": "ValueError", "message": "Market model not loaded or unavailable", "traceback": "Traceback (most recent call last):\n  File \"/app/flashcamp/backend/analysis.py\", line 80, in pillar_scores\n    market_score, _ = calculate_market_score_fn(metrics_data)\n                      ^^^^^^^^^^^^^^^^^^^^^^^^^^^^^^^^^^^^^^^\n  File \"/app/flashcamp/backend/app/engines/market.py\", line 20, in calculate_market_score\n    raise ValueError(\"Market model not loaded or unavailable\")\nValueError: Market model not loaded or unavailable"}}
{"timestamp": "2025-05-03 13:43:07,023", "level": "ERROR", "message": "Error importing engine function _fallback_prediction: module 'flashcamp.backend.app.engines.ml' has no attribute '_fallback_prediction'", "module": "analysis", "function": "_import_engine_function", "line": "54", "process": "1", "thread": "140320016731008"}
{"timestamp": "2025-05-03 13:43:07,025", "level": "ERROR", "message": "Could not import fallback prediction function!", "module": "analysis", "function": "predict_success", "line": "178", "process": "1", "thread": "140320016731008"}
{"timestamp": "2025-05-04 13:18:14,826", "level": "ERROR", "message": "Error calculating pillar scores: prepare() takes 1 positional argument but 2 were given", "module": "analysis", "function": "pillar_scores", "line": "105", "process": "58047", "thread": "140704646966208", "exception": {"type": "TypeError", "message": "prepare() takes 1 positional argument but 2 were given", "traceback": "Traceback (most recent call last):\n  File \"/Users/sf/Desktop/FLASH/flashcamp/backend/analysis.py\", line 80, in pillar_scores\n    market_score, _ = calculate_market_score_fn(metrics_data)\n                      ^^^^^^^^^^^^^^^^^^^^^^^^^^^^^^^^^^^^^^^\n  File \"/Users/sf/Desktop/FLASH/flashcamp/backend/app/engines/market.py\", line 23, in calculate_market_score\n    X = prepare(metrics, _model)\n        ^^^^^^^^^^^^^^^^^^^^^^^^\nTypeError: prepare() takes 1 positional argument but 2 were given"}}
{"timestamp": "2025-05-04 13:18:14,832", "level": "ERROR", "message": "Error importing engine function _fallback_prediction: module 'flashcamp.backend.app.engines.ml' has no attribute '_fallback_prediction'", "module": "analysis", "function": "_import_engine_function", "line": "54", "process": "58047", "thread": "140704646966208"}
{"timestamp": "2025-05-04 13:18:14,833", "level": "ERROR", "message": "Could not import fallback prediction function!", "module": "analysis", "function": "predict_success", "line": "178", "process": "58047", "thread": "140704646966208"}
{"timestamp": "2025-05-04 13:19:00,374", "level": "ERROR", "message": "Error calculating pillar scores: prepare() takes 1 positional argument but 2 were given", "module": "analysis", "function": "pillar_scores", "line": "105", "process": "58193", "thread": "140704646966208", "exception": {"type": "TypeError", "message": "prepare() takes 1 positional argument but 2 were given", "traceback": "Traceback (most recent call last):\n  File \"/Users/sf/Desktop/FLASH/flashcamp/backend/analysis.py\", line 80, in pillar_scores\n    market_score, _ = calculate_market_score_fn(metrics_data)\n                      ^^^^^^^^^^^^^^^^^^^^^^^^^^^^^^^^^^^^^^^\n  File \"/Users/sf/Desktop/FLASH/flashcamp/backend/app/engines/market.py\", line 23, in calculate_market_score\n    X = prepare(metrics, _model)\n        ^^^^^^^^^^^^^^^^^^^^^^^^\nTypeError: prepare() takes 1 positional argument but 2 were given"}}
{"timestamp": "2025-05-04 13:19:00,379", "level": "ERROR", "message": "Error importing engine function _fallback_prediction: module 'flashcamp.backend.app.engines.ml' has no attribute '_fallback_prediction'", "module": "analysis", "function": "_import_engine_function", "line": "54", "process": "58193", "thread": "140704646966208"}
{"timestamp": "2025-05-04 13:19:00,379", "level": "ERROR", "message": "Could not import fallback prediction function!", "module": "analysis", "function": "predict_success", "line": "178", "process": "58193", "thread": "140704646966208"}
{"timestamp": "2025-05-04 04:26:33,739", "level": "ERROR", "message": "Error loading model /app/flashcamp/models/pillar/capital_lgbm.joblib: libgomp.so.1: cannot open shared object file: No such file or directory", "module": "model_loader", "function": "load_model", "line": "43", "process": "8", "thread": "140074463259520", "exception": {"type": "OSError", "message": "libgomp.so.1: cannot open shared object file: No such file or directory", "traceback": "Traceback (most recent call last):\n  File \"/app/flashcamp/backend/model_loader.py\", line 28, in load_model\n    model = joblib.load(absolute_path)\n            ^^^^^^^^^^^^^^^^^^^^^^^^^^\n  File \"/root/.local/lib/python3.11/site-packages/joblib/numpy_pickle.py\", line 658, in load\n    obj = _unpickle(fobj, filename, mmap_mode)\n          ^^^^^^^^^^^^^^^^^^^^^^^^^^^^^^^^^^^^\n  File \"/root/.local/lib/python3.11/site-packages/joblib/numpy_pickle.py\", line 577, in _unpickle\n    obj = unpickler.load()\n          ^^^^^^^^^^^^^^^^\n  File \"/usr/local/lib/python3.11/pickle.py\", line 1213, in load\n    dispatch[key[0]](self)\n  File \"/usr/local/lib/python3.11/pickle.py\", line 1538, in load_stack_global\n    self.append(self.find_class(module, name))\n                ^^^^^^^^^^^^^^^^^^^^^^^^^^^^^\n  File \"/usr/local/lib/python3.11/pickle.py\", line 1580, in find_class\n    __import__(module, level=0)\n  File \"/root/.local/lib/python3.11/site-packages/lightgbm/__init__.py\", line 8, in <module>\n    from .basic import Booster, Dataset, Sequence, register_logger\n  File \"/root/.local/lib/python3.11/site-packages/lightgbm/basic.py\", line 247, in <module>\n    _LIB = _load_lib()\n           ^^^^^^^^^^^\n  File \"/root/.local/lib/python3.11/site-packages/lightgbm/basic.py\", line 232, in _load_lib\n    lib = ctypes.cdll.LoadLibrary(lib_path[0])\n          ^^^^^^^^^^^^^^^^^^^^^^^^^^^^^^^^^^^^\n  File \"/usr/local/lib/python3.11/ctypes/__init__.py\", line 454, in LoadLibrary\n    return self._dlltype(name)\n           ^^^^^^^^^^^^^^^^^^^\n  File \"/usr/local/lib/python3.11/ctypes/__init__.py\", line 376, in __init__\n    self._handle = _dlopen(self._name, mode)\n                   ^^^^^^^^^^^^^^^^^^^^^^^^^\nOSError: libgomp.so.1: cannot open shared object file: No such file or directory"}}
{"timestamp": "2025-05-04 04:26:33,772", "level": "ERROR", "message": "Error loading model /app/flashcamp/models/pillar/advantage_lgbm.joblib: libgomp.so.1: cannot open shared object file: No such file or directory", "module": "model_loader", "function": "load_model", "line": "43", "process": "8", "thread": "140074463259520", "exception": {"type": "OSError", "message": "libgomp.so.1: cannot open shared object file: No such file or directory", "traceback": "Traceback (most recent call last):\n  File \"/app/flashcamp/backend/model_loader.py\", line 28, in load_model\n    model = joblib.load(absolute_path)\n            ^^^^^^^^^^^^^^^^^^^^^^^^^^\n  File \"/root/.local/lib/python3.11/site-packages/joblib/numpy_pickle.py\", line 658, in load\n    obj = _unpickle(fobj, filename, mmap_mode)\n          ^^^^^^^^^^^^^^^^^^^^^^^^^^^^^^^^^^^^\n  File \"/root/.local/lib/python3.11/site-packages/joblib/numpy_pickle.py\", line 577, in _unpickle\n    obj = unpickler.load()\n          ^^^^^^^^^^^^^^^^\n  File \"/usr/local/lib/python3.11/pickle.py\", line 1213, in load\n    dispatch[key[0]](self)\n  File \"/usr/local/lib/python3.11/pickle.py\", line 1538, in load_stack_global\n    self.append(self.find_class(module, name))\n                ^^^^^^^^^^^^^^^^^^^^^^^^^^^^^\n  File \"/usr/local/lib/python3.11/pickle.py\", line 1580, in find_class\n    __import__(module, level=0)\n  File \"/root/.local/lib/python3.11/site-packages/lightgbm/__init__.py\", line 8, in <module>\n    from .basic import Booster, Dataset, Sequence, register_logger\n  File \"/root/.local/lib/python3.11/site-packages/lightgbm/basic.py\", line 247, in <module>\n    _LIB = _load_lib()\n           ^^^^^^^^^^^\n  File \"/root/.local/lib/python3.11/site-packages/lightgbm/basic.py\", line 232, in _load_lib\n    lib = ctypes.cdll.LoadLibrary(lib_path[0])\n          ^^^^^^^^^^^^^^^^^^^^^^^^^^^^^^^^^^^^\n  File \"/usr/local/lib/python3.11/ctypes/__init__.py\", line 454, in LoadLibrary\n    return self._dlltype(name)\n           ^^^^^^^^^^^^^^^^^^^\n  File \"/usr/local/lib/python3.11/ctypes/__init__.py\", line 376, in __init__\n    self._handle = _dlopen(self._name, mode)\n                   ^^^^^^^^^^^^^^^^^^^^^^^^^\nOSError: libgomp.so.1: cannot open shared object file: No such file or directory"}}
{"timestamp": "2025-05-04 04:26:33,791", "level": "ERROR", "message": "Error loading model /app/flashcamp/models/pillar/market_lgbm.joblib: libgomp.so.1: cannot open shared object file: No such file or directory", "module": "model_loader", "function": "load_model", "line": "43", "process": "8", "thread": "140074463259520", "exception": {"type": "OSError", "message": "libgomp.so.1: cannot open shared object file: No such file or directory", "traceback": "Traceback (most recent call last):\n  File \"/app/flashcamp/backend/model_loader.py\", line 28, in load_model\n    model = joblib.load(absolute_path)\n            ^^^^^^^^^^^^^^^^^^^^^^^^^^\n  File \"/root/.local/lib/python3.11/site-packages/joblib/numpy_pickle.py\", line 658, in load\n    obj = _unpickle(fobj, filename, mmap_mode)\n          ^^^^^^^^^^^^^^^^^^^^^^^^^^^^^^^^^^^^\n  File \"/root/.local/lib/python3.11/site-packages/joblib/numpy_pickle.py\", line 577, in _unpickle\n    obj = unpickler.load()\n          ^^^^^^^^^^^^^^^^\n  File \"/usr/local/lib/python3.11/pickle.py\", line 1213, in load\n    dispatch[key[0]](self)\n  File \"/usr/local/lib/python3.11/pickle.py\", line 1538, in load_stack_global\n    self.append(self.find_class(module, name))\n                ^^^^^^^^^^^^^^^^^^^^^^^^^^^^^\n  File \"/usr/local/lib/python3.11/pickle.py\", line 1580, in find_class\n    __import__(module, level=0)\n  File \"/root/.local/lib/python3.11/site-packages/lightgbm/__init__.py\", line 8, in <module>\n    from .basic import Booster, Dataset, Sequence, register_logger\n  File \"/root/.local/lib/python3.11/site-packages/lightgbm/basic.py\", line 247, in <module>\n    _LIB = _load_lib()\n           ^^^^^^^^^^^\n  File \"/root/.local/lib/python3.11/site-packages/lightgbm/basic.py\", line 232, in _load_lib\n    lib = ctypes.cdll.LoadLibrary(lib_path[0])\n          ^^^^^^^^^^^^^^^^^^^^^^^^^^^^^^^^^^^^\n  File \"/usr/local/lib/python3.11/ctypes/__init__.py\", line 454, in LoadLibrary\n    return self._dlltype(name)\n           ^^^^^^^^^^^^^^^^^^^\n  File \"/usr/local/lib/python3.11/ctypes/__init__.py\", line 376, in __init__\n    self._handle = _dlopen(self._name, mode)\n                   ^^^^^^^^^^^^^^^^^^^^^^^^^\nOSError: libgomp.so.1: cannot open shared object file: No such file or directory"}}
{"timestamp": "2025-05-04 04:26:33,809", "level": "ERROR", "message": "Error loading model /app/flashcamp/models/pillar/people_lgbm.joblib: libgomp.so.1: cannot open shared object file: No such file or directory", "module": "model_loader", "function": "load_model", "line": "43", "process": "8", "thread": "140074463259520", "exception": {"type": "OSError", "message": "libgomp.so.1: cannot open shared object file: No such file or directory", "traceback": "Traceback (most recent call last):\n  File \"/app/flashcamp/backend/model_loader.py\", line 28, in load_model\n    model = joblib.load(absolute_path)\n            ^^^^^^^^^^^^^^^^^^^^^^^^^^\n  File \"/root/.local/lib/python3.11/site-packages/joblib/numpy_pickle.py\", line 658, in load\n    obj = _unpickle(fobj, filename, mmap_mode)\n          ^^^^^^^^^^^^^^^^^^^^^^^^^^^^^^^^^^^^\n  File \"/root/.local/lib/python3.11/site-packages/joblib/numpy_pickle.py\", line 577, in _unpickle\n    obj = unpickler.load()\n          ^^^^^^^^^^^^^^^^\n  File \"/usr/local/lib/python3.11/pickle.py\", line 1213, in load\n    dispatch[key[0]](self)\n  File \"/usr/local/lib/python3.11/pickle.py\", line 1538, in load_stack_global\n    self.append(self.find_class(module, name))\n                ^^^^^^^^^^^^^^^^^^^^^^^^^^^^^\n  File \"/usr/local/lib/python3.11/pickle.py\", line 1580, in find_class\n    __import__(module, level=0)\n  File \"/root/.local/lib/python3.11/site-packages/lightgbm/__init__.py\", line 8, in <module>\n    from .basic import Booster, Dataset, Sequence, register_logger\n  File \"/root/.local/lib/python3.11/site-packages/lightgbm/basic.py\", line 247, in <module>\n    _LIB = _load_lib()\n           ^^^^^^^^^^^\n  File \"/root/.local/lib/python3.11/site-packages/lightgbm/basic.py\", line 232, in _load_lib\n    lib = ctypes.cdll.LoadLibrary(lib_path[0])\n          ^^^^^^^^^^^^^^^^^^^^^^^^^^^^^^^^^^^^\n  File \"/usr/local/lib/python3.11/ctypes/__init__.py\", line 454, in LoadLibrary\n    return self._dlltype(name)\n           ^^^^^^^^^^^^^^^^^^^\n  File \"/usr/local/lib/python3.11/ctypes/__init__.py\", line 376, in __init__\n    self._handle = _dlopen(self._name, mode)\n                   ^^^^^^^^^^^^^^^^^^^^^^^^^\nOSError: libgomp.so.1: cannot open shared object file: No such file or directory"}}
{"timestamp": "2025-05-04 04:26:33,822", "level": "ERROR", "message": "Market model not loaded.", "module": "market", "function": "calculate_market_score", "line": "19", "process": "8", "thread": "140074463259520"}
{"timestamp": "2025-05-04 04:26:33,823", "level": "ERROR", "message": "Error calculating pillar scores: Market model not loaded or unavailable", "module": "analysis", "function": "pillar_scores", "line": "105", "process": "8", "thread": "140074463259520", "exception": {"type": "ValueError", "message": "Market model not loaded or unavailable", "traceback": "Traceback (most recent call last):\n  File \"/app/flashcamp/backend/analysis.py\", line 80, in pillar_scores\n    market_score, _ = calculate_market_score_fn(metrics_data)\n                      ^^^^^^^^^^^^^^^^^^^^^^^^^^^^^^^^^^^^^^^\n  File \"/app/flashcamp/backend/app/engines/market.py\", line 20, in calculate_market_score\n    raise ValueError(\"Market model not loaded or unavailable\")\nValueError: Market model not loaded or unavailable"}}
{"timestamp": "2025-05-04 04:26:33,834", "level": "ERROR", "message": "Error importing engine function _fallback_prediction: module 'flashcamp.backend.app.engines.ml' has no attribute '_fallback_prediction'", "module": "analysis", "function": "_import_engine_function", "line": "54", "process": "8", "thread": "140074463259520"}
{"timestamp": "2025-05-04 04:26:33,836", "level": "ERROR", "message": "Could not import fallback prediction function!", "module": "analysis", "function": "predict_success", "line": "178", "process": "8", "thread": "140074463259520"}
{"timestamp": "2025-05-04 04:50:14,009", "level": "ERROR", "message": "Market model not loaded.", "module": "market", "function": "calculate_market_score", "line": "19", "process": "8", "thread": "140074463259520"}
{"timestamp": "2025-05-04 04:50:14,015", "level": "ERROR", "message": "Error calculating pillar scores: Market model not loaded or unavailable", "module": "analysis", "function": "pillar_scores", "line": "105", "process": "8", "thread": "140074463259520", "exception": {"type": "ValueError", "message": "Market model not loaded or unavailable", "traceback": "Traceback (most recent call last):\n  File \"/app/flashcamp/backend/analysis.py\", line 80, in pillar_scores\n    market_score, _ = calculate_market_score_fn(metrics_data)\n                      ^^^^^^^^^^^^^^^^^^^^^^^^^^^^^^^^^^^^^^^\n  File \"/app/flashcamp/backend/app/engines/market.py\", line 20, in calculate_market_score\n    raise ValueError(\"Market model not loaded or unavailable\")\nValueError: Market model not loaded or unavailable"}}
{"timestamp": "2025-05-04 04:50:14,026", "level": "ERROR", "message": "Error importing engine function _fallback_prediction: module 'flashcamp.backend.app.engines.ml' has no attribute '_fallback_prediction'", "module": "analysis", "function": "_import_engine_function", "line": "54", "process": "8", "thread": "140074463259520"}
{"timestamp": "2025-05-04 04:50:14,033", "level": "ERROR", "message": "Could not import fallback prediction function!", "module": "analysis", "function": "predict_success", "line": "178", "process": "8", "thread": "140074463259520"}
{"timestamp": "2025-05-04 05:10:29,266", "level": "ERROR", "message": "Market model not loaded.", "module": "market", "function": "calculate_market_score", "line": "19", "process": "8", "thread": "140074463259520"}
{"timestamp": "2025-05-04 05:10:29,268", "level": "ERROR", "message": "Error calculating pillar scores: Market model not loaded or unavailable", "module": "analysis", "function": "pillar_scores", "line": "105", "process": "8", "thread": "140074463259520", "exception": {"type": "ValueError", "message": "Market model not loaded or unavailable", "traceback": "Traceback (most recent call last):\n  File \"/app/flashcamp/backend/analysis.py\", line 80, in pillar_scores\n    market_score, _ = calculate_market_score_fn(metrics_data)\n                      ^^^^^^^^^^^^^^^^^^^^^^^^^^^^^^^^^^^^^^^\n  File \"/app/flashcamp/backend/app/engines/market.py\", line 20, in calculate_market_score\n    raise ValueError(\"Market model not loaded or unavailable\")\nValueError: Market model not loaded or unavailable"}}
{"timestamp": "2025-05-04 05:10:29,284", "level": "ERROR", "message": "Error importing engine function _fallback_prediction: module 'flashcamp.backend.app.engines.ml' has no attribute '_fallback_prediction'", "module": "analysis", "function": "_import_engine_function", "line": "54", "process": "8", "thread": "140074463259520"}
{"timestamp": "2025-05-04 05:10:29,285", "level": "ERROR", "message": "Could not import fallback prediction function!", "module": "analysis", "function": "predict_success", "line": "178", "process": "8", "thread": "140074463259520"}
{"timestamp": "2025-05-04 05:20:32,858", "level": "ERROR", "message": "Error loading model /app/flashcamp/models/pillar/capital_lgbm.joblib: libgomp.so.1: cannot open shared object file: No such file or directory", "module": "model_loader", "function": "load_model", "line": "43", "process": "489", "thread": "139864071007104", "exception": {"type": "OSError", "message": "libgomp.so.1: cannot open shared object file: No such file or directory", "traceback": "Traceback (most recent call last):\n  File \"/app/flashcamp/backend/model_loader.py\", line 28, in load_model\n    model = joblib.load(absolute_path)\n            ^^^^^^^^^^^^^^^^^^^^^^^^^^\n  File \"/root/.local/lib/python3.11/site-packages/joblib/numpy_pickle.py\", line 658, in load\n    obj = _unpickle(fobj, filename, mmap_mode)\n          ^^^^^^^^^^^^^^^^^^^^^^^^^^^^^^^^^^^^\n  File \"/root/.local/lib/python3.11/site-packages/joblib/numpy_pickle.py\", line 577, in _unpickle\n    obj = unpickler.load()\n          ^^^^^^^^^^^^^^^^\n  File \"/usr/local/lib/python3.11/pickle.py\", line 1213, in load\n    dispatch[key[0]](self)\n  File \"/usr/local/lib/python3.11/pickle.py\", line 1538, in load_stack_global\n    self.append(self.find_class(module, name))\n                ^^^^^^^^^^^^^^^^^^^^^^^^^^^^^\n  File \"/usr/local/lib/python3.11/pickle.py\", line 1580, in find_class\n    __import__(module, level=0)\n  File \"/root/.local/lib/python3.11/site-packages/lightgbm/__init__.py\", line 8, in <module>\n    from .basic import Booster, Dataset, Sequence, register_logger\n  File \"/root/.local/lib/python3.11/site-packages/lightgbm/basic.py\", line 247, in <module>\n    _LIB = _load_lib()\n           ^^^^^^^^^^^\n  File \"/root/.local/lib/python3.11/site-packages/lightgbm/basic.py\", line 232, in _load_lib\n    lib = ctypes.cdll.LoadLibrary(lib_path[0])\n          ^^^^^^^^^^^^^^^^^^^^^^^^^^^^^^^^^^^^\n  File \"/usr/local/lib/python3.11/ctypes/__init__.py\", line 454, in LoadLibrary\n    return self._dlltype(name)\n           ^^^^^^^^^^^^^^^^^^^\n  File \"/usr/local/lib/python3.11/ctypes/__init__.py\", line 376, in __init__\n    self._handle = _dlopen(self._name, mode)\n                   ^^^^^^^^^^^^^^^^^^^^^^^^^\nOSError: libgomp.so.1: cannot open shared object file: No such file or directory"}}
{"timestamp": "2025-05-04 05:20:32,894", "level": "ERROR", "message": "Error loading model /app/flashcamp/models/pillar/advantage_lgbm.joblib: libgomp.so.1: cannot open shared object file: No such file or directory", "module": "model_loader", "function": "load_model", "line": "43", "process": "489", "thread": "139864071007104", "exception": {"type": "OSError", "message": "libgomp.so.1: cannot open shared object file: No such file or directory", "traceback": "Traceback (most recent call last):\n  File \"/app/flashcamp/backend/model_loader.py\", line 28, in load_model\n    model = joblib.load(absolute_path)\n            ^^^^^^^^^^^^^^^^^^^^^^^^^^\n  File \"/root/.local/lib/python3.11/site-packages/joblib/numpy_pickle.py\", line 658, in load\n    obj = _unpickle(fobj, filename, mmap_mode)\n          ^^^^^^^^^^^^^^^^^^^^^^^^^^^^^^^^^^^^\n  File \"/root/.local/lib/python3.11/site-packages/joblib/numpy_pickle.py\", line 577, in _unpickle\n    obj = unpickler.load()\n          ^^^^^^^^^^^^^^^^\n  File \"/usr/local/lib/python3.11/pickle.py\", line 1213, in load\n    dispatch[key[0]](self)\n  File \"/usr/local/lib/python3.11/pickle.py\", line 1538, in load_stack_global\n    self.append(self.find_class(module, name))\n                ^^^^^^^^^^^^^^^^^^^^^^^^^^^^^\n  File \"/usr/local/lib/python3.11/pickle.py\", line 1580, in find_class\n    __import__(module, level=0)\n  File \"/root/.local/lib/python3.11/site-packages/lightgbm/__init__.py\", line 8, in <module>\n    from .basic import Booster, Dataset, Sequence, register_logger\n  File \"/root/.local/lib/python3.11/site-packages/lightgbm/basic.py\", line 247, in <module>\n    _LIB = _load_lib()\n           ^^^^^^^^^^^\n  File \"/root/.local/lib/python3.11/site-packages/lightgbm/basic.py\", line 232, in _load_lib\n    lib = ctypes.cdll.LoadLibrary(lib_path[0])\n          ^^^^^^^^^^^^^^^^^^^^^^^^^^^^^^^^^^^^\n  File \"/usr/local/lib/python3.11/ctypes/__init__.py\", line 454, in LoadLibrary\n    return self._dlltype(name)\n           ^^^^^^^^^^^^^^^^^^^\n  File \"/usr/local/lib/python3.11/ctypes/__init__.py\", line 376, in __init__\n    self._handle = _dlopen(self._name, mode)\n                   ^^^^^^^^^^^^^^^^^^^^^^^^^\nOSError: libgomp.so.1: cannot open shared object file: No such file or directory"}}
{"timestamp": "2025-05-04 05:20:32,923", "level": "ERROR", "message": "Error loading model /app/flashcamp/models/pillar/market_lgbm.joblib: libgomp.so.1: cannot open shared object file: No such file or directory", "module": "model_loader", "function": "load_model", "line": "43", "process": "489", "thread": "139864071007104", "exception": {"type": "OSError", "message": "libgomp.so.1: cannot open shared object file: No such file or directory", "traceback": "Traceback (most recent call last):\n  File \"/app/flashcamp/backend/model_loader.py\", line 28, in load_model\n    model = joblib.load(absolute_path)\n            ^^^^^^^^^^^^^^^^^^^^^^^^^^\n  File \"/root/.local/lib/python3.11/site-packages/joblib/numpy_pickle.py\", line 658, in load\n    obj = _unpickle(fobj, filename, mmap_mode)\n          ^^^^^^^^^^^^^^^^^^^^^^^^^^^^^^^^^^^^\n  File \"/root/.local/lib/python3.11/site-packages/joblib/numpy_pickle.py\", line 577, in _unpickle\n    obj = unpickler.load()\n          ^^^^^^^^^^^^^^^^\n  File \"/usr/local/lib/python3.11/pickle.py\", line 1213, in load\n    dispatch[key[0]](self)\n  File \"/usr/local/lib/python3.11/pickle.py\", line 1538, in load_stack_global\n    self.append(self.find_class(module, name))\n                ^^^^^^^^^^^^^^^^^^^^^^^^^^^^^\n  File \"/usr/local/lib/python3.11/pickle.py\", line 1580, in find_class\n    __import__(module, level=0)\n  File \"/root/.local/lib/python3.11/site-packages/lightgbm/__init__.py\", line 8, in <module>\n    from .basic import Booster, Dataset, Sequence, register_logger\n  File \"/root/.local/lib/python3.11/site-packages/lightgbm/basic.py\", line 247, in <module>\n    _LIB = _load_lib()\n           ^^^^^^^^^^^\n  File \"/root/.local/lib/python3.11/site-packages/lightgbm/basic.py\", line 232, in _load_lib\n    lib = ctypes.cdll.LoadLibrary(lib_path[0])\n          ^^^^^^^^^^^^^^^^^^^^^^^^^^^^^^^^^^^^\n  File \"/usr/local/lib/python3.11/ctypes/__init__.py\", line 454, in LoadLibrary\n    return self._dlltype(name)\n           ^^^^^^^^^^^^^^^^^^^\n  File \"/usr/local/lib/python3.11/ctypes/__init__.py\", line 376, in __init__\n    self._handle = _dlopen(self._name, mode)\n                   ^^^^^^^^^^^^^^^^^^^^^^^^^\nOSError: libgomp.so.1: cannot open shared object file: No such file or directory"}}
{"timestamp": "2025-05-04 05:20:32,952", "level": "ERROR", "message": "Error loading model /app/flashcamp/models/pillar/people_lgbm.joblib: libgomp.so.1: cannot open shared object file: No such file or directory", "module": "model_loader", "function": "load_model", "line": "43", "process": "489", "thread": "139864071007104", "exception": {"type": "OSError", "message": "libgomp.so.1: cannot open shared object file: No such file or directory", "traceback": "Traceback (most recent call last):\n  File \"/app/flashcamp/backend/model_loader.py\", line 28, in load_model\n    model = joblib.load(absolute_path)\n            ^^^^^^^^^^^^^^^^^^^^^^^^^^\n  File \"/root/.local/lib/python3.11/site-packages/joblib/numpy_pickle.py\", line 658, in load\n    obj = _unpickle(fobj, filename, mmap_mode)\n          ^^^^^^^^^^^^^^^^^^^^^^^^^^^^^^^^^^^^\n  File \"/root/.local/lib/python3.11/site-packages/joblib/numpy_pickle.py\", line 577, in _unpickle\n    obj = unpickler.load()\n          ^^^^^^^^^^^^^^^^\n  File \"/usr/local/lib/python3.11/pickle.py\", line 1213, in load\n    dispatch[key[0]](self)\n  File \"/usr/local/lib/python3.11/pickle.py\", line 1538, in load_stack_global\n    self.append(self.find_class(module, name))\n                ^^^^^^^^^^^^^^^^^^^^^^^^^^^^^\n  File \"/usr/local/lib/python3.11/pickle.py\", line 1580, in find_class\n    __import__(module, level=0)\n  File \"/root/.local/lib/python3.11/site-packages/lightgbm/__init__.py\", line 8, in <module>\n    from .basic import Booster, Dataset, Sequence, register_logger\n  File \"/root/.local/lib/python3.11/site-packages/lightgbm/basic.py\", line 247, in <module>\n    _LIB = _load_lib()\n           ^^^^^^^^^^^\n  File \"/root/.local/lib/python3.11/site-packages/lightgbm/basic.py\", line 232, in _load_lib\n    lib = ctypes.cdll.LoadLibrary(lib_path[0])\n          ^^^^^^^^^^^^^^^^^^^^^^^^^^^^^^^^^^^^\n  File \"/usr/local/lib/python3.11/ctypes/__init__.py\", line 454, in LoadLibrary\n    return self._dlltype(name)\n           ^^^^^^^^^^^^^^^^^^^\n  File \"/usr/local/lib/python3.11/ctypes/__init__.py\", line 376, in __init__\n    self._handle = _dlopen(self._name, mode)\n                   ^^^^^^^^^^^^^^^^^^^^^^^^^\nOSError: libgomp.so.1: cannot open shared object file: No such file or directory"}}
{"timestamp": "2025-05-04 05:20:32,975", "level": "ERROR", "message": "Market model not loaded.", "module": "market", "function": "calculate_market_score", "line": "19", "process": "489", "thread": "139864071007104"}
{"timestamp": "2025-05-04 05:20:32,977", "level": "ERROR", "message": "Error calculating pillar scores: Market model not loaded or unavailable", "module": "analysis", "function": "pillar_scores", "line": "105", "process": "489", "thread": "139864071007104", "exception": {"type": "ValueError", "message": "Market model not loaded or unavailable", "traceback": "Traceback (most recent call last):\n  File \"/app/flashcamp/backend/analysis.py\", line 80, in pillar_scores\n    market_score, _ = calculate_market_score_fn(metrics_data)\n                      ^^^^^^^^^^^^^^^^^^^^^^^^^^^^^^^^^^^^^^^\n  File \"/app/flashcamp/backend/app/engines/market.py\", line 20, in calculate_market_score\n    raise ValueError(\"Market model not loaded or unavailable\")\nValueError: Market model not loaded or unavailable"}}
{"timestamp": "2025-05-04 05:20:32,990", "level": "ERROR", "message": "Error importing engine function _fallback_prediction: module 'flashcamp.backend.app.engines.ml' has no attribute '_fallback_prediction'", "module": "analysis", "function": "_import_engine_function", "line": "54", "process": "489", "thread": "139864071007104"}
{"timestamp": "2025-05-04 05:20:32,991", "level": "ERROR", "message": "Could not import fallback prediction function!", "module": "analysis", "function": "predict_success", "line": "178", "process": "489", "thread": "139864071007104"}
{"timestamp": "2025-05-04 05:20:38,587", "level": "ERROR", "message": "Market model not loaded.", "module": "market", "function": "calculate_market_score", "line": "19", "process": "489", "thread": "139864071007104"}
{"timestamp": "2025-05-04 05:20:38,590", "level": "ERROR", "message": "Error calculating pillar scores: Market model not loaded or unavailable", "module": "analysis", "function": "pillar_scores", "line": "105", "process": "489", "thread": "139864071007104", "exception": {"type": "ValueError", "message": "Market model not loaded or unavailable", "traceback": "Traceback (most recent call last):\n  File \"/app/flashcamp/backend/analysis.py\", line 80, in pillar_scores\n    market_score, _ = calculate_market_score_fn(metrics_data)\n                      ^^^^^^^^^^^^^^^^^^^^^^^^^^^^^^^^^^^^^^^\n  File \"/app/flashcamp/backend/app/engines/market.py\", line 20, in calculate_market_score\n    raise ValueError(\"Market model not loaded or unavailable\")\nValueError: Market model not loaded or unavailable"}}
{"timestamp": "2025-05-04 05:20:38,601", "level": "ERROR", "message": "Error importing engine function _fallback_prediction: module 'flashcamp.backend.app.engines.ml' has no attribute '_fallback_prediction'", "module": "analysis", "function": "_import_engine_function", "line": "54", "process": "489", "thread": "139864071007104"}
{"timestamp": "2025-05-04 05:20:38,603", "level": "ERROR", "message": "Could not import fallback prediction function!", "module": "analysis", "function": "predict_success", "line": "178", "process": "489", "thread": "139864071007104"}
{"timestamp": "2025-05-04 05:20:39,809", "level": "ERROR", "message": "Market model not loaded.", "module": "market", "function": "calculate_market_score", "line": "19", "process": "489", "thread": "139864071007104"}
{"timestamp": "2025-05-04 05:20:39,812", "level": "ERROR", "message": "Error calculating pillar scores: Market model not loaded or unavailable", "module": "analysis", "function": "pillar_scores", "line": "105", "process": "489", "thread": "139864071007104", "exception": {"type": "ValueError", "message": "Market model not loaded or unavailable", "traceback": "Traceback (most recent call last):\n  File \"/app/flashcamp/backend/analysis.py\", line 80, in pillar_scores\n    market_score, _ = calculate_market_score_fn(metrics_data)\n                      ^^^^^^^^^^^^^^^^^^^^^^^^^^^^^^^^^^^^^^^\n  File \"/app/flashcamp/backend/app/engines/market.py\", line 20, in calculate_market_score\n    raise ValueError(\"Market model not loaded or unavailable\")\nValueError: Market model not loaded or unavailable"}}
{"timestamp": "2025-05-04 05:20:39,824", "level": "ERROR", "message": "Error importing engine function _fallback_prediction: module 'flashcamp.backend.app.engines.ml' has no attribute '_fallback_prediction'", "module": "analysis", "function": "_import_engine_function", "line": "54", "process": "489", "thread": "139864071007104"}
{"timestamp": "2025-05-04 05:20:39,830", "level": "ERROR", "message": "Could not import fallback prediction function!", "module": "analysis", "function": "predict_success", "line": "178", "process": "489", "thread": "139864071007104"}
{"timestamp": "2025-05-04 05:22:03,567", "level": "ERROR", "message": "Market model not loaded.", "module": "market", "function": "calculate_market_score", "line": "19", "process": "489", "thread": "139864071007104"}
{"timestamp": "2025-05-04 05:22:03,569", "level": "ERROR", "message": "Error calculating pillar scores: Market model not loaded or unavailable", "module": "analysis", "function": "pillar_scores", "line": "105", "process": "489", "thread": "139864071007104", "exception": {"type": "ValueError", "message": "Market model not loaded or unavailable", "traceback": "Traceback (most recent call last):\n  File \"/app/flashcamp/backend/analysis.py\", line 80, in pillar_scores\n    market_score, _ = calculate_market_score_fn(metrics_data)\n                      ^^^^^^^^^^^^^^^^^^^^^^^^^^^^^^^^^^^^^^^\n  File \"/app/flashcamp/backend/app/engines/market.py\", line 20, in calculate_market_score\n    raise ValueError(\"Market model not loaded or unavailable\")\nValueError: Market model not loaded or unavailable"}}
{"timestamp": "2025-05-04 05:22:03,580", "level": "ERROR", "message": "Error importing engine function _fallback_prediction: module 'flashcamp.backend.app.engines.ml' has no attribute '_fallback_prediction'", "module": "analysis", "function": "_import_engine_function", "line": "54", "process": "489", "thread": "139864071007104"}
{"timestamp": "2025-05-04 05:22:03,583", "level": "ERROR", "message": "Could not import fallback prediction function!", "module": "analysis", "function": "predict_success", "line": "178", "process": "489", "thread": "139864071007104"}
{"timestamp": "2025-05-04 14:25:06,863", "level": "ERROR", "message": "Error calculating pillar scores: prepare() takes 1 positional argument but 2 were given", "module": "analysis", "function": "pillar_scores", "line": "105", "process": "63929", "thread": "140704646966208", "exception": {"type": "TypeError", "message": "prepare() takes 1 positional argument but 2 were given", "traceback": "Traceback (most recent call last):\n  File \"/Users/sf/Desktop/FLASH/flashcamp/backend/analysis.py\", line 80, in pillar_scores\n    market_score, _ = calculate_market_score_fn(metrics_data)\n                      ^^^^^^^^^^^^^^^^^^^^^^^^^^^^^^^^^^^^^^^\n  File \"/Users/sf/Desktop/FLASH/flashcamp/backend/app/engines/market.py\", line 23, in calculate_market_score\n    X = prepare(metrics, _model)\n        ^^^^^^^^^^^^^^^^^^^^^^^^\nTypeError: prepare() takes 1 positional argument but 2 were given"}}
{"timestamp": "2025-05-04 14:25:06,869", "level": "ERROR", "message": "Error importing engine function _fallback_prediction: module 'flashcamp.backend.app.engines.ml' has no attribute '_fallback_prediction'", "module": "analysis", "function": "_import_engine_function", "line": "54", "process": "63929", "thread": "140704646966208"}
{"timestamp": "2025-05-04 14:25:06,869", "level": "ERROR", "message": "Could not import fallback prediction function!", "module": "analysis", "function": "predict_success", "line": "178", "process": "63929", "thread": "140704646966208"}
{"timestamp": "2025-05-04 05:25:22,400", "level": "ERROR", "message": "Error loading model /app/flashcamp/models/pillar/capital_lgbm.joblib: libgomp.so.1: cannot open shared object file: No such file or directory", "module": "model_loader", "function": "load_model", "line": "43", "process": "599", "thread": "140580654353280", "exception": {"type": "OSError", "message": "libgomp.so.1: cannot open shared object file: No such file or directory", "traceback": "Traceback (most recent call last):\n  File \"/app/flashcamp/backend/model_loader.py\", line 28, in load_model\n    model = joblib.load(absolute_path)\n            ^^^^^^^^^^^^^^^^^^^^^^^^^^\n  File \"/root/.local/lib/python3.11/site-packages/joblib/numpy_pickle.py\", line 658, in load\n    obj = _unpickle(fobj, filename, mmap_mode)\n          ^^^^^^^^^^^^^^^^^^^^^^^^^^^^^^^^^^^^\n  File \"/root/.local/lib/python3.11/site-packages/joblib/numpy_pickle.py\", line 577, in _unpickle\n    obj = unpickler.load()\n          ^^^^^^^^^^^^^^^^\n  File \"/usr/local/lib/python3.11/pickle.py\", line 1213, in load\n    dispatch[key[0]](self)\n  File \"/usr/local/lib/python3.11/pickle.py\", line 1538, in load_stack_global\n    self.append(self.find_class(module, name))\n                ^^^^^^^^^^^^^^^^^^^^^^^^^^^^^\n  File \"/usr/local/lib/python3.11/pickle.py\", line 1580, in find_class\n    __import__(module, level=0)\n  File \"/root/.local/lib/python3.11/site-packages/lightgbm/__init__.py\", line 8, in <module>\n    from .basic import Booster, Dataset, Sequence, register_logger\n  File \"/root/.local/lib/python3.11/site-packages/lightgbm/basic.py\", line 247, in <module>\n    _LIB = _load_lib()\n           ^^^^^^^^^^^\n  File \"/root/.local/lib/python3.11/site-packages/lightgbm/basic.py\", line 232, in _load_lib\n    lib = ctypes.cdll.LoadLibrary(lib_path[0])\n          ^^^^^^^^^^^^^^^^^^^^^^^^^^^^^^^^^^^^\n  File \"/usr/local/lib/python3.11/ctypes/__init__.py\", line 454, in LoadLibrary\n    return self._dlltype(name)\n           ^^^^^^^^^^^^^^^^^^^\n  File \"/usr/local/lib/python3.11/ctypes/__init__.py\", line 376, in __init__\n    self._handle = _dlopen(self._name, mode)\n                   ^^^^^^^^^^^^^^^^^^^^^^^^^\nOSError: libgomp.so.1: cannot open shared object file: No such file or directory"}}
{"timestamp": "2025-05-04 05:25:22,444", "level": "ERROR", "message": "Error loading model /app/flashcamp/models/pillar/advantage_lgbm.joblib: libgomp.so.1: cannot open shared object file: No such file or directory", "module": "model_loader", "function": "load_model", "line": "43", "process": "599", "thread": "140580654353280", "exception": {"type": "OSError", "message": "libgomp.so.1: cannot open shared object file: No such file or directory", "traceback": "Traceback (most recent call last):\n  File \"/app/flashcamp/backend/model_loader.py\", line 28, in load_model\n    model = joblib.load(absolute_path)\n            ^^^^^^^^^^^^^^^^^^^^^^^^^^\n  File \"/root/.local/lib/python3.11/site-packages/joblib/numpy_pickle.py\", line 658, in load\n    obj = _unpickle(fobj, filename, mmap_mode)\n          ^^^^^^^^^^^^^^^^^^^^^^^^^^^^^^^^^^^^\n  File \"/root/.local/lib/python3.11/site-packages/joblib/numpy_pickle.py\", line 577, in _unpickle\n    obj = unpickler.load()\n          ^^^^^^^^^^^^^^^^\n  File \"/usr/local/lib/python3.11/pickle.py\", line 1213, in load\n    dispatch[key[0]](self)\n  File \"/usr/local/lib/python3.11/pickle.py\", line 1538, in load_stack_global\n    self.append(self.find_class(module, name))\n                ^^^^^^^^^^^^^^^^^^^^^^^^^^^^^\n  File \"/usr/local/lib/python3.11/pickle.py\", line 1580, in find_class\n    __import__(module, level=0)\n  File \"/root/.local/lib/python3.11/site-packages/lightgbm/__init__.py\", line 8, in <module>\n    from .basic import Booster, Dataset, Sequence, register_logger\n  File \"/root/.local/lib/python3.11/site-packages/lightgbm/basic.py\", line 247, in <module>\n    _LIB = _load_lib()\n           ^^^^^^^^^^^\n  File \"/root/.local/lib/python3.11/site-packages/lightgbm/basic.py\", line 232, in _load_lib\n    lib = ctypes.cdll.LoadLibrary(lib_path[0])\n          ^^^^^^^^^^^^^^^^^^^^^^^^^^^^^^^^^^^^\n  File \"/usr/local/lib/python3.11/ctypes/__init__.py\", line 454, in LoadLibrary\n    return self._dlltype(name)\n           ^^^^^^^^^^^^^^^^^^^\n  File \"/usr/local/lib/python3.11/ctypes/__init__.py\", line 376, in __init__\n    self._handle = _dlopen(self._name, mode)\n                   ^^^^^^^^^^^^^^^^^^^^^^^^^\nOSError: libgomp.so.1: cannot open shared object file: No such file or directory"}}
{"timestamp": "2025-05-04 05:25:22,473", "level": "ERROR", "message": "Error loading model /app/flashcamp/models/pillar/market_lgbm.joblib: libgomp.so.1: cannot open shared object file: No such file or directory", "module": "model_loader", "function": "load_model", "line": "43", "process": "599", "thread": "140580654353280", "exception": {"type": "OSError", "message": "libgomp.so.1: cannot open shared object file: No such file or directory", "traceback": "Traceback (most recent call last):\n  File \"/app/flashcamp/backend/model_loader.py\", line 28, in load_model\n    model = joblib.load(absolute_path)\n            ^^^^^^^^^^^^^^^^^^^^^^^^^^\n  File \"/root/.local/lib/python3.11/site-packages/joblib/numpy_pickle.py\", line 658, in load\n    obj = _unpickle(fobj, filename, mmap_mode)\n          ^^^^^^^^^^^^^^^^^^^^^^^^^^^^^^^^^^^^\n  File \"/root/.local/lib/python3.11/site-packages/joblib/numpy_pickle.py\", line 577, in _unpickle\n    obj = unpickler.load()\n          ^^^^^^^^^^^^^^^^\n  File \"/usr/local/lib/python3.11/pickle.py\", line 1213, in load\n    dispatch[key[0]](self)\n  File \"/usr/local/lib/python3.11/pickle.py\", line 1538, in load_stack_global\n    self.append(self.find_class(module, name))\n                ^^^^^^^^^^^^^^^^^^^^^^^^^^^^^\n  File \"/usr/local/lib/python3.11/pickle.py\", line 1580, in find_class\n    __import__(module, level=0)\n  File \"/root/.local/lib/python3.11/site-packages/lightgbm/__init__.py\", line 8, in <module>\n    from .basic import Booster, Dataset, Sequence, register_logger\n  File \"/root/.local/lib/python3.11/site-packages/lightgbm/basic.py\", line 247, in <module>\n    _LIB = _load_lib()\n           ^^^^^^^^^^^\n  File \"/root/.local/lib/python3.11/site-packages/lightgbm/basic.py\", line 232, in _load_lib\n    lib = ctypes.cdll.LoadLibrary(lib_path[0])\n          ^^^^^^^^^^^^^^^^^^^^^^^^^^^^^^^^^^^^\n  File \"/usr/local/lib/python3.11/ctypes/__init__.py\", line 454, in LoadLibrary\n    return self._dlltype(name)\n           ^^^^^^^^^^^^^^^^^^^\n  File \"/usr/local/lib/python3.11/ctypes/__init__.py\", line 376, in __init__\n    self._handle = _dlopen(self._name, mode)\n                   ^^^^^^^^^^^^^^^^^^^^^^^^^\nOSError: libgomp.so.1: cannot open shared object file: No such file or directory"}}
{"timestamp": "2025-05-04 05:25:22,499", "level": "ERROR", "message": "Error loading model /app/flashcamp/models/pillar/people_lgbm.joblib: libgomp.so.1: cannot open shared object file: No such file or directory", "module": "model_loader", "function": "load_model", "line": "43", "process": "599", "thread": "140580654353280", "exception": {"type": "OSError", "message": "libgomp.so.1: cannot open shared object file: No such file or directory", "traceback": "Traceback (most recent call last):\n  File \"/app/flashcamp/backend/model_loader.py\", line 28, in load_model\n    model = joblib.load(absolute_path)\n            ^^^^^^^^^^^^^^^^^^^^^^^^^^\n  File \"/root/.local/lib/python3.11/site-packages/joblib/numpy_pickle.py\", line 658, in load\n    obj = _unpickle(fobj, filename, mmap_mode)\n          ^^^^^^^^^^^^^^^^^^^^^^^^^^^^^^^^^^^^\n  File \"/root/.local/lib/python3.11/site-packages/joblib/numpy_pickle.py\", line 577, in _unpickle\n    obj = unpickler.load()\n          ^^^^^^^^^^^^^^^^\n  File \"/usr/local/lib/python3.11/pickle.py\", line 1213, in load\n    dispatch[key[0]](self)\n  File \"/usr/local/lib/python3.11/pickle.py\", line 1538, in load_stack_global\n    self.append(self.find_class(module, name))\n                ^^^^^^^^^^^^^^^^^^^^^^^^^^^^^\n  File \"/usr/local/lib/python3.11/pickle.py\", line 1580, in find_class\n    __import__(module, level=0)\n  File \"/root/.local/lib/python3.11/site-packages/lightgbm/__init__.py\", line 8, in <module>\n    from .basic import Booster, Dataset, Sequence, register_logger\n  File \"/root/.local/lib/python3.11/site-packages/lightgbm/basic.py\", line 247, in <module>\n    _LIB = _load_lib()\n           ^^^^^^^^^^^\n  File \"/root/.local/lib/python3.11/site-packages/lightgbm/basic.py\", line 232, in _load_lib\n    lib = ctypes.cdll.LoadLibrary(lib_path[0])\n          ^^^^^^^^^^^^^^^^^^^^^^^^^^^^^^^^^^^^\n  File \"/usr/local/lib/python3.11/ctypes/__init__.py\", line 454, in LoadLibrary\n    return self._dlltype(name)\n           ^^^^^^^^^^^^^^^^^^^\n  File \"/usr/local/lib/python3.11/ctypes/__init__.py\", line 376, in __init__\n    self._handle = _dlopen(self._name, mode)\n                   ^^^^^^^^^^^^^^^^^^^^^^^^^\nOSError: libgomp.so.1: cannot open shared object file: No such file or directory"}}
{"timestamp": "2025-05-04 05:25:22,523", "level": "ERROR", "message": "Market model not loaded.", "module": "market", "function": "calculate_market_score", "line": "19", "process": "599", "thread": "140580654353280"}
{"timestamp": "2025-05-04 05:25:22,525", "level": "ERROR", "message": "Error calculating pillar scores: Market model not loaded or unavailable", "module": "analysis", "function": "pillar_scores", "line": "105", "process": "599", "thread": "140580654353280", "exception": {"type": "ValueError", "message": "Market model not loaded or unavailable", "traceback": "Traceback (most recent call last):\n  File \"/app/flashcamp/backend/analysis.py\", line 80, in pillar_scores\n    market_score, _ = calculate_market_score_fn(metrics_data)\n                      ^^^^^^^^^^^^^^^^^^^^^^^^^^^^^^^^^^^^^^^\n  File \"/app/flashcamp/backend/app/engines/market.py\", line 20, in calculate_market_score\n    raise ValueError(\"Market model not loaded or unavailable\")\nValueError: Market model not loaded or unavailable"}}
{"timestamp": "2025-05-04 05:25:22,540", "level": "ERROR", "message": "Error importing engine function _fallback_prediction: module 'flashcamp.backend.app.engines.ml' has no attribute '_fallback_prediction'", "module": "analysis", "function": "_import_engine_function", "line": "54", "process": "599", "thread": "140580654353280"}
{"timestamp": "2025-05-04 05:25:22,542", "level": "ERROR", "message": "Could not import fallback prediction function!", "module": "analysis", "function": "predict_success", "line": "178", "process": "599", "thread": "140580654353280"}
{"timestamp": "2025-05-04 05:25:46,222", "level": "ERROR", "message": "Market model not loaded.", "module": "market", "function": "calculate_market_score", "line": "19", "process": "599", "thread": "140580654353280"}
{"timestamp": "2025-05-04 05:25:46,225", "level": "ERROR", "message": "Error calculating pillar scores: Market model not loaded or unavailable", "module": "analysis", "function": "pillar_scores", "line": "105", "process": "599", "thread": "140580654353280", "exception": {"type": "ValueError", "message": "Market model not loaded or unavailable", "traceback": "Traceback (most recent call last):\n  File \"/app/flashcamp/backend/analysis.py\", line 80, in pillar_scores\n    market_score, _ = calculate_market_score_fn(metrics_data)\n                      ^^^^^^^^^^^^^^^^^^^^^^^^^^^^^^^^^^^^^^^\n  File \"/app/flashcamp/backend/app/engines/market.py\", line 20, in calculate_market_score\n    raise ValueError(\"Market model not loaded or unavailable\")\nValueError: Market model not loaded or unavailable"}}
{"timestamp": "2025-05-04 05:25:46,237", "level": "ERROR", "message": "Error importing engine function _fallback_prediction: module 'flashcamp.backend.app.engines.ml' has no attribute '_fallback_prediction'", "module": "analysis", "function": "_import_engine_function", "line": "54", "process": "599", "thread": "140580654353280"}
{"timestamp": "2025-05-04 05:25:46,239", "level": "ERROR", "message": "Could not import fallback prediction function!", "module": "analysis", "function": "predict_success", "line": "178", "process": "599", "thread": "140580654353280"}
{"timestamp": "2025-05-04 14:30:13,374", "level": "ERROR", "message": "Error calculating pillar scores: prepare() takes 1 positional argument but 2 were given", "module": "analysis", "function": "pillar_scores", "line": "105", "process": "64587", "thread": "140704646966208", "exception": {"type": "TypeError", "message": "prepare() takes 1 positional argument but 2 were given", "traceback": "Traceback (most recent call last):\n  File \"/Users/sf/Desktop/FLASH/flashcamp/backend/analysis.py\", line 80, in pillar_scores\n    market_score, _ = calculate_market_score_fn(metrics_data)\n                      ^^^^^^^^^^^^^^^^^^^^^^^^^^^^^^^^^^^^^^^\n  File \"/Users/sf/Desktop/FLASH/flashcamp/backend/app/engines/market.py\", line 23, in calculate_market_score\n    X = prepare(metrics, _model)\n        ^^^^^^^^^^^^^^^^^^^^^^^^\nTypeError: prepare() takes 1 positional argument but 2 were given"}}
{"timestamp": "2025-05-04 14:30:13,377", "level": "ERROR", "message": "Error importing engine function _fallback_prediction: module 'flashcamp.backend.app.engines.ml' has no attribute '_fallback_prediction'", "module": "analysis", "function": "_import_engine_function", "line": "54", "process": "64587", "thread": "140704646966208"}
{"timestamp": "2025-05-04 14:30:13,378", "level": "ERROR", "message": "Could not import fallback prediction function!", "module": "analysis", "function": "predict_success", "line": "178", "process": "64587", "thread": "140704646966208"}
{"timestamp": "2025-05-04 05:31:56,545", "level": "ERROR", "message": "Error loading model /app/flashcamp/models/pillar/capital_lgbm.joblib: libgomp.so.1: cannot open shared object file: No such file or directory", "module": "model_loader", "function": "load_model", "line": "43", "process": "708", "thread": "140151767849856", "exception": {"type": "OSError", "message": "libgomp.so.1: cannot open shared object file: No such file or directory", "traceback": "Traceback (most recent call last):\n  File \"/app/flashcamp/backend/model_loader.py\", line 28, in load_model\n    model = joblib.load(absolute_path)\n            ^^^^^^^^^^^^^^^^^^^^^^^^^^\n  File \"/root/.local/lib/python3.11/site-packages/joblib/numpy_pickle.py\", line 658, in load\n    obj = _unpickle(fobj, filename, mmap_mode)\n          ^^^^^^^^^^^^^^^^^^^^^^^^^^^^^^^^^^^^\n  File \"/root/.local/lib/python3.11/site-packages/joblib/numpy_pickle.py\", line 577, in _unpickle\n    obj = unpickler.load()\n          ^^^^^^^^^^^^^^^^\n  File \"/usr/local/lib/python3.11/pickle.py\", line 1213, in load\n    dispatch[key[0]](self)\n  File \"/usr/local/lib/python3.11/pickle.py\", line 1538, in load_stack_global\n    self.append(self.find_class(module, name))\n                ^^^^^^^^^^^^^^^^^^^^^^^^^^^^^\n  File \"/usr/local/lib/python3.11/pickle.py\", line 1580, in find_class\n    __import__(module, level=0)\n  File \"/root/.local/lib/python3.11/site-packages/lightgbm/__init__.py\", line 8, in <module>\n    from .basic import Booster, Dataset, Sequence, register_logger\n  File \"/root/.local/lib/python3.11/site-packages/lightgbm/basic.py\", line 247, in <module>\n    _LIB = _load_lib()\n           ^^^^^^^^^^^\n  File \"/root/.local/lib/python3.11/site-packages/lightgbm/basic.py\", line 232, in _load_lib\n    lib = ctypes.cdll.LoadLibrary(lib_path[0])\n          ^^^^^^^^^^^^^^^^^^^^^^^^^^^^^^^^^^^^\n  File \"/usr/local/lib/python3.11/ctypes/__init__.py\", line 454, in LoadLibrary\n    return self._dlltype(name)\n           ^^^^^^^^^^^^^^^^^^^\n  File \"/usr/local/lib/python3.11/ctypes/__init__.py\", line 376, in __init__\n    self._handle = _dlopen(self._name, mode)\n                   ^^^^^^^^^^^^^^^^^^^^^^^^^\nOSError: libgomp.so.1: cannot open shared object file: No such file or directory"}}
{"timestamp": "2025-05-04 05:31:56,647", "level": "ERROR", "message": "Error loading model /app/flashcamp/models/pillar/advantage_lgbm.joblib: libgomp.so.1: cannot open shared object file: No such file or directory", "module": "model_loader", "function": "load_model", "line": "43", "process": "708", "thread": "140151767849856", "exception": {"type": "OSError", "message": "libgomp.so.1: cannot open shared object file: No such file or directory", "traceback": "Traceback (most recent call last):\n  File \"/app/flashcamp/backend/model_loader.py\", line 28, in load_model\n    model = joblib.load(absolute_path)\n            ^^^^^^^^^^^^^^^^^^^^^^^^^^\n  File \"/root/.local/lib/python3.11/site-packages/joblib/numpy_pickle.py\", line 658, in load\n    obj = _unpickle(fobj, filename, mmap_mode)\n          ^^^^^^^^^^^^^^^^^^^^^^^^^^^^^^^^^^^^\n  File \"/root/.local/lib/python3.11/site-packages/joblib/numpy_pickle.py\", line 577, in _unpickle\n    obj = unpickler.load()\n          ^^^^^^^^^^^^^^^^\n  File \"/usr/local/lib/python3.11/pickle.py\", line 1213, in load\n    dispatch[key[0]](self)\n  File \"/usr/local/lib/python3.11/pickle.py\", line 1538, in load_stack_global\n    self.append(self.find_class(module, name))\n                ^^^^^^^^^^^^^^^^^^^^^^^^^^^^^\n  File \"/usr/local/lib/python3.11/pickle.py\", line 1580, in find_class\n    __import__(module, level=0)\n  File \"/root/.local/lib/python3.11/site-packages/lightgbm/__init__.py\", line 8, in <module>\n    from .basic import Booster, Dataset, Sequence, register_logger\n  File \"/root/.local/lib/python3.11/site-packages/lightgbm/basic.py\", line 247, in <module>\n    _LIB = _load_lib()\n           ^^^^^^^^^^^\n  File \"/root/.local/lib/python3.11/site-packages/lightgbm/basic.py\", line 232, in _load_lib\n    lib = ctypes.cdll.LoadLibrary(lib_path[0])\n          ^^^^^^^^^^^^^^^^^^^^^^^^^^^^^^^^^^^^\n  File \"/usr/local/lib/python3.11/ctypes/__init__.py\", line 454, in LoadLibrary\n    return self._dlltype(name)\n           ^^^^^^^^^^^^^^^^^^^\n  File \"/usr/local/lib/python3.11/ctypes/__init__.py\", line 376, in __init__\n    self._handle = _dlopen(self._name, mode)\n                   ^^^^^^^^^^^^^^^^^^^^^^^^^\nOSError: libgomp.so.1: cannot open shared object file: No such file or directory"}}
{"timestamp": "2025-05-04 05:31:56,687", "level": "ERROR", "message": "Error loading model /app/flashcamp/models/pillar/market_lgbm.joblib: libgomp.so.1: cannot open shared object file: No such file or directory", "module": "model_loader", "function": "load_model", "line": "43", "process": "708", "thread": "140151767849856", "exception": {"type": "OSError", "message": "libgomp.so.1: cannot open shared object file: No such file or directory", "traceback": "Traceback (most recent call last):\n  File \"/app/flashcamp/backend/model_loader.py\", line 28, in load_model\n    model = joblib.load(absolute_path)\n            ^^^^^^^^^^^^^^^^^^^^^^^^^^\n  File \"/root/.local/lib/python3.11/site-packages/joblib/numpy_pickle.py\", line 658, in load\n    obj = _unpickle(fobj, filename, mmap_mode)\n          ^^^^^^^^^^^^^^^^^^^^^^^^^^^^^^^^^^^^\n  File \"/root/.local/lib/python3.11/site-packages/joblib/numpy_pickle.py\", line 577, in _unpickle\n    obj = unpickler.load()\n          ^^^^^^^^^^^^^^^^\n  File \"/usr/local/lib/python3.11/pickle.py\", line 1213, in load\n    dispatch[key[0]](self)\n  File \"/usr/local/lib/python3.11/pickle.py\", line 1538, in load_stack_global\n    self.append(self.find_class(module, name))\n                ^^^^^^^^^^^^^^^^^^^^^^^^^^^^^\n  File \"/usr/local/lib/python3.11/pickle.py\", line 1580, in find_class\n    __import__(module, level=0)\n  File \"/root/.local/lib/python3.11/site-packages/lightgbm/__init__.py\", line 8, in <module>\n    from .basic import Booster, Dataset, Sequence, register_logger\n  File \"/root/.local/lib/python3.11/site-packages/lightgbm/basic.py\", line 247, in <module>\n    _LIB = _load_lib()\n           ^^^^^^^^^^^\n  File \"/root/.local/lib/python3.11/site-packages/lightgbm/basic.py\", line 232, in _load_lib\n    lib = ctypes.cdll.LoadLibrary(lib_path[0])\n          ^^^^^^^^^^^^^^^^^^^^^^^^^^^^^^^^^^^^\n  File \"/usr/local/lib/python3.11/ctypes/__init__.py\", line 454, in LoadLibrary\n    return self._dlltype(name)\n           ^^^^^^^^^^^^^^^^^^^\n  File \"/usr/local/lib/python3.11/ctypes/__init__.py\", line 376, in __init__\n    self._handle = _dlopen(self._name, mode)\n                   ^^^^^^^^^^^^^^^^^^^^^^^^^\nOSError: libgomp.so.1: cannot open shared object file: No such file or directory"}}
{"timestamp": "2025-05-04 05:31:56,726", "level": "ERROR", "message": "Error loading model /app/flashcamp/models/pillar/people_lgbm.joblib: libgomp.so.1: cannot open shared object file: No such file or directory", "module": "model_loader", "function": "load_model", "line": "43", "process": "708", "thread": "140151767849856", "exception": {"type": "OSError", "message": "libgomp.so.1: cannot open shared object file: No such file or directory", "traceback": "Traceback (most recent call last):\n  File \"/app/flashcamp/backend/model_loader.py\", line 28, in load_model\n    model = joblib.load(absolute_path)\n            ^^^^^^^^^^^^^^^^^^^^^^^^^^\n  File \"/root/.local/lib/python3.11/site-packages/joblib/numpy_pickle.py\", line 658, in load\n    obj = _unpickle(fobj, filename, mmap_mode)\n          ^^^^^^^^^^^^^^^^^^^^^^^^^^^^^^^^^^^^\n  File \"/root/.local/lib/python3.11/site-packages/joblib/numpy_pickle.py\", line 577, in _unpickle\n    obj = unpickler.load()\n          ^^^^^^^^^^^^^^^^\n  File \"/usr/local/lib/python3.11/pickle.py\", line 1213, in load\n    dispatch[key[0]](self)\n  File \"/usr/local/lib/python3.11/pickle.py\", line 1538, in load_stack_global\n    self.append(self.find_class(module, name))\n                ^^^^^^^^^^^^^^^^^^^^^^^^^^^^^\n  File \"/usr/local/lib/python3.11/pickle.py\", line 1580, in find_class\n    __import__(module, level=0)\n  File \"/root/.local/lib/python3.11/site-packages/lightgbm/__init__.py\", line 8, in <module>\n    from .basic import Booster, Dataset, Sequence, register_logger\n  File \"/root/.local/lib/python3.11/site-packages/lightgbm/basic.py\", line 247, in <module>\n    _LIB = _load_lib()\n           ^^^^^^^^^^^\n  File \"/root/.local/lib/python3.11/site-packages/lightgbm/basic.py\", line 232, in _load_lib\n    lib = ctypes.cdll.LoadLibrary(lib_path[0])\n          ^^^^^^^^^^^^^^^^^^^^^^^^^^^^^^^^^^^^\n  File \"/usr/local/lib/python3.11/ctypes/__init__.py\", line 454, in LoadLibrary\n    return self._dlltype(name)\n           ^^^^^^^^^^^^^^^^^^^\n  File \"/usr/local/lib/python3.11/ctypes/__init__.py\", line 376, in __init__\n    self._handle = _dlopen(self._name, mode)\n                   ^^^^^^^^^^^^^^^^^^^^^^^^^\nOSError: libgomp.so.1: cannot open shared object file: No such file or directory"}}
{"timestamp": "2025-05-04 05:31:56,756", "level": "ERROR", "message": "Market model not loaded.", "module": "market", "function": "calculate_market_score", "line": "19", "process": "708", "thread": "140151767849856"}
{"timestamp": "2025-05-04 05:31:56,759", "level": "ERROR", "message": "Error calculating pillar scores: Market model not loaded or unavailable", "module": "analysis", "function": "pillar_scores", "line": "105", "process": "708", "thread": "140151767849856", "exception": {"type": "ValueError", "message": "Market model not loaded or unavailable", "traceback": "Traceback (most recent call last):\n  File \"/app/flashcamp/backend/analysis.py\", line 80, in pillar_scores\n    market_score, _ = calculate_market_score_fn(metrics_data)\n                      ^^^^^^^^^^^^^^^^^^^^^^^^^^^^^^^^^^^^^^^\n  File \"/app/flashcamp/backend/app/engines/market.py\", line 20, in calculate_market_score\n    raise ValueError(\"Market model not loaded or unavailable\")\nValueError: Market model not loaded or unavailable"}}
{"timestamp": "2025-05-04 05:31:56,775", "level": "ERROR", "message": "Error importing engine function _fallback_prediction: module 'flashcamp.backend.app.engines.ml' has no attribute '_fallback_prediction'", "module": "analysis", "function": "_import_engine_function", "line": "54", "process": "708", "thread": "140151767849856"}
{"timestamp": "2025-05-04 05:31:56,778", "level": "ERROR", "message": "Could not import fallback prediction function!", "module": "analysis", "function": "predict_success", "line": "178", "process": "708", "thread": "140151767849856"}
{"timestamp": "2025-05-04 14:35:08,002", "level": "ERROR", "message": "Error calculating pillar scores: prepare() takes 1 positional argument but 2 were given", "module": "analysis", "function": "pillar_scores", "line": "105", "process": "65102", "thread": "140704646966208", "exception": {"type": "TypeError", "message": "prepare() takes 1 positional argument but 2 were given", "traceback": "Traceback (most recent call last):\n  File \"/Users/sf/Desktop/FLASH/flashcamp/backend/analysis.py\", line 80, in pillar_scores\n    market_score, _ = calculate_market_score_fn(metrics_data)\n                      ^^^^^^^^^^^^^^^^^^^^^^^^^^^^^^^^^^^^^^^\n  File \"/Users/sf/Desktop/FLASH/flashcamp/backend/app/engines/market.py\", line 23, in calculate_market_score\n    X = prepare(metrics, _model)\n        ^^^^^^^^^^^^^^^^^^^^^^^^\nTypeError: prepare() takes 1 positional argument but 2 were given"}}
{"timestamp": "2025-05-04 14:35:08,021", "level": "ERROR", "message": "Error importing engine function _fallback_prediction: module 'flashcamp.backend.app.engines.ml' has no attribute '_fallback_prediction'", "module": "analysis", "function": "_import_engine_function", "line": "54", "process": "65102", "thread": "140704646966208"}
{"timestamp": "2025-05-04 14:35:08,024", "level": "ERROR", "message": "Could not import fallback prediction function!", "module": "analysis", "function": "predict_success", "line": "178", "process": "65102", "thread": "140704646966208"}
{"timestamp": "2025-05-04 14:36:29,224", "level": "ERROR", "message": "Error calculating pillar scores: prepare() takes 1 positional argument but 2 were given", "module": "analysis", "function": "pillar_scores", "line": "105", "process": "65102", "thread": "140704646966208", "exception": {"type": "TypeError", "message": "prepare() takes 1 positional argument but 2 were given", "traceback": "Traceback (most recent call last):\n  File \"/Users/sf/Desktop/FLASH/flashcamp/backend/analysis.py\", line 80, in pillar_scores\n    market_score, _ = calculate_market_score_fn(metrics_data)\n                      ^^^^^^^^^^^^^^^^^^^^^^^^^^^^^^^^^^^^^^^\n  File \"/Users/sf/Desktop/FLASH/flashcamp/backend/app/engines/market.py\", line 23, in calculate_market_score\n    X = prepare(metrics, _model)\n        ^^^^^^^^^^^^^^^^^^^^^^^^\nTypeError: prepare() takes 1 positional argument but 2 were given"}}
{"timestamp": "2025-05-04 14:36:29,227", "level": "ERROR", "message": "Error importing engine function _fallback_prediction: module 'flashcamp.backend.app.engines.ml' has no attribute '_fallback_prediction'", "module": "analysis", "function": "_import_engine_function", "line": "54", "process": "65102", "thread": "140704646966208"}
{"timestamp": "2025-05-04 14:36:29,228", "level": "ERROR", "message": "Could not import fallback prediction function!", "module": "analysis", "function": "predict_success", "line": "178", "process": "65102", "thread": "140704646966208"}
{"timestamp": "2025-05-04 14:37:14,304", "level": "ERROR", "message": "Error calculating pillar scores: prepare() takes 1 positional argument but 2 were given", "module": "analysis", "function": "pillar_scores", "line": "105", "process": "65102", "thread": "140704646966208", "exception": {"type": "TypeError", "message": "prepare() takes 1 positional argument but 2 were given", "traceback": "Traceback (most recent call last):\n  File \"/Users/sf/Desktop/FLASH/flashcamp/backend/analysis.py\", line 80, in pillar_scores\n    market_score, _ = calculate_market_score_fn(metrics_data)\n                      ^^^^^^^^^^^^^^^^^^^^^^^^^^^^^^^^^^^^^^^\n  File \"/Users/sf/Desktop/FLASH/flashcamp/backend/app/engines/market.py\", line 23, in calculate_market_score\n    X = prepare(metrics, _model)\n        ^^^^^^^^^^^^^^^^^^^^^^^^\nTypeError: prepare() takes 1 positional argument but 2 were given"}}
{"timestamp": "2025-05-04 14:37:14,308", "level": "ERROR", "message": "Error importing engine function _fallback_prediction: module 'flashcamp.backend.app.engines.ml' has no attribute '_fallback_prediction'", "module": "analysis", "function": "_import_engine_function", "line": "54", "process": "65102", "thread": "140704646966208"}
{"timestamp": "2025-05-04 14:37:14,309", "level": "ERROR", "message": "Could not import fallback prediction function!", "module": "analysis", "function": "predict_success", "line": "178", "process": "65102", "thread": "140704646966208"}
{"timestamp": "2025-05-04 14:40:20,018", "level": "ERROR", "message": "Error calculating pillar scores: prepare() takes 1 positional argument but 2 were given", "module": "analysis", "function": "pillar_scores", "line": "105", "process": "65102", "thread": "140704646966208", "exception": {"type": "TypeError", "message": "prepare() takes 1 positional argument but 2 were given", "traceback": "Traceback (most recent call last):\n  File \"/Users/sf/Desktop/FLASH/flashcamp/backend/analysis.py\", line 80, in pillar_scores\n    market_score, _ = calculate_market_score_fn(metrics_data)\n                      ^^^^^^^^^^^^^^^^^^^^^^^^^^^^^^^^^^^^^^^\n  File \"/Users/sf/Desktop/FLASH/flashcamp/backend/app/engines/market.py\", line 23, in calculate_market_score\n    X = prepare(metrics, _model)\n        ^^^^^^^^^^^^^^^^^^^^^^^^\nTypeError: prepare() takes 1 positional argument but 2 were given"}}
{"timestamp": "2025-05-04 14:40:20,025", "level": "ERROR", "message": "Error importing engine function _fallback_prediction: module 'flashcamp.backend.app.engines.ml' has no attribute '_fallback_prediction'", "module": "analysis", "function": "_import_engine_function", "line": "54", "process": "65102", "thread": "140704646966208"}
{"timestamp": "2025-05-04 14:40:20,026", "level": "ERROR", "message": "Could not import fallback prediction function!", "module": "analysis", "function": "predict_success", "line": "178", "process": "65102", "thread": "140704646966208"}
{"timestamp": "2025-05-04 14:40:52,584", "level": "ERROR", "message": "Error calculating pillar scores: prepare() takes 1 positional argument but 2 were given", "module": "analysis", "function": "pillar_scores", "line": "105", "process": "65102", "thread": "140704646966208", "exception": {"type": "TypeError", "message": "prepare() takes 1 positional argument but 2 were given", "traceback": "Traceback (most recent call last):\n  File \"/Users/sf/Desktop/FLASH/flashcamp/backend/analysis.py\", line 80, in pillar_scores\n    market_score, _ = calculate_market_score_fn(metrics_data)\n                      ^^^^^^^^^^^^^^^^^^^^^^^^^^^^^^^^^^^^^^^\n  File \"/Users/sf/Desktop/FLASH/flashcamp/backend/app/engines/market.py\", line 23, in calculate_market_score\n    X = prepare(metrics, _model)\n        ^^^^^^^^^^^^^^^^^^^^^^^^\nTypeError: prepare() takes 1 positional argument but 2 were given"}}
{"timestamp": "2025-05-04 14:40:52,590", "level": "ERROR", "message": "Error importing engine function _fallback_prediction: module 'flashcamp.backend.app.engines.ml' has no attribute '_fallback_prediction'", "module": "analysis", "function": "_import_engine_function", "line": "54", "process": "65102", "thread": "140704646966208"}
{"timestamp": "2025-05-04 14:40:52,590", "level": "ERROR", "message": "Could not import fallback prediction function!", "module": "analysis", "function": "predict_success", "line": "178", "process": "65102", "thread": "140704646966208"}
{"timestamp": "2025-05-04 15:43:26,594", "level": "ERROR", "message": "Error calculating pillar scores: prepare() takes 1 positional argument but 2 were given", "module": "analysis", "function": "pillar_scores", "line": "105", "process": "65102", "thread": "140704646966208", "exception": {"type": "TypeError", "message": "prepare() takes 1 positional argument but 2 were given", "traceback": "Traceback (most recent call last):\n  File \"/Users/sf/Desktop/FLASH/flashcamp/backend/analysis.py\", line 80, in pillar_scores\n    market_score, _ = calculate_market_score_fn(metrics_data)\n                      ^^^^^^^^^^^^^^^^^^^^^^^^^^^^^^^^^^^^^^^\n  File \"/Users/sf/Desktop/FLASH/flashcamp/backend/app/engines/market.py\", line 23, in calculate_market_score\n    X = prepare(metrics, _model)\n        ^^^^^^^^^^^^^^^^^^^^^^^^\nTypeError: prepare() takes 1 positional argument but 2 were given"}}
{"timestamp": "2025-05-04 15:43:26,605", "level": "ERROR", "message": "Error importing engine function _fallback_prediction: module 'flashcamp.backend.app.engines.ml' has no attribute '_fallback_prediction'", "module": "analysis", "function": "_import_engine_function", "line": "54", "process": "65102", "thread": "140704646966208"}
{"timestamp": "2025-05-04 15:43:26,606", "level": "ERROR", "message": "Could not import fallback prediction function!", "module": "analysis", "function": "predict_success", "line": "178", "process": "65102", "thread": "140704646966208"}
{"timestamp": "2025-05-04 16:29:18,246", "level": "ERROR", "message": "Error calculating pillar scores: prepare() takes 1 positional argument but 2 were given", "module": "analysis", "function": "pillar_scores", "line": "105", "process": "65102", "thread": "140704646966208", "exception": {"type": "TypeError", "message": "prepare() takes 1 positional argument but 2 were given", "traceback": "Traceback (most recent call last):\n  File \"/Users/sf/Desktop/FLASH/flashcamp/backend/analysis.py\", line 80, in pillar_scores\n    market_score, _ = calculate_market_score_fn(metrics_data)\n                      ^^^^^^^^^^^^^^^^^^^^^^^^^^^^^^^^^^^^^^^\n  File \"/Users/sf/Desktop/FLASH/flashcamp/backend/app/engines/market.py\", line 23, in calculate_market_score\n    X = prepare(metrics, _model)\n        ^^^^^^^^^^^^^^^^^^^^^^^^\nTypeError: prepare() takes 1 positional argument but 2 were given"}}
{"timestamp": "2025-05-04 16:29:18,268", "level": "ERROR", "message": "Error importing engine function _fallback_prediction: module 'flashcamp.backend.app.engines.ml' has no attribute '_fallback_prediction'", "module": "analysis", "function": "_import_engine_function", "line": "54", "process": "65102", "thread": "140704646966208"}
{"timestamp": "2025-05-04 16:29:18,269", "level": "ERROR", "message": "Could not import fallback prediction function!", "module": "analysis", "function": "predict_success", "line": "178", "process": "65102", "thread": "140704646966208"}
{"timestamp": "2025-05-04 17:30:35,683", "level": "ERROR", "message": "Error calculating pillar scores: prepare() takes 1 positional argument but 2 were given", "module": "analysis", "function": "pillar_scores", "line": "105", "process": "81345", "thread": "140704646966208", "exception": {"type": "TypeError", "message": "prepare() takes 1 positional argument but 2 were given", "traceback": "Traceback (most recent call last):\n  File \"/Users/sf/Desktop/FLASH/flashcamp/backend/analysis.py\", line 80, in pillar_scores\n    market_score, _ = calculate_market_score_fn(metrics_data)\n                      ^^^^^^^^^^^^^^^^^^^^^^^^^^^^^^^^^^^^^^^\n  File \"/Users/sf/Desktop/FLASH/flashcamp/backend/app/engines/market.py\", line 23, in calculate_market_score\n    X = prepare(metrics, _model)\n        ^^^^^^^^^^^^^^^^^^^^^^^^\nTypeError: prepare() takes 1 positional argument but 2 were given"}}
{"timestamp": "2025-05-04 17:30:35,690", "level": "ERROR", "message": "Error importing engine function _fallback_prediction: module 'flashcamp.backend.app.engines.ml' has no attribute '_fallback_prediction'", "module": "analysis", "function": "_import_engine_function", "line": "54", "process": "81345", "thread": "140704646966208"}
{"timestamp": "2025-05-04 17:30:35,690", "level": "ERROR", "message": "Could not import fallback prediction function!", "module": "analysis", "function": "predict_success", "line": "178", "process": "81345", "thread": "140704646966208"}
{"timestamp": "2025-05-04 18:34:20,866", "level": "ERROR", "message": "Error calculating pillar scores: prepare() takes 1 positional argument but 2 were given", "module": "analysis", "function": "pillar_scores", "line": "105", "process": "81345", "thread": "140704646966208", "exception": {"type": "TypeError", "message": "prepare() takes 1 positional argument but 2 were given", "traceback": "Traceback (most recent call last):\n  File \"/Users/sf/Desktop/FLASH/flashcamp/backend/analysis.py\", line 80, in pillar_scores\n    market_score, _ = calculate_market_score_fn(metrics_data)\n                      ^^^^^^^^^^^^^^^^^^^^^^^^^^^^^^^^^^^^^^^\n  File \"/Users/sf/Desktop/FLASH/flashcamp/backend/app/engines/market.py\", line 23, in calculate_market_score\n    X = prepare(metrics, _model)\n        ^^^^^^^^^^^^^^^^^^^^^^^^\nTypeError: prepare() takes 1 positional argument but 2 were given"}}
{"timestamp": "2025-05-04 18:34:20,872", "level": "ERROR", "message": "Error importing engine function _fallback_prediction: module 'flashcamp.backend.app.engines.ml' has no attribute '_fallback_prediction'", "module": "analysis", "function": "_import_engine_function", "line": "54", "process": "81345", "thread": "140704646966208"}
{"timestamp": "2025-05-04 18:34:20,872", "level": "ERROR", "message": "Could not import fallback prediction function!", "module": "analysis", "function": "predict_success", "line": "178", "process": "81345", "thread": "140704646966208"}
{"timestamp": "2025-05-04 18:34:48,282", "level": "ERROR", "message": "Error calculating pillar scores: prepare() takes 1 positional argument but 2 were given", "module": "analysis", "function": "pillar_scores", "line": "105", "process": "81345", "thread": "140704646966208", "exception": {"type": "TypeError", "message": "prepare() takes 1 positional argument but 2 were given", "traceback": "Traceback (most recent call last):\n  File \"/Users/sf/Desktop/FLASH/flashcamp/backend/analysis.py\", line 80, in pillar_scores\n    market_score, _ = calculate_market_score_fn(metrics_data)\n                      ^^^^^^^^^^^^^^^^^^^^^^^^^^^^^^^^^^^^^^^\n  File \"/Users/sf/Desktop/FLASH/flashcamp/backend/app/engines/market.py\", line 23, in calculate_market_score\n    X = prepare(metrics, _model)\n        ^^^^^^^^^^^^^^^^^^^^^^^^\nTypeError: prepare() takes 1 positional argument but 2 were given"}}
{"timestamp": "2025-05-04 18:34:48,285", "level": "ERROR", "message": "Error importing engine function _fallback_prediction: module 'flashcamp.backend.app.engines.ml' has no attribute '_fallback_prediction'", "module": "analysis", "function": "_import_engine_function", "line": "54", "process": "81345", "thread": "140704646966208"}
{"timestamp": "2025-05-04 18:34:48,286", "level": "ERROR", "message": "Could not import fallback prediction function!", "module": "analysis", "function": "predict_success", "line": "178", "process": "81345", "thread": "140704646966208"}
{"timestamp": "2025-05-04 18:42:10,540", "level": "ERROR", "message": "Error calculating pillar scores: prepare() takes 1 positional argument but 2 were given", "module": "analysis", "function": "pillar_scores", "line": "105", "process": "82837", "thread": "140704646966208", "exception": {"type": "TypeError", "message": "prepare() takes 1 positional argument but 2 were given", "traceback": "Traceback (most recent call last):\n  File \"/Users/sf/Desktop/FLASH/flashcamp/backend/analysis.py\", line 80, in pillar_scores\n    market_score, _ = calculate_market_score_fn(metrics_data)\n                      ^^^^^^^^^^^^^^^^^^^^^^^^^^^^^^^^^^^^^^^\n  File \"/Users/sf/Desktop/FLASH/flashcamp/backend/app/engines/market.py\", line 23, in calculate_market_score\n    X = prepare(metrics, _model)\n        ^^^^^^^^^^^^^^^^^^^^^^^^\nTypeError: prepare() takes 1 positional argument but 2 were given"}}
{"timestamp": "2025-05-04 18:42:10,548", "level": "ERROR", "message": "Error importing engine function _fallback_prediction: module 'flashcamp.backend.app.engines.ml' has no attribute '_fallback_prediction'", "module": "analysis", "function": "_import_engine_function", "line": "54", "process": "82837", "thread": "140704646966208"}
{"timestamp": "2025-05-04 18:42:10,548", "level": "ERROR", "message": "Could not import fallback prediction function!", "module": "analysis", "function": "predict_success", "line": "178", "process": "82837", "thread": "140704646966208"}
{"timestamp": "2025-05-04 18:42:19,337", "level": "ERROR", "message": "Error calculating pillar scores: prepare() takes 1 positional argument but 2 were given", "module": "analysis", "function": "pillar_scores", "line": "105", "process": "82837", "thread": "140704646966208", "exception": {"type": "TypeError", "message": "prepare() takes 1 positional argument but 2 were given", "traceback": "Traceback (most recent call last):\n  File \"/Users/sf/Desktop/FLASH/flashcamp/backend/analysis.py\", line 80, in pillar_scores\n    market_score, _ = calculate_market_score_fn(metrics_data)\n                      ^^^^^^^^^^^^^^^^^^^^^^^^^^^^^^^^^^^^^^^\n  File \"/Users/sf/Desktop/FLASH/flashcamp/backend/app/engines/market.py\", line 23, in calculate_market_score\n    X = prepare(metrics, _model)\n        ^^^^^^^^^^^^^^^^^^^^^^^^\nTypeError: prepare() takes 1 positional argument but 2 were given"}}
{"timestamp": "2025-05-04 18:42:19,340", "level": "ERROR", "message": "Error importing engine function _fallback_prediction: module 'flashcamp.backend.app.engines.ml' has no attribute '_fallback_prediction'", "module": "analysis", "function": "_import_engine_function", "line": "54", "process": "82837", "thread": "140704646966208"}
{"timestamp": "2025-05-04 18:42:19,341", "level": "ERROR", "message": "Could not import fallback prediction function!", "module": "analysis", "function": "predict_success", "line": "178", "process": "82837", "thread": "140704646966208"}
{"timestamp": "2025-05-04 18:42:28,941", "level": "ERROR", "message": "Error calculating pillar scores: prepare() takes 1 positional argument but 2 were given", "module": "analysis", "function": "pillar_scores", "line": "105", "process": "82837", "thread": "140704646966208", "exception": {"type": "TypeError", "message": "prepare() takes 1 positional argument but 2 were given", "traceback": "Traceback (most recent call last):\n  File \"/Users/sf/Desktop/FLASH/flashcamp/backend/analysis.py\", line 80, in pillar_scores\n    market_score, _ = calculate_market_score_fn(metrics_data)\n                      ^^^^^^^^^^^^^^^^^^^^^^^^^^^^^^^^^^^^^^^\n  File \"/Users/sf/Desktop/FLASH/flashcamp/backend/app/engines/market.py\", line 23, in calculate_market_score\n    X = prepare(metrics, _model)\n        ^^^^^^^^^^^^^^^^^^^^^^^^\nTypeError: prepare() takes 1 positional argument but 2 were given"}}
{"timestamp": "2025-05-04 18:42:28,944", "level": "ERROR", "message": "Error importing engine function _fallback_prediction: module 'flashcamp.backend.app.engines.ml' has no attribute '_fallback_prediction'", "module": "analysis", "function": "_import_engine_function", "line": "54", "process": "82837", "thread": "140704646966208"}
{"timestamp": "2025-05-04 18:42:28,944", "level": "ERROR", "message": "Could not import fallback prediction function!", "module": "analysis", "function": "predict_success", "line": "178", "process": "82837", "thread": "140704646966208"}
{"timestamp": "2025-05-04 18:43:25,877", "level": "ERROR", "message": "Error calculating pillar scores: prepare() takes 1 positional argument but 2 were given", "module": "analysis", "function": "pillar_scores", "line": "105", "process": "82837", "thread": "140704646966208", "exception": {"type": "TypeError", "message": "prepare() takes 1 positional argument but 2 were given", "traceback": "Traceback (most recent call last):\n  File \"/Users/sf/Desktop/FLASH/flashcamp/backend/analysis.py\", line 80, in pillar_scores\n    market_score, _ = calculate_market_score_fn(metrics_data)\n                      ^^^^^^^^^^^^^^^^^^^^^^^^^^^^^^^^^^^^^^^\n  File \"/Users/sf/Desktop/FLASH/flashcamp/backend/app/engines/market.py\", line 23, in calculate_market_score\n    X = prepare(metrics, _model)\n        ^^^^^^^^^^^^^^^^^^^^^^^^\nTypeError: prepare() takes 1 positional argument but 2 were given"}}
{"timestamp": "2025-05-04 18:43:25,881", "level": "ERROR", "message": "Error importing engine function _fallback_prediction: module 'flashcamp.backend.app.engines.ml' has no attribute '_fallback_prediction'", "module": "analysis", "function": "_import_engine_function", "line": "54", "process": "82837", "thread": "140704646966208"}
{"timestamp": "2025-05-04 18:43:25,881", "level": "ERROR", "message": "Could not import fallback prediction function!", "module": "analysis", "function": "predict_success", "line": "178", "process": "82837", "thread": "140704646966208"}
{"timestamp": "2025-05-04 18:46:29,457", "level": "ERROR", "message": "Error calculating pillar scores: prepare() takes 1 positional argument but 2 were given", "module": "analysis", "function": "pillar_scores", "line": "105", "process": "83462", "thread": "140704646966208", "exception": {"type": "TypeError", "message": "prepare() takes 1 positional argument but 2 were given", "traceback": "Traceback (most recent call last):\n  File \"/Users/sf/Desktop/FLASH/flashcamp/backend/analysis.py\", line 80, in pillar_scores\n    market_score, _ = calculate_market_score_fn(metrics_data)\n                      ^^^^^^^^^^^^^^^^^^^^^^^^^^^^^^^^^^^^^^^\n  File \"/Users/sf/Desktop/FLASH/flashcamp/backend/app/engines/market.py\", line 23, in calculate_market_score\n    X = prepare(metrics, _model)\n        ^^^^^^^^^^^^^^^^^^^^^^^^\nTypeError: prepare() takes 1 positional argument but 2 were given"}}
{"timestamp": "2025-05-04 18:46:29,466", "level": "ERROR", "message": "Error importing engine function _fallback_prediction: module 'flashcamp.backend.app.engines.ml' has no attribute '_fallback_prediction'", "module": "analysis", "function": "_import_engine_function", "line": "54", "process": "83462", "thread": "140704646966208"}
{"timestamp": "2025-05-04 18:46:29,466", "level": "ERROR", "message": "Could not import fallback prediction function!", "module": "analysis", "function": "predict_success", "line": "178", "process": "83462", "thread": "140704646966208"}
{"timestamp": "2025-05-04 18:46:35,641", "level": "ERROR", "message": "Error calculating pillar scores: prepare() takes 1 positional argument but 2 were given", "module": "analysis", "function": "pillar_scores", "line": "105", "process": "83462", "thread": "140704646966208", "exception": {"type": "TypeError", "message": "prepare() takes 1 positional argument but 2 were given", "traceback": "Traceback (most recent call last):\n  File \"/Users/sf/Desktop/FLASH/flashcamp/backend/analysis.py\", line 80, in pillar_scores\n    market_score, _ = calculate_market_score_fn(metrics_data)\n                      ^^^^^^^^^^^^^^^^^^^^^^^^^^^^^^^^^^^^^^^\n  File \"/Users/sf/Desktop/FLASH/flashcamp/backend/app/engines/market.py\", line 23, in calculate_market_score\n    X = prepare(metrics, _model)\n        ^^^^^^^^^^^^^^^^^^^^^^^^\nTypeError: prepare() takes 1 positional argument but 2 were given"}}
{"timestamp": "2025-05-04 18:46:35,644", "level": "ERROR", "message": "Error importing engine function _fallback_prediction: module 'flashcamp.backend.app.engines.ml' has no attribute '_fallback_prediction'", "module": "analysis", "function": "_import_engine_function", "line": "54", "process": "83462", "thread": "140704646966208"}
{"timestamp": "2025-05-04 18:46:35,645", "level": "ERROR", "message": "Could not import fallback prediction function!", "module": "analysis", "function": "predict_success", "line": "178", "process": "83462", "thread": "140704646966208"}
{"timestamp": "2025-05-04 18:47:31,103", "level": "ERROR", "message": "Error calculating pillar scores: prepare() takes 1 positional argument but 2 were given", "module": "analysis", "function": "pillar_scores", "line": "105", "process": "83462", "thread": "140704646966208", "exception": {"type": "TypeError", "message": "prepare() takes 1 positional argument but 2 were given", "traceback": "Traceback (most recent call last):\n  File \"/Users/sf/Desktop/FLASH/flashcamp/backend/analysis.py\", line 80, in pillar_scores\n    market_score, _ = calculate_market_score_fn(metrics_data)\n                      ^^^^^^^^^^^^^^^^^^^^^^^^^^^^^^^^^^^^^^^\n  File \"/Users/sf/Desktop/FLASH/flashcamp/backend/app/engines/market.py\", line 23, in calculate_market_score\n    X = prepare(metrics, _model)\n        ^^^^^^^^^^^^^^^^^^^^^^^^\nTypeError: prepare() takes 1 positional argument but 2 were given"}}
{"timestamp": "2025-05-04 18:47:31,106", "level": "ERROR", "message": "Error importing engine function _fallback_prediction: module 'flashcamp.backend.app.engines.ml' has no attribute '_fallback_prediction'", "module": "analysis", "function": "_import_engine_function", "line": "54", "process": "83462", "thread": "140704646966208"}
{"timestamp": "2025-05-04 18:47:31,106", "level": "ERROR", "message": "Could not import fallback prediction function!", "module": "analysis", "function": "predict_success", "line": "178", "process": "83462", "thread": "140704646966208"}
{"timestamp": "2025-05-04 18:48:02,806", "level": "ERROR", "message": "Error calculating pillar scores: prepare() takes 1 positional argument but 2 were given", "module": "analysis", "function": "pillar_scores", "line": "105", "process": "83462", "thread": "140704646966208", "exception": {"type": "TypeError", "message": "prepare() takes 1 positional argument but 2 were given", "traceback": "Traceback (most recent call last):\n  File \"/Users/sf/Desktop/FLASH/flashcamp/backend/analysis.py\", line 80, in pillar_scores\n    market_score, _ = calculate_market_score_fn(metrics_data)\n                      ^^^^^^^^^^^^^^^^^^^^^^^^^^^^^^^^^^^^^^^\n  File \"/Users/sf/Desktop/FLASH/flashcamp/backend/app/engines/market.py\", line 23, in calculate_market_score\n    X = prepare(metrics, _model)\n        ^^^^^^^^^^^^^^^^^^^^^^^^\nTypeError: prepare() takes 1 positional argument but 2 were given"}}
{"timestamp": "2025-05-04 18:48:02,810", "level": "ERROR", "message": "Error importing engine function _fallback_prediction: module 'flashcamp.backend.app.engines.ml' has no attribute '_fallback_prediction'", "module": "analysis", "function": "_import_engine_function", "line": "54", "process": "83462", "thread": "140704646966208"}
{"timestamp": "2025-05-04 18:48:02,811", "level": "ERROR", "message": "Could not import fallback prediction function!", "module": "analysis", "function": "predict_success", "line": "178", "process": "83462", "thread": "140704646966208"}
{"timestamp": "2025-05-04 18:48:02,965", "level": "ERROR", "message": "Error calculating pillar scores: prepare() takes 1 positional argument but 2 were given", "module": "analysis", "function": "pillar_scores", "line": "105", "process": "83462", "thread": "140704646966208", "exception": {"type": "TypeError", "message": "prepare() takes 1 positional argument but 2 were given", "traceback": "Traceback (most recent call last):\n  File \"/Users/sf/Desktop/FLASH/flashcamp/backend/analysis.py\", line 80, in pillar_scores\n    market_score, _ = calculate_market_score_fn(metrics_data)\n                      ^^^^^^^^^^^^^^^^^^^^^^^^^^^^^^^^^^^^^^^\n  File \"/Users/sf/Desktop/FLASH/flashcamp/backend/app/engines/market.py\", line 23, in calculate_market_score\n    X = prepare(metrics, _model)\n        ^^^^^^^^^^^^^^^^^^^^^^^^\nTypeError: prepare() takes 1 positional argument but 2 were given"}}
{"timestamp": "2025-05-04 18:48:02,970", "level": "ERROR", "message": "Error importing engine function _fallback_prediction: module 'flashcamp.backend.app.engines.ml' has no attribute '_fallback_prediction'", "module": "analysis", "function": "_import_engine_function", "line": "54", "process": "83462", "thread": "140704646966208"}
{"timestamp": "2025-05-04 18:48:02,971", "level": "ERROR", "message": "Could not import fallback prediction function!", "module": "analysis", "function": "predict_success", "line": "178", "process": "83462", "thread": "140704646966208"}
{"timestamp": "2025-05-04 18:50:50,191", "level": "ERROR", "message": "Error calculating pillar scores: The number of features in data (95) is not the same as it was in training data (4).\nYou can set ``predict_disable_shape_check=true`` to discard this error, but please be aware what you are doing.", "module": "analysis", "function": "pillar_scores", "line": "105", "process": "84119", "thread": "140704646966208", "exception": {"type": "LightGBMError", "message": "The number of features in data (95) is not the same as it was in training data (4).\nYou can set ``predict_disable_shape_check=true`` to discard this error, but please be aware what you are doing.", "traceback": "Traceback (most recent call last):\n  File \"/Users/sf/Desktop/FLASH/flashcamp/backend/analysis.py\", line 80, in pillar_scores\n    market_score, _ = calculate_market_score_fn(metrics_data)\n                      ^^^^^^^^^^^^^^^^^^^^^^^^^^^^^^^^^^^^^^^\n  File \"/Users/sf/Desktop/FLASH/flashcamp/backend/app/engines/market.py\", line 26, in calculate_market_score\n    raw_prediction = _model.predict(X)\n                     ^^^^^^^^^^^^^^^^^\n  File \"/Users/sf/Desktop/FLASH/.venv/lib/python3.11/site-packages/lightgbm/basic.py\", line 4453, in predict\n    return predictor.predict(\n           ^^^^^^^^^^^^^^^^^^\n  File \"/Users/sf/Desktop/FLASH/.venv/lib/python3.11/site-packages/lightgbm/basic.py\", line 1159, in predict\n    preds, nrow = self.__pred_for_np2d(\n                  ^^^^^^^^^^^^^^^^^^^^^\n  File \"/Users/sf/Desktop/FLASH/.venv/lib/python3.11/site-packages/lightgbm/basic.py\", line 1306, in __pred_for_np2d\n    return self.__inner_predict_np2d(\n           ^^^^^^^^^^^^^^^^^^^^^^^^^^\n  File \"/Users/sf/Desktop/FLASH/.venv/lib/python3.11/site-packages/lightgbm/basic.py\", line 1259, in __inner_predict_np2d\n    _safe_call(_LIB.LGBM_BoosterPredictForMat(\n  File \"/Users/sf/Desktop/FLASH/.venv/lib/python3.11/site-packages/lightgbm/basic.py\", line 263, in _safe_call\n    raise LightGBMError(_LIB.LGBM_GetLastError().decode('utf-8'))\nlightgbm.basic.LightGBMError: The number of features in data (95) is not the same as it was in training data (4).\nYou can set ``predict_disable_shape_check=true`` to discard this error, but please be aware what you are doing."}}
{"timestamp": "2025-05-04 18:50:50,206", "level": "ERROR", "message": "Error during fallback prediction import/call: unsupported operand type(s) for -: 'int' and 'NoneType'", "module": "analysis", "function": "predict_success", "line": "182", "process": "84119", "thread": "140704646966208", "exception": {"type": "TypeError", "message": "unsupported operand type(s) for -: 'int' and 'NoneType'", "traceback": "Traceback (most recent call last):\n  File \"/Users/sf/Desktop/FLASH/flashcamp/backend/analysis.py\", line 174, in predict_success\n    fallback_result = fallback_fn(metrics_data)\n                      ^^^^^^^^^^^^^^^^^^^^^^^^^\n  File \"/Users/sf/Desktop/FLASH/flashcamp/backend/app/engines/ml.py\", line 152, in _fallback_prediction\n    (max(0, (3 - burn_multiple) / 3)) * 0.15 +            # Inverse burn multiple\n            ~~^~~~~~~~~~~~~~~\nTypeError: unsupported operand type(s) for -: 'int' and 'NoneType'"}}
{"timestamp": "2025-05-04 18:50:57,672", "level": "ERROR", "message": "Error calculating pillar scores: The number of features in data (95) is not the same as it was in training data (4).\nYou can set ``predict_disable_shape_check=true`` to discard this error, but please be aware what you are doing.", "module": "analysis", "function": "pillar_scores", "line": "105", "process": "84119", "thread": "140704646966208", "exception": {"type": "LightGBMError", "message": "The number of features in data (95) is not the same as it was in training data (4).\nYou can set ``predict_disable_shape_check=true`` to discard this error, but please be aware what you are doing.", "traceback": "Traceback (most recent call last):\n  File \"/Users/sf/Desktop/FLASH/flashcamp/backend/analysis.py\", line 80, in pillar_scores\n    market_score, _ = calculate_market_score_fn(metrics_data)\n                      ^^^^^^^^^^^^^^^^^^^^^^^^^^^^^^^^^^^^^^^\n  File \"/Users/sf/Desktop/FLASH/flashcamp/backend/app/engines/market.py\", line 26, in calculate_market_score\n    raw_prediction = _model.predict(X)\n                     ^^^^^^^^^^^^^^^^^\n  File \"/Users/sf/Desktop/FLASH/.venv/lib/python3.11/site-packages/lightgbm/basic.py\", line 4453, in predict\n    return predictor.predict(\n           ^^^^^^^^^^^^^^^^^^\n  File \"/Users/sf/Desktop/FLASH/.venv/lib/python3.11/site-packages/lightgbm/basic.py\", line 1159, in predict\n    preds, nrow = self.__pred_for_np2d(\n                  ^^^^^^^^^^^^^^^^^^^^^\n  File \"/Users/sf/Desktop/FLASH/.venv/lib/python3.11/site-packages/lightgbm/basic.py\", line 1306, in __pred_for_np2d\n    return self.__inner_predict_np2d(\n           ^^^^^^^^^^^^^^^^^^^^^^^^^^\n  File \"/Users/sf/Desktop/FLASH/.venv/lib/python3.11/site-packages/lightgbm/basic.py\", line 1259, in __inner_predict_np2d\n    _safe_call(_LIB.LGBM_BoosterPredictForMat(\n  File \"/Users/sf/Desktop/FLASH/.venv/lib/python3.11/site-packages/lightgbm/basic.py\", line 263, in _safe_call\n    raise LightGBMError(_LIB.LGBM_GetLastError().decode('utf-8'))\nlightgbm.basic.LightGBMError: The number of features in data (95) is not the same as it was in training data (4).\nYou can set ``predict_disable_shape_check=true`` to discard this error, but please be aware what you are doing."}}
{"timestamp": "2025-05-04 18:50:57,679", "level": "ERROR", "message": "Error during fallback prediction import/call: unsupported operand type(s) for -: 'int' and 'NoneType'", "module": "analysis", "function": "predict_success", "line": "182", "process": "84119", "thread": "140704646966208", "exception": {"type": "TypeError", "message": "unsupported operand type(s) for -: 'int' and 'NoneType'", "traceback": "Traceback (most recent call last):\n  File \"/Users/sf/Desktop/FLASH/flashcamp/backend/analysis.py\", line 174, in predict_success\n    fallback_result = fallback_fn(metrics_data)\n                      ^^^^^^^^^^^^^^^^^^^^^^^^^\n  File \"/Users/sf/Desktop/FLASH/flashcamp/backend/app/engines/ml.py\", line 152, in _fallback_prediction\n    (max(0, (3 - burn_multiple) / 3)) * 0.15 +            # Inverse burn multiple\n            ~~^~~~~~~~~~~~~~~\nTypeError: unsupported operand type(s) for -: 'int' and 'NoneType'"}}
{"timestamp": "2025-05-04 21:57:23,803", "level": "ERROR", "message": "Error predicting success probability: [Errno 2] No such file or directory: '/mnt/data/success_xgb.joblib'", "module": "analysis", "function": "predict_success", "line": "172", "process": "4133", "thread": "140704646966208", "exception": {"type": "FileNotFoundError", "message": "[Errno 2] No such file or directory: '/mnt/data/success_xgb.joblib'", "traceback": "Traceback (most recent call last):\n  File \"/Users/sf/Desktop/FLASH/flashcamp/backend/analysis.py\", line 168, in predict_success\n    probability = predict_fn(metrics_data)\n                  ^^^^^^^^^^^^^^^^^^^^^^^^\n  File \"/Users/sf/Desktop/FLASH/flashcamp/backend/app/engines/ml.py\", line 110, in predict_success_probability\n    model = _load_model()\n            ^^^^^^^^^^^^^\n  File \"/Users/sf/Desktop/FLASH/flashcamp/backend/app/engines/ml.py\", line 49, in _load_model\n    _model = joblib.load(model_path_to_load)\n             ^^^^^^^^^^^^^^^^^^^^^^^^^^^^^^^\n  File \"/Users/sf/Desktop/FLASH/.venv/lib/python3.11/site-packages/joblib/numpy_pickle.py\", line 650, in load\n    with open(filename, 'rb') as f:\n         ^^^^^^^^^^^^^^^^^^^^\nFileNotFoundError: [Errno 2] No such file or directory: '/mnt/data/success_xgb.joblib'"}}
{"timestamp": "2025-05-04 21:58:36,944", "level": "ERROR", "message": "Model file not found: /mnt/data/success_xgb.joblib", "module": "ml", "function": "_load_model", "line": "69", "process": "4412", "thread": "140704646966208"}
{"timestamp": "2025-05-04 21:58:36,944", "level": "ERROR", "message": "Success probability model not loaded", "module": "ml", "function": "predict_success_probability", "line": "144", "process": "4412", "thread": "140704646966208"}
{"timestamp": "2025-05-04 21:58:36,945", "level": "ERROR", "message": "Error predicting success probability: Success probability model not loaded or unavailable", "module": "analysis", "function": "predict_success", "line": "172", "process": "4412", "thread": "140704646966208", "exception": {"type": "ValueError", "message": "Success probability model not loaded or unavailable", "traceback": "Traceback (most recent call last):\n  File \"/Users/sf/Desktop/FLASH/flashcamp/backend/analysis.py\", line 168, in predict_success\n    probability = predict_fn(metrics_data)\n                  ^^^^^^^^^^^^^^^^^^^^^^^^\n  File \"/Users/sf/Desktop/FLASH/flashcamp/backend/app/engines/ml.py\", line 145, in predict_success_probability\n    raise ValueError(\"Success probability model not loaded or unavailable\")\nValueError: Success probability model not loaded or unavailable"}}
{"timestamp": "2025-05-04 21:58:46,720", "level": "ERROR", "message": "Model file not found: /mnt/data/success_xgb.joblib", "module": "ml", "function": "_load_model", "line": "69", "process": "4412", "thread": "140704646966208"}
{"timestamp": "2025-05-04 21:58:46,720", "level": "ERROR", "message": "Success probability model not loaded", "module": "ml", "function": "predict_success_probability", "line": "144", "process": "4412", "thread": "140704646966208"}
{"timestamp": "2025-05-04 21:58:46,721", "level": "ERROR", "message": "Error predicting success probability: Success probability model not loaded or unavailable", "module": "analysis", "function": "predict_success", "line": "172", "process": "4412", "thread": "140704646966208", "exception": {"type": "ValueError", "message": "Success probability model not loaded or unavailable", "traceback": "Traceback (most recent call last):\n  File \"/Users/sf/Desktop/FLASH/flashcamp/backend/analysis.py\", line 168, in predict_success\n    probability = predict_fn(metrics_data)\n                  ^^^^^^^^^^^^^^^^^^^^^^^^\n  File \"/Users/sf/Desktop/FLASH/flashcamp/backend/app/engines/ml.py\", line 145, in predict_success_probability\n    raise ValueError(\"Success probability model not loaded or unavailable\")\nValueError: Success probability model not loaded or unavailable"}}
{"timestamp": "2025-05-17 19:54:36,335", "level": "ERROR", "message": "Error during model prediction: unsupported operand type(s) for /: 'float' and 'NoneType'", "module": "ml", "function": "predict_success_probability", "line": "242", "process": "74899", "thread": "140704624868288", "exception": {"type": "TypeError", "message": "unsupported operand type(s) for /: 'float' and 'NoneType'", "traceback": "Traceback (most recent call last):\n  File \"/Users/sf/Desktop/FLASH/flashcamp/backend/app/engines/ml.py\", line 193, in predict_success_probability\n    X = build_feature_vector(metrics)\n        ^^^^^^^^^^^^^^^^^^^^^^^^^^^^^\n  File \"/Users/sf/Desktop/FLASH/flashcamp/features/build_features.py\", line 76, in build_feature_vector\n    burn_multiple = safe_div(d.get(\"monthly_burn_usd\", 0) * 12, d.get(\"annual_revenue_run_rate\", 1e-6))\n                    ^^^^^^^^^^^^^^^^^^^^^^^^^^^^^^^^^^^^^^^^^^^^^^^^^^^^^^^^^^^^^^^^^^^^^^^^^^^^^^^^^^^\n  File \"/Users/sf/Desktop/FLASH/flashcamp/features/encode.py\", line 21, in safe_div\n    return 0.0 if denom == 0 else num / denom\n                                  ~~~~^~~~~~~\nTypeError: unsupported operand type(s) for /: 'float' and 'NoneType'"}}
{"timestamp": "2025-05-17 19:54:36,338", "level": "ERROR", "message": "Error predicting success probability: unsupported format string passed to dict.__format__", "module": "analysis", "function": "predict_success", "line": "172", "process": "74899", "thread": "140704624868288", "exception": {"type": "TypeError", "message": "unsupported format string passed to dict.__format__", "traceback": "Traceback (most recent call last):\n  File \"/Users/sf/Desktop/FLASH/flashcamp/backend/analysis.py\", line 169, in predict_success\n    logger.info(f\"Predicted success probability: {probability:.2f}\")\n                ^^^^^^^^^^^^^^^^^^^^^^^^^^^^^^^^^^^^^^^^^^^^^^^^^^^\nTypeError: unsupported format string passed to dict.__format__"}}
